Workbook

Sheet BOQ
B2: CONTRACT SANRAL N.002-300-2022/2R | H2: Estimate @ 26/05/2025
B4: ITEM | F4: DESCRIPTION | G4: UNIT | H4: SCHEDULED QTY | I4: FINAL EST. QTY | J4: PREVIOUS QTY | K4: CURRENT QTY | L4: TO DATE QTY | M4: RATE R | N4: SCHEDULED AMOUNT | O4: FINAL EST. AMOUNT | P4: VARIANCE | Q4: COMMENTS | Y4: TEN Civils Rate | Z4: TEN Civils Amount
B5: C1.2 | F5: GENERAL REQUIREMENTS AND PROVISIONS
B6: C1.2.1 | F6: ENVIRONMENTAL MANAGEMENT
C7: C1.2.1.1 | F7: Monitoring of compliance with and reporting on the EMP | G7: month | H7: 12 | I7: 9 | J7: 0 | K7: =L7-J7 -> 0 | L7: 0 | M7: 35000 | N7: =IFERROR(IF(AND($G7<>"",$H7<>""),$H7*$M7,""),0) -> 420000 | O7: =IFERROR(IF(AND($G7<>"",$H7<>""),$I7*$M7,""),0) -> 315000 | P7: =+N7-O7 -> 105000 | Q7: Original Contract Duration | R7: =+Q7-N7 -> #VALUE!
C8: C1.2.1.2 | F8: Dedicated environmental officer (if specified in the Contract Documentation) | G8: month | H8: 12 | I8: 9 | J8: 0 | K8: =L8-J8 -> 0 | L8: 0 | M8: 24000 | N8: =IFERROR(IF(AND($G8<>"",$H8<>""),$H8*$M8,""),0) -> 288000 | O8: =IFERROR(IF(AND($G8<>"",$H8<>""),$I8*$M8,""),0) -> 216000 | P8: =+N8-O8 -> 72000 | Q8: Original Contract Duration | R8: =+Q8-N8 -> #VALUE!
R9: =+Q9-N9 -> 0
B10: C1.2.2 | F10: Programming and Reporting | P10: =IFERROR(IF(AND($G10<>"",$H10<>""),$L10*$M10,""),0) | R10: =+Q10-N10 -> 0
C11: C1.2.2.3 | F11: Reviewing and updating a Scheme 2 Initial Programme | G11: lump sum | H11: 1 | I11: 1 | J11: 0 | K11: 1 | L11: =K11+J11 -> 1 | M11: 10000 | N11: =IFERROR(IF(AND($G11<>"",$H11<>""),$H11*$M11,""),0) -> 10000 | O11: =IFERROR(IF(AND($G11<>"",$H11<>""),$I11*$M11,""),0) -> 10000 | P11: =+N11-O11 -> 0 | R11: =+Q11-N11 -> -10000
C12: C1.2.2.4 | F12: Reviewing and updating a Scheme 2 Full Programme | G12: lump sum | H12: 1 | I12: 1 | J12: 0 | K12: 1 | L12: =K12+J12 -> 1 | M12: 10000 | N12: =IFERROR(IF(AND($G12<>"",$H12<>""),$H12*$M12,""),0) -> 10000 | O12: =IFERROR(IF(AND($G12<>"",$H12<>""),$I12*$M12,""),0) -> 10000 | P12: =+N12-O12 -> 0 | R12: =+Q12-N12 -> -10000
C13: C1.2.2.5 | F13: Reviewing and updating a Scheme 2 programme every month | G13: month | H13: 12 | I13: 9 | J13: 0 | K13: =L13-J13 -> 0 | L13: 0 | M13: 3500 | N13: =IFERROR(IF(AND($G13<>"",$H13<>""),$H13*$M13,""),0) -> 42000 | O13: =IFERROR(IF(AND($G13<>"",$H13<>""),$I13*$M13,""),0) -> 31500 | P13: =+N13-O13 -> 10500 | Q13: Original Contract Duration | R13: =+Q13-N13 -> #VALUE!
C14: C1.2.2.6 | F14: Preparation and submission of all information and reports specified in the Contract Documentation | G14: month | H14: 12 | I14: 9 | J14: 0 | K14: =L14-J14 -> 0 | L14: 0 | M14: 5800 | N14: =IFERROR(IF(AND($G14<>"",$H14<>""),$H14*$M14,""),0) -> 69600 | O14: =IFERROR(IF(AND($G14<>"",$H14<>""),$I14*$M14,""),0) -> 52200 | P14: =+N14-O14 -> 17400 | Q14: Original Contract Duration | R14: =+Q14-N14 -> #VALUE!
R15: =+Q15-N15 -> 0
B16: C1.2.3 | F16: Routine road maintenance of existing public roads within the Site of Works or other public roads outside the Site of the Works which are used as detours | N16: =IFERROR(IF(AND($G16<>"",$H16<>""),$H16*$M16,""),0) | O16: =IFERROR(IF(AND($G16<>"",$H16<>""),$I16*$M16,""),0) | P16: =IFERROR(IF(AND($G16<>"",$H16<>""),$L16*$M16,""),0)
C17: C1.2.3.7 | F17: Base and/or surface patching using hot plant mixed asphalt | G17: ton (t) | H17: 500 | I17: 0 | J17: 0 | K17: =L17-J17 -> 0 | L17: 0 | M17: 1500 | N17: =IFERROR(IF(AND($G17<>"",$H17<>""),$H17*$M17,""),0) -> 750000 | O17: =IFERROR(IF(AND($G17<>"",$H17<>""),$I17*$M17,""),0) -> 0 | P17: =+N17-O17 -> 750000 | Q17: Contractor likely wont do this item | R17: =+Q17-N17 -> #VALUE!
C18: C1.2.3.8 | F18: Replacement of damaged guardrails including posts | G18: metre (m) | H18: 15200 | I18: 0 | J18: 0 | K18: =L18-J18 -> 0 | L18: 0 | M18: 1090 | N18: =IFERROR(IF(AND($G18<>"",$H18<>""),$H18*$M18,""),0) -> 16568000 | O18: =IFERROR(IF(AND($G18<>"",$H18<>""),$I18*$M18,""),0) -> 0 | P18: =+N18-O18 -> 16568000 | Q18: Nil, masured below | R18: =+Q18-N18 -> #VALUE!
C19: C1.2.3.13 | F19: Liaison with the routine road maintenance contractor | G19: month | H19: 12 | I19: 9 | J19: 0 | K19: =L19-J19 -> 0 | L19: 0 | M19: 5000 | N19: =IFERROR(IF(AND($G19<>"",$H19<>""),$H19*$M19,""),0) -> 60000 | O19: =IFERROR(IF(AND($G19<>"",$H19<>""),$I19*$M19,""),0) -> 45000 | P19: =+N19-O19 -> 15000 | Q19: Original Contract Duration | R19: =+Q19-N19 -> #VALUE!
R20: =+Q20-N20 -> 0
B21: C1.2.4 | F21: Stakeholder Liaison | G21: month | H21: 12 | I21: 9 | J21: 0 | K21: 6 | L21: =K21+J21 -> 6 | M21: 10000 | N21: =IFERROR(IF(AND($G21<>"",$H21<>""),$H21*$M21,""),0) -> 120000 | O21: =IFERROR(IF(AND($G21<>"",$H21<>""),$I21*$M21,""),0) -> 90000 | P21: =+N21-O21 -> 30000 | Q21: original Contract Duration | R21: =+Q21-N21 -> #VALUE!
R22: =+Q22-N22 -> 0
B23: C1.2.5 | F23: SAFETY | N23: =IFERROR(IF(AND($G23<>"",$H23<>""),$H23*$M23,""),0) | O23: =IFERROR(IF(AND($G23<>"",$H23<>""),$I23*$M23,""),0) | P23: =IFERROR(IF(AND($G23<>"",$H23<>""),$L23*$M23,""),0)
C24: C1.2.5.1 | F24: Health and Safety Plan | G24: lump sum | H24: 1 | I24: 1 | J24: 0 | K24: 1 | L24: =K24+J24 -> 1 | M24: 18000 | N24: =IFERROR(IF(AND($G24<>"",$H24<>""),$H24*$M24,""),0) -> 18000 | O24: =IFERROR(IF(AND($G24<>"",$H24<>""),$I24*$M24,""),0) -> 18000 | P24: =+N24-O24 -> 0 | R24: =+Q24-N24 -> -18000
C25: C1.2.5.2 | F25: Implementation of health and safety plan | G25: month | H25: 12 | I25: 9 | J25: 0 | K25: 2 | L25: =K25+J25 -> 2 | M25: 5000 | N25: =IFERROR(IF(AND($G25<>"",$H25<>""),$H25*$M25,""),0) -> 60000 | O25: =IFERROR(IF(AND($G25<>"",$H25<>""),$I25*$M25,""),0) -> 45000 | P25: =+N25-O25 -> 15000 | Q25: original Contract Duration | R25: =+Q25-N25 -> #VALUE!
R26: =+Q26-N26 -> 0
B27: PC1.2.7 | F27: Road Safety Audits | N27: =IFERROR(IF(AND($G27<>"",$H27<>""),$H27*$M27,""),0) | O27: =IFERROR(IF(AND($G27<>"",$H27<>""),$I27*$M27,""),0) | P27: =IFERROR(IF(AND($G27<>"",$H27<>""),$L27*$M27,""),0)
C28: C1.2.7.1 | F28: Stage 4 work zone traffic management audit | G28: provisional sum | H28: 1 | I28: =32500/150000 -> 0.21666667 | K28: =L28-J28 -> 0 | M28: 150000 | N28: =IFERROR(IF(AND($G28<>"",$H28<>""),$H28*$M28,""),0) -> 150000 | O28: =IFERROR(IF(AND($G28<>"",$H28<>""),$I28*$M28,""),0) -> 32500 | P28: =+N28-O28 -> 117500 | Q28: Actual | R28: =+Q28-N28 -> #VALUE!
C29: C1.2.7.2 | F29: Handling cost, profit and all other charges in respect of item C1.2.7.1 | G29: percentage (%) | H29: 150000 | I29: =O28*M29 -> 3250 | K29: =L29-J29 -> 0 | M29: 0.1 | N29: =IFERROR(IF(AND($G29<>"",$H29<>""),$H29*$M29,""),0) -> 15000 | O29: =IFERROR(IF(AND($G29<>"",$H29<>""),$I29*$M29,""),0) -> 325 | P29: =+N29-O29 -> 14675 | R29: =+Q29-N29 -> -15000
C30: C1.2.7.3 | F30: Stage 5 pre-opening stage traffic safety audit | G30: provisional sum | H30: 1 | I30: =30760/150000 -> 0.20506667 | K30: =L30-J30 -> 0 | M30: 150000 | N30: =IFERROR(IF(AND($G30<>"",$H30<>""),$H30*$M30,""),0) -> 150000 | O30: =IFERROR(IF(AND($G30<>"",$H30<>""),$I30*$M30,""),0) -> 30760 | P30: =+N30-O30 -> 119240 | Q30: Actual | R30: =+Q30-N30 -> #VALUE!
C31: C1.2.7.4 | F31: Handling cost, profit and all other charges in respect of item C1.2.7.3 | G31: percentage (%) | H31: 150000 | I31: =O30*M31 -> 3076 | K31: =L31-J31 -> 0 | M31: 0.1 | N31: =IFERROR(IF(AND($G31<>"",$H31<>""),$H31*$M31,""),0) -> 15000 | O31: =IFERROR(IF(AND($G31<>"",$H31<>""),$I31*$M31,""),0) -> 307.6 | P31: =+N31-O31 -> 14692.4 | R31: =+Q31-N31 -> -15000
R32: =+Q32-N32 -> 0
B33: C1.2.8 | F33: DAYWORKS | N33: =IFERROR(IF(AND($G33<>"",$H33<>""),$H33*$M33,""),0) | O33: =IFERROR(IF(AND($G33<>"",$H33<>""),$I33*$M33,""),0) | P33: =IFERROR(IF(AND($G33<>"",$H33<>""),$L33*$M33,""),0)
C34: C1.2.8.1 | F34: Personnel | N34: =IFERROR(IF(AND($G34<>"",$H34<>""),$H34*$M34,""),0) | O34: =IFERROR(IF(AND($G34<>"",$H34<>""),$I34*$M34,""),0) | P34: =IFERROR(IF(AND($G34<>"",$H34<>""),$L34*$M34,""),0)
D35: (a) | F35: Unskilled labourer | G35: hour (h) | H35: 100 | I35: 0 | K35: =L35-J35 -> 0 | M35: 50.03 | N35: =IFERROR(IF(AND($G35<>"",$H35<>""),$H35*$M35,""),0) -> 5003 | O35: =IFERROR(IF(AND($G35<>"",$H35<>""),$I35*$M35,""),0) -> 0 | P35: =+N35-O35 -> 5003 | Q35: Estimated to be Nil | R35: =+Q35-N35 -> #VALUE!
D36: (b) | F36: Semi-skilled labourer | G36: hour (h) | H36: 100 | I36: 0 | K36: =L36-J36 -> 0 | M36: 67.33 | N36: =IFERROR(IF(AND($G36<>"",$H36<>""),$H36*$M36,""),0) -> 6733 | O36: =IFERROR(IF(AND($G36<>"",$H36<>""),$I36*$M36,""),0) -> 0 | P36: =+N36-O36 -> 6733 | Q36: Estimated to be Nil | R36: =+Q36-N36 -> #VALUE!
D37: (c) | F37: Skilled labourer | G37: hour (h) | H37: 100 | I37: 0 | K37: =L37-J37 -> 0 | M37: 93.6 | N37: =IFERROR(IF(AND($G37<>"",$H37<>""),$H37*$M37,""),0) -> 9360 | O37: =IFERROR(IF(AND($G37<>"",$H37<>""),$I37*$M37,""),0) -> 0 | P37: =+N37-O37 -> 9360 | Q37: Estimated to be Nil | R37: =+Q37-N37 -> #VALUE!
D38: (d) | F38: Gang leader | G38: hour (h) | H38: 100 | I38: 0 | K38: =L38-J38 -> 0 | M38: 93.5 | N38: =IFERROR(IF(AND($G38<>"",$H38<>""),$H38*$M38,""),0) -> 9350 | O38: =IFERROR(IF(AND($G38<>"",$H38<>""),$I38*$M38,""),0) -> 0 | P38: =+N38-O38 -> 9350 | Q38: Estimated to be Nil | R38: =+Q38-N38 -> #VALUE!
D39: (e) | F39: Foreman | G39: hour (h) | H39: 100 | I39: 0 | K39: =L39-J39 -> 0 | M39: 135 | N39: =IFERROR(IF(AND($G39<>"",$H39<>""),$H39*$M39,""),0) -> 13500 | O39: =IFERROR(IF(AND($G39<>"",$H39<>""),$I39*$M39,""),0) -> 0 | P39: =+N39-O39 -> 13500 | Q39: Estimated to be Nil | R39: =+Q39-N39 -> #VALUE!
D40: (f) | F40: Skilled artisan | G40: hour (h) | H40: 100 | I40: 0 | K40: =L40-J40 -> 0 | M40: 125 | N40: =IFERROR(IF(AND($G40<>"",$H40<>""),$H40*$M40,""),0) -> 12500 | O40: =IFERROR(IF(AND($G40<>"",$H40<>""),$I40*$M40,""),0) -> 0 | P40: =+N40-O40 -> 12500 | Q40: Estimated to be Nil | R40: =+Q40-N40 -> #VALUE!
R41: =+Q41-N41 -> 0
B42: C1.2.8.2 | F42: Construction Equipment | N42: =IFERROR(IF(AND($G42<>"",$H42<>""),$H42*$M42,""),0) | O42: =IFERROR(IF(AND($G42<>"",$H42<>""),$I42*$M42,""),0) | P42: =IFERROR(IF(AND($G42<>"",$H42<>""),$L42*$M42,""),0)
...

Sheet BoQ Summary
A1: SUMMARY OF SCHEDULE OF QUANTITIES
A3: SCHEDULE A : ROAD CONSTRUCTION
A4: SECTION | B4: DESCRIPTION | C4: TENDER AMOUNT | D4: ESTIMATE AMOUNT | F4: Variance | G4: TEN Civils
A5: C1.2 | B5: GENERAL REQUIREMENTS AND PROVISIONS | C5: =+BOQ!N60 -> 19376146 | D5: =+BOQ!O60 -> 896592.6 | F5: =C5-D5 -> 18479553
A6: C1.3 | B6: THE CONTRACTOR'S SITE ESTABLISHMENT AND GENERAL OBLIGATIONS | C6: =+BOQ!N76 -> 24229674 | D6: =+BOQ!O76 -> 18978234 | F6: =C6-D6 -> 5251440 | G6: =BOQ!Z76 -> 4615878.5 | H6: =G6/(G26-G6) -> 0.043281456
A7: C1.4 | B7: FACILITIES FOR THE ENGINEER | C7: =+BOQ!N145 -> 2871850 | D7: =+BOQ!O145 -> 2033976.7 | F7: =C7-D7 -> 837873.26
A8: C1.5 | B8: ACCOMMODATION OF TRAFFIC | C8: =+BOQ!N200 -> 7659396 | D8: =+BOQ!O200 -> 7440918 | F8: =C8-D8 -> 218478
A9: C1.6 | B9: CLEARING AND GRUBBING | C9: =+BOQ!N210 -> 3305250 | D9: =+BOQ!O210 -> 934370 | F9: =C9-D9 -> 2370880
A10: C3.1 | B10: DRAINS | C10: =+BOQ!N246 -> 3460162.5 | D10: =+BOQ!O246 -> 1980663 | F10: =C10-D10 -> 1479499.5
A11: C3.3 | B11: CONCRETE KERBING AND CHANNELING, ASPHALT BERMS, CHUTES, DOWNPIPES, AS WELL AS CONCRETE, STONE PITCHED AND GABION LININGS FOR OPEN DRAINS | C11: =+BOQ!N262 -> 3657850 | D11: =+BOQ!O262 -> 1509792 | F11: =C11-D11 -> 2148058
A12: C4.3 | B12: EXISTING ROAD MATERIALS | C12: =+BOQ!N273 -> 1100000 | D12: =+BOQ!O273 -> 0 | F12: =C12-D12 -> 1100000
A13: C8.5 | B13: STANDARD CRACK SEALING | C13: =+BOQ!N284 -> 84940 | D13: =+BOQ!O284 -> 0 | F13: =C13-D13 -> 84940
A14: C8.8 | B14: PATCHING AND EDGE BREAK REPAIR | C14: =BOQ!N308 -> 8268600 | D14: =+BOQ!O308 -> 3608965.3 | F14: =C14-D14 -> 4659634.7 | G14: =BOQ!Z308 -> 6251558
A15: C8.9 | B15: REPAIR OF SURFACE DEFECTS | C15: =+BOQ!N319 -> 1292500 | D15: =+BOQ!O319 -> 1480600 | F15: =C15-D15 -> -188100 | G15: =BOQ!Z319 -> 1036966.5
A16: C9.1 | B16: ASPHALT LAYERS | C16: =BOQ!N347 -> 62069100 | D16: =+BOQ!O347 -> 1.0674602e+08 | F16: =C16-D16 -> -44676919 | G16: =BOQ!Z347 -> 96068324 | H16: =D16-G16 -> 10677695
A17: C11.4 | B17: ROAD RESTRAINT SYSTEMS | C17: =+BOQ!N365 -> 9066350 | D17: =+BOQ!O365 -> 12816737 | F17: =C17-D17 -> -3750386.8
A18: C11.6 | B18: ROAD SIGNS | C18: =+BOQ!N397 -> 328800 | D18: =+BOQ!O397 -> 148179.4 | F18: =C18-D18 -> 180620.6
A19: C11.7 | B19: ROAD MARKINGS AND ROAD STUDS | C19: =+BOQ!N421 -> 8361450 | D19: =+BOQ!O421 -> 8089502.7 | F19: =C19-D19 -> 271947.26 | G19: =BOQ!Z421 -> 2761842.8
A20: C11.9 | B20: FINISHING THE ROAD AND ROAD RESERVE AND TREATING OLD ROADS | C20: =+BOQ!N426 -> 423700 | D20: =+BOQ!O426 -> 423700 | F20: =C20-D20 -> 0 | G20: =BOQ!Z426 -> 296097.17
A21: C13.7 | B21: JOINTS | C21: =+BOQ!N435 -> 390785 | D21: =+BOQ!O435 -> 269065 | F21: =C21-D21 -> 121720 | G21: =BOQ!Z435 -> 233160.4
A22: C20.1 | B22: TESTING MATERIALS AND JUDGEMENT OF WORKMANSHIP | C22: =+BOQ!N448 -> 585000 | D22: =+BOQ!O448 -> -4365000 | F22: =C22-D22 -> 4950000
A26: TOTAL SCHEDULE A : ROAD CONSTRUCTION | C26: =SUM(C5:C22) -> 156531554 | D26: =SUM(D5:D22) -> 1.6299232e+08 | F26: =SUM(D5:D25)-D16+F16 -> 11569377 | G26: =SUM(G5:G22) -> 1.1126383e+08 | H26: =D26-G26 -> 51728488
A28: TOTAL ROADWORKS | C28: =C26 -> 156531554 | D28: =D26 -> 1.6299232e+08 | E28: =E26 -> 0 | F28: =F26 -> 11569377 | G28: =G26 -> 1.1126383e+08
A30: SECTION
A31: D1000 | B31: TRAINING, COACHING, GUIDANCE, MENTORING AND ASSISTANCE | C31: =+BOQ!N483 -> 18154356 | D31: =BOQ!O483 -> 11695834 | E31: =BOQ!P483 -> 6458522.4 | F31: =D31 -> 11695834
A33: TOTAL SCHEDULE D : STAKEHOLDER AND COMMUNITY LIAISON, AND TARGETED LABOUR AND TARGETED ENTERPRISES UTILISATION AND DEVELOPMENT | C33: =SUM(C31:C32) -> 18154356 | D33: =SUM(D31:D32) -> 11695834 | E33: =SUM(E31:E32) -> 6458522.4 | F33: =SUM(F31:F32) -> 11695834
A35: GRAND TOTAL | C35: =SUM(C28+C33) -> 174685910 | D35: =SUM(D28+D33) -> 1.7468815e+08 | E35: =SUM(E28+E33) -> 6458522.4 | F35: =SUM(F28+F33) -> 23265211
F36: =C35-F35 -> 1.514207e+08
A37: CALCULATION OF TENDER SUM
A39: TOTAL SCHEDULE A : ROAD CONSTRUCTION | C39: =C28 -> 156531554 | D39: =D28 -> 1.6299232e+08 | G39: =G28 -> 1.1126383e+08
A40: TOTAL SCHEDULE D : STAKEHOLDER AND COMMUNITY LIAISON, AND TARGETED LABOUR AND TARGETED ENTERPRISES UTILISATION AND DEVELOPMENT | C40: =C33 -> 18154356 | D40: =D33 -> 11695834
A41: TOTAL WORK | C41: =SUM(C39:C40) -> 174685910 | D41: =SUM(D39:D40) -> 1.7468815e+08 | G41: =SUM(G39:G40) -> 1.1126383e+08
A42: VAT 15% | C42: =C41*15% -> 26202886 | D42: =D41*15% -> 26203222 | G42: =G41*15% -> 16689574
A43: TENDER SUM CARRIED TO FORM OF TENDER | C43: =C41+C42 -> 2.008888e+08 | D43: =D41+D42 -> 2.0089137e+08 | G43: =G41+G42 -> 1.279534e+08
D44: =C43-D43 -> -2574.8929

Sheet Guardrails
A1: ITEM | E1: DESCRIPTION | F1: UNIT | G1: QTY | H1: RATE | I1: AMOUNT | N1: GUARDRAILS (LHS)
A2: C11.4 | E2: ROAD RESTRAINT SYSTEMS
A3: C11.4.1 | E3: Erecting of guardrails at 3.81m spacing | M3: REF No. | N3: KM MARKER | O3: KM START | P3: DISTANCE TO START | Q3: KM END | R3: TOTAL LENGTH (KM) | S3: STRAIGHT LENGTH (KM) | T3: APPROACH LENGTH (KM) | U3: DEPARTING LENGTH (KM) | V3: REMARKS
B4: C11.4.1.1 | E4: Complete galvanised system compliant to SANS 1350: on timber posts | M4: 1 | N4: 55.4 | O4: 55.37 | P4: =N4-O4 -> 0.03 | Q4: 55.7 | R4: 0.33147 | S4: =+R4-T4-U4 -> 0.29337 | T4: =1.905*10/1000 -> 0.01905 | U4: =+T4 -> 0.01905
C5: (a) | E5: on timber posts | F5: metre (m) | G5: =G26 -> 8800 | H5: 1000 | I5: =G5*H5 -> 8800000 | M5: 2 | N5: 56.2 | O5: 56.33 | P5: =O5-N5 -> 0.13 | Q5: 56.343 | R5: 0.01524 | S5: =+R5-T5-U5 -> 0.01524 | T5: 0 | U5: 0 | V5: End Wings
B6: C11.4.1.2 | E6: Terminal sections for 3.81m guardrails comprising of: | M6: 3 | N6: 56.34 | O6: 56.42 | P6: =O6-N6 -> 0.08 | Q6: 56.596 | R6: 0.17526 | S6: =+R6-T6-U6 -> 0.13716 | T6: =1.905*10/1000 -> 0.01905 | U6: =+T6 -> 0.01905
C7: (a) | E7: End Wings to SANS 1350 | F7: number (No.) | G7: 0 | H7: 800 | I7: =G7*H7 -> 0 | M7: 4 | N7: 57.4 | O7: 57.5 | P7: =O7-N7 -> 0.1 | Q7: 57.752 | R7: 0.25146 | S7: =+R7-T7-U7 -> 0.21336 | T7: =1.905*10/1000 -> 0.01905 | U7: =+T7 -> 0.01905
A8: C11.4.6 | E8: Reflective plates | M8: 5 | N8: 58.2 | O8: 58.3 | P8: =O8-N8 -> 0.1 | Q8: 58.466 | R8: 0.16764 | S8: =+R8-T8-U8 -> 0.12954 | T8: =1.905*10/1000 -> 0.01905 | U8: =+T8 -> 0.01905
B9: C11.4.6.1 | E9: Steel Plates | F9: number (No.) | G9: =(G5/3.8)/2 -> 1157.8947 | H9: 15 | I9: =G9*H9 -> 17368.421 | M9: 6 | N9: 59.4 | O9: 59.421 | P9: =O9-N9 -> 0.021 | Q9: 59.585 | R9: 0.16383 | S9: =+R9-T9-U9 -> 0.12573 | T9: =1.905*10/1000 -> 0.01905 | U9: =+T9 -> 0.01905
A10: C11.4.7 | E10: Removing Existing Guardrails | F10: metre (m) | G10: =G26 -> 8800 | H10: 380 | I10: =G10*H10 -> 3344000 | M10: 7 | N10: 60.6 | O10: 60.59 | P10: =N10-O10 -> 0.01 | Q10: 60.722 | R10: 0.13335 | S10: =+R10-T10-U10 -> 0.09525 | T10: =1.905*10/1000 -> 0.01905 | U10: =+T10 -> 0.01905
A11: C11.4.14 | E11: Nailing of gang nail plates on top of timber guardrail posts | F11: number (No.) | G11: =G26/3.8 -> 2315.7895 | H11: 55 | I11: =G11*H11 -> 127368.42 | M11: 8 | N11: 61.8 | O11: 61.9 | P11: =O11-N11 -> 0.1 | Q11: 62.125 | R11: 0.22479 | S11: =+R11-T11-U11 -> 0.18669 | T11: =1.905*10/1000 -> 0.01905 | U11: =+T11 -> 0.01905
A12: C11.4.15 | E12: Disposal of existing guardrails | I12: =G12*H12 -> 0 | M12: 9 | N12: 63.2 | O12: 63.23 | P12: =O12-N12 -> 0.03 | Q12: 63.289 | R12: 0.06096 | S12: =+R12-T12-U12 -> 0.02286 | T12: =1.905*10/1000 -> 0.01905 | U12: =+T12 -> 0.01905
B13: C11.4.15.1 | E13: Straight or curved long guardrails | F13: metre (m) | G13: =G26 -> 8800 | H13: 60 | I13: =G13*H13 -> 528000 | M13: 10 | N13: 64.2 | O13: 64.135 | P13: =N13-O13 -> 0.065 | Q13: 64.258 | R13: 0.12192 | S13: =+R13-T13-U13 -> 0.08382 | T13: =1.905*10/1000 -> 0.01905 | U13: =+T13 -> 0.01905
B14: C11.4.15.2 | E14: End treatments with single guardrails | F14: metre (m) | G14: 0 | H14: 80 | I14: =G14*H14 -> 0 | M14: 11 | N14: 65.6 | O14: 65.67 | P14: =O14-N14 -> 0.07 | Q14: 65.862 | R14: 0.1905 | S14: =+R14-T14-U14 -> 0.1524 | T14: =1.905*10/1000 -> 0.01905 | U14: =+T14 -> 0.01905
M15: 12 | N15: 66.4 | O15: 66.49 | P15: =O15-N15 -> 0.09 | Q15: 66.653 | R15: 0.16383 | S15: =+R15-T15-U15 -> 0.12573 | T15: =1.905*10/1000 -> 0.01905 | U15: =+T15 -> 0.01905
H16: Total | I16: =SUM(I3:I14) -> 12816737 | M16: 13 | N16: 67 | O16: 66.952 | P16: =N16-O16 -> 0.048 | Q16: 67.084 | R16: 0.13335 | S16: =+R16-T16-U16 -> 0.09525 | T16: =1.905*10/1000 -> 0.01905 | U16: =+T16 -> 0.01905
M17: 14 | N17: 67.4 | O17: 67.42 | P17: =O17-N17 -> 0.02 | Q17: 67.626 | R17: 0.20574 | S17: =+R17-T17-U17 -> 0.16764 | T17: =1.905*10/1000 -> 0.01905 | U17: =+T17 -> 0.01905
M18: 15 | N18: 68 | O18: 68.08 | P18: =O18-N18 -> 0.08 | Q18: 68.31 | R18: 0.2286 | S18: =+R18-T18-U18 -> 0.1905 | T18: =1.905*10/1000 -> 0.01905 | U18: =+T18 -> 0.01905
M19: 16 | N19: 68.6 | O19: 68.65 | P19: =O19-N19 -> 0.05 | Q19: 68.848 | R19: 0.19812 | S19: =+R19-T19-U19 -> 0.16002 | T19: =1.905*10/1000 -> 0.01905 | U19: =+T19 -> 0.01905
M20: 17 | N20: 69.2 | O20: 69.19 | P20: =N20-O20 -> 0.01 | Q20: 69.369 | R20: 0.17907 | S20: =+R20-T20-U20 -> 0.14097 | T20: =1.905*10/1000 -> 0.01905 | U20: =+T20 -> 0.01905
M21: 18 | N21: 69.6 | O21: 69.65 | P21: =O21-N21 -> 0.05 | Q21: 69.735 | R21: 0.08382 | S21: =+R21-T21-U21 -> 0.04572 | T21: =1.905*10/1000 -> 0.01905 | U21: =+T21 -> 0.01905
M22: 19 | N22: 70 | O22: 70.11 | P22: =O22-N22 -> 0.11 | Q22: 70.203 | R22: 0.09525 | S22: =+R22-T22-U22 -> 0.05715 | T22: =1.905*10/1000 -> 0.01905 | U22: =+T22 -> 0.01905
M23: 20 | N23: 71.2 | O23: 71.28 | P23: =O23-N23 -> 0.08 | Q23: 71.535 | R23: 0.25527 | S23: =+R23-T23-U23 -> 0.21717 | T23: =1.905*10/1000 -> 0.01905 | U23: =+T23 -> 0.01905
M24: 21 | N24: 72.2 | O24: 72.32 | P24: =O24-N24 -> 0.12 | Q24: 72.588 | R24: 0.2667 | S24: =+R24-T24-U24 -> 0.2286 | T24: =1.905*10/1000 -> 0.01905 | U24: =+T24 -> 0.01905
M25: 22 | N25: 73.4 | O25: 73.51 | P25: =O25-N25 -> 0.11 | Q25: 73.658 | R25: 0.14859 | S25: =+R25-T25-U25 -> 0.11049 | T25: =1.905*10/1000 -> 0.01905 | U25: =+T25 -> 0.01905
F26: Guardrails (m) | G26: 8800 | M26: 23 | N26: 74 | O26: 74.04 | P26: =O26-N26 -> 0.04 | Q26: =+O26+(R26/1000) -> 74.040408 | R26: 0.40767 | S26: =+R26-T26-U26 -> 0.36957 | T26: =1.905*10/1000 -> 0.01905 | U26: =+T26 -> 0.01905
O27: TOTALS | R27: =SUM(R4:R26) -> 4.20243 | S27: =SUM(S4:S26) -> 3.36423 | T27: =SUM(T4:T26) -> 0.4191 | U27: =SUM(U4:U26) -> 0.4191
N32: GUARDRAILS (LHS)
M34: REF No. | N34: KM MARKER | O34: KM START | P34: KM END | Q34: KM END | R34: TOTAL LENGTH (KM) | S34: STRAIGHT LENGTH (KM) | T34: APPROACH LENGTH (KM) | U34: DEPARTING LENGTH (KM) | V34: REMARKS
M35: 1 | N35: 56.33 | O35: 56.33 | P35: 56.343 | Q35: 55.7 | R35: 0.14478 | S35: =+R35-T35-U35 -> 0.14478 | T35: 0 | U35: =+T35 -> 0 | V35: End Wings
M36: 2 | N36: 56.619 | O36: 56.619 | P36: 56.763 | Q36: 56.343 | R36: 0.28575 | S36: =+R36-T36-U36 -> 0.24765 | T36: =1.905*10/1000 -> 0.01905 | U36: =+T36 -> 0.01905
M37: 3 | N37: 57.797 | O37: 57.797 | P37: 58.082 | Q37: 56.596 | R37: 0.20193 | S37: =+R37-T37-U37 -> 0.16383 | T37: =1.905*10/1000 -> 0.01905 | U37: =+T37 -> 0.01905
M38: 4 | N38: 58.344 | O38: 58.344 | P38: 58.547 | Q38: 57.752 | R38: 0.10287 | S38: =+R38-T38-U38 -> 0.06477 | T38: =1.905*10/1000 -> 0.01905 | U38: =+T38 -> 0.01905
M39: 5 | N39: 58.662 | O39: 58.662 | P39: 58.765 | Q39: 58.466 | R39: 0.2286 | S39: =+R39-T39-U39 -> 0.1905 | T39: =1.905*10/1000 -> 0.01905 | U39: =+T39 -> 0.01905
M40: 6 | N40: 59.593 | O40: 59.593 | P40: 59.822 | Q40: 59.585 | R40: 0.31242 | S40: =+R40-T40-U40 -> 0.27432 | T40: =1.905*10/1000 -> 0.01905 | U40: =+T40 -> 0.01905
M41: 7 | N41: 60.59 | O41: 60.59 | P41: 60.902 | Q41: 60.722 | R41: 0.46101 | S41: =+R41-T41-U41 -> 0.42291 | T41: =1.905*10/1000 -> 0.01905 | U41: =+T41 -> 0.01905
M42: 8 | N42: 61.861 | O42: 61.861 | P42: 62.321 | Q42: 62.125 | R42: 0.06096 | S42: =+R42-T42-U42 -> 0.02286 | T42: =1.905*10/1000 -> 0.01905 | U42: =+T42 -> 0.01905
M43: 9 | N43: 63.23 | O43: 63.23 | P43: 63.289 | Q43: 63.289 | R43: 0.19431 | S43: =+R43-T43-U43 -> 0.15621 | T43: =1.905*10/1000 -> 0.01905 | U43: =+T43 -> 0.01905
M44: 10 | N44: 64.905 | O44: 64.905 | P44: 65.101 | Q44: 64.258 | R44: 0.2286 | S44: =+R44-T44-U44 -> 0.1905 | T44: =1.905*10/1000 -> 0.01905 | U44: =+T44 -> 0.01905
M45: 11 | N45: 65.692 | O45: 65.692 | P45: 65.921 | Q45: 65.862 | R45: 0.22098 | S45: =+R45-T45-U45 -> 0.18288 | T45: =1.905*10/1000 -> 0.01905 | U45: =+T45 -> 0.01905
...

Sheet Road Marking
A1: ITEM | E1: DESCRIPTION | F1: UNIT | G1: QTY | H1: RATE | I1: AMOUNT
A2: C11.7 | E2: ROAD MARKINGS AND ROAD STUDS
A3: C11.7.2 | E3: Retro-reflective road marking: | V3: KM (Start) | W3: KM (End) | X3: Position | Y3: Lane/Centerline | AA3: Type | AC3: Width (m) | AE3: Length (m) | AG3: Area (m^2) | AI3: Material | AK3: Condition | AP3: KM (Start) | AQ3: KM (End) | AR3: Island ID | AT3: Height (m) | AU3: Width (m) | AW3: Area (m^2) | AY3: Material | BA3: Condition
B4: C11.7.2.1 | E4: White lines broken or unbroken (solvent based paint 100mm width) | F4: kilometre (km) | G4: =22*2.5 -> 55 | H4: 6500 | I4: =G4*H4 -> 357500 | V4: 44+000 | W4: 74+300 | X4: N2 | Y4: SBC | AA4: Yellow line | AC4: 0.1 | AE4: 22300 | AG4: =AC4*AE4 -> 2230 | AI4: Thermoplastic | AK4: Worn Out | AP4: 43+900 | AQ4: 44+027 | AR4: 1 | AT4: 79.6 | AU4: 6.01 | AW4: =0.5*AT4*AU4 -> 239.198 | AY4: Thermoplastic | BA4: Worn Out
B5: C11.7.2.2 | E5: Yellow lines broken or unbroken (solvent based paint 100mm width) | F5: kilometre (km) | G5: =AF64 -> 44.6 | H5: 6500 | I5: =G5*H5 -> 289900 | V5: 44+000 | W5: 74+300 | X5: N2 | Y5: NBC | AA5: Yellow line | AC5: 0.1 | AE5: 22300 | AG5: =AC5*AE5 -> 2230 | AI5: Thermoplastic | AK5: Worn Out | AP5: 46+700 | AQ5: 46+892 | AR5: 2 | AT5: 192.03 | AU5: 3.35 | AW5: =0.5*AT5*AU5 -> 321.65025 | AY5: Thermoplastic | BA5: Worn Out
B6: C11.7.2.4 | E6: White and yellow lettering and symbols (solvent based) | F6: square metre (m²) | G6: 200 | H6: 80 | I6: =G6*H6 -> 16000 | V6: 44+000 | W6: 44+022 | X6: Extending from on ramp | Y6: NBC | AA6: Dotted White | AC6: 0.1 | AE6: 22 | AG6: =AC6*AE6 -> 2.2 | AI6: Thermoplastic | AK6: Worn Out | AP6: 46+870 | AQ6: 46+893 | AR6: 3 | AT6: 22.74 | AU6: 14.79 | AW6: =0.5*AT6*AU6 -> 168.1623 | AY6: Thermoplastic | BA6: Worn Out
B7: C11.7.2.7 | E7: Transverse lines, painted island and arrestor bed markings (any colour) (paint type indicated) | F7: square metre (m²) | G7: =AW10 -> 1632.7568 | H7: 80 | I7: =G7*H7 -> 130620.54 | V7: 44+000 | W7: 44+075 | X7: N2 | Y7: SBC | AA7: Dotted White | AC7: 0.1 | AE7: 75 | AG7: =AC7*AE7 -> 7.5 | AI7: Thermoplastic | AK7: Worn Out | AP7: 55+650 | AQ7: 55+723 | AR7: 4 | AT7: 73.03 | AU7: 7.25 | AW7: =0.5*AT7*AU7 -> 264.73375 | AY7: Thermoplastic | BA7: Worn Out
A8: C11.7.3 | E8: Thermoplastic road marking | V8: 44+000 | W8: 44+290 | X8: N2 | Y8: Centerline | AA8: Solid Broken White Line | AC8: 0.1 | AE8: 290 | AG8: =AC8*AE8 -> 29 | AI8: Thermoplastic | AK8: Worn Out | AP8: 64+800 | AQ8: 64+873 | AR8: 5 | AT8: 73.03 | AU8: 8.25 | AW8: =0.5*AT8*AU8 -> 301.24875 | AY8: Thermoplastic | BA8: Worn Out
B9: C11.7.3.1 | E9: Thermoplastic road marking, broken or unbroken | V9: 44+298 | W9: 45+498 | X9: N2 | Y9: Centerline | AA9: Broken White Line | AC9: 0.1 | AE9: 1200 | AG9: =AC9*AE9 -> 120 | AI9: Thermoplastic | AK9: Worn Out | AP9: 65+600 | AQ9: 65+673 | AR9: 6 | AT9: 73.03 | AU9: 9.25 | AW9: =0.5*AT9*AU9 -> 337.76375 | AY9: Thermoplastic | BA9: Worn Out
C10: (a) | E10: White lines broken or unbroken 100mm width | F10: kilometre (km) | G10: =+G4 -> 55 | H10: 5500 | I10: =G10*H10 -> 302500 | V10: 45+498 | W10: 45+506 | X10: N2 | Y10: Centerline | AA10: Solid Broken White Line | AC10: 0.1 | AE10: 130 | AG10: =AC10*AE10 -> 13 | AI10: Thermoplastic | AK10: Worn Out | AW10: =SUM(AW4:AX9) -> 1632.7568
C11: (b) | E11: Yellow lines broken or unbroken 100mm width | F11: kilometre (km) | G11: =+G5 -> 44.6 | H11: 5500 | I11: =G11*H11 -> 245300 | V11: 45+520 | W11: 45+660 | X11: N2 | Y11: NBC | AA11: Broken White Line | AC11: 0.1 | AE11: 140 | AG11: =AC11*AE11 -> 14 | AI11: Thermoplastic | AK11: Worn Out
A12: C11.7.5 | E12: Variations in rate of application : | I12: =G12*H12 -> 0 | V12: 45+715 | W12: 45+739 | X12: N2 | Y12: Centerline | AA12: Solid White Line | AC12: 0.1 | AE12: 24 | AG12: =AC12*AE12 -> 2.4 | AI12: Thermoplastic | AK12: Worn Out
B13: C11.7.5.1 | E13: White paint | F13: litre (ℓ) | H13: 21 | I13: =G13*H13 -> 0 | V13: 45+741 | W13: 45+839 | X13: N2 | Y13: Centerline | AA13: Broken White Line | AC13: 0.1 | AE13: 98 | AG13: =AC13*AE13 -> 9.8 | AI13: Thermoplastic | AK13: Worn Out
B14: C11.7.5.2 | E14: Yellow paint | F14: litre (ℓ) | H14: 21 | I14: =G14*H14 -> 0 | V14: 45+979 | W14: 46+060 | X14: N2 | Y14: Centerline | AA14: Dual Soild Broken White Line | AC14: 0.1 | AE14: =81*2 -> 162 | AG14: =AC14*AE14 -> 16.2 | AI14: Thermoplastic | AK14: Worn Out
B15: C11.7.5.4 | E15: Retro-reflective beads | F15: kilogram (kg) | H15: 21 | I15: =G15*H15 -> 0 | V15: 45+060 | W15: 43+131 | X15: N2 | Y15: Centerline | AA15: Solid Broken White Line | AC15: 0.1 | AE15: 71 | AG15: =AC15*AE15 -> 7.1 | AI15: Thermoplastic | AK15: Worn Out
B16: C11.7.5.5 | E16: Thermoplastic material, all colours | F16: kilogram (kg) | H16: 21 | I16: =G16*H16 -> 0 | V16: 46+138 | W16: 46+488 | X16: N2 | Y16: Centerline | AA16: Broken White Line | AC16: 0.1 | AE16: 350 | AG16: =AC16*AE16 -> 35 | AI16: Thermoplastic | AK16: Worn Out
A17: C11.7.7 | E17: Road studs | V17: 46+495 | W17: 46+845 | X17: N2 | Y17: Centerline | AA17: Solid Broken White Line | AC17: 0.1 | AE17: 350 | AG17: =AC17*AE17 -> 35 | AI17: Thermoplastic | AK17: Worn Out
B18: C11.7.7.1 | E18: Permanent road studs compliant to SANS 1442 (100mm X 100mm x 20mm plastic stick on type with 43 bead glass reflectors - Bi-directional (any colour) | F18: number (No.) | G18: =+G10/18*1000*3 -> 9166.6667 | H18: 460 | I18: =G18*H18 -> 4216666.7 | V18: 46+845 | W18: 46+913 | X18: N2 | Y18: Centerline | AA18: Dual Soild Broken White Line | AC18: 0.1 | AE18: =68*2 -> 136 | AG18: =AC18*AE18 -> 13.6 | AI18: Thermoplastic | AK18: Worn Out
B19: C11.7.7.3 | E19: Temporary road studs compliant to SANS 1442 (100mm X 100mm x 20mm plastic stick on type with 43 bead glass reflectors - Bi-directional (any colour) | F19: number (No.) | G19: =+G18 -> 9166.6667 | H19: 200 | I19: =G19*H19 -> 1833333.3 | V19: 55+000 | W19: 55+040 | X19: N2 | Y19: Centerline | AA19: Broken White Line | AC19: 0.1 | AE19: 40 | AG19: =AC19*AE19 -> 4 | AI19: Thermoplastic | AK19: Worn Out
A20: C11.7.8 | E20: Setting out and premarking the lines (excluding traffic island markings, lettering and symbols) | F20: kilometre (km) | G20: =22*3*2 -> 132 | H20: 65 | I20: =G20*H20 -> 8580 | V20: 55+041 | W20: 55+391 | X20: N2 | Y20: Centerline | AA20: Solid Broken White Line | AC20: 0.1 | AE20: 350 | AG20: =AC20*AE20 -> 35 | AI20: Thermoplastic | AK20: Worn Out
A21: C11.7.9 | E21: Re-establishing the painting unit during the defects notification period and at other instances on instruction of the Engineer | F21: number (No.) | G21: 3 | H21: 18000 | I21: =G21*H21 -> 54000 | V21: 55+350 | W21: 55+510 | X21: Extending from on ramp | Y21: NBC | AA21: Broken White Line | AC21: 0.1 | AE21: 160 | AG21: =AC21*AE21 -> 16 | AI21: Thermoplastic | AK21: Worn Out
A22: C11.7.11 | E22: Removal of existing road studs | F22: number (No.) | G22: 9200 | H22: 30 | I22: =G22*H22 -> 276000 | V22: 55+516 | W22: 55+736 | X22: N2 | Y22: Centerline | AA22: Dual Soild Broken White Line | AC22: 0.1 | AE22: =220*2 -> 440 | AG22: =AC22*AE22 -> 44 | AI22: Thermoplastic | AK22: Worn Out
V23: 55+736 | W23: 56+136 | X23: N2 | Y23: Centerline | AA23: Solid Broken White Line | AC23: 0.1 | AE23: 400 | AG23: =AC23*AE23 -> 40 | AI23: Thermoplastic | AK23: Worn Out
H24: Total | I24: =SUM(I2:I22) -> 7730400.5 | V24: 56+142 | W24: 58+842 | X24: N2 | Y24: Centerline | AA24: Broken White Line | AC24: 0.1 | AE24: 2700 | AG24: =AC24*AE24 -> 270 | AI24: Thermoplastic | AK24: Worn Out
V25: 58+846 | W25: 59+082 | X25: N2 | Y25: Centerline | AA25: Solid Broken White Line | AC25: 0.1 | AE25: 240 | AG25: =AC25*AE25 -> 24 | AI25: Thermoplastic | AK25: Worn Out
V26: 59+090 | W26: 59+142 | X26: N2 | Y26: Centerline | AA26: Broken White Line | AC26: 0.1 | AE26: 52 | AG26: =AC26*AE26 -> 5.2 | AI26: Thermoplastic | AK26: Worn Out
V27: 59+149 | W27: 60+242 | X27: N2 | Y27: Centerline | AA27: Solid Broken White Line | AC27: 0.1 | AE27: 1100 | AG27: =AC27*AE27 -> 110 | AI27: Thermoplastic | AK27: Worn Out
V28: 59+349 | W28: 59+849 | X28: N2 | Y28: Centerline | AA28: Dual Soild Broken White Line | AC28: 0.1 | AE28: =550*2 -> 1100 | AG28: =AC28*AE28 -> 110 | AI28: Thermoplastic | AK28: Worn Out
V29: 60+248 | W29: 62+148 | X29: N2 | Y29: Centerline | AA29: Broken White Line | AC29: 0.1 | AE29: 1900 | AG29: =AC29*AE29 -> 190 | AI29: Thermoplastic | AK29: Worn Out
V30: 62+155 | W30: 62+805 | X30: N2 | Y30: Centerline | AA30: Solid Broken White Line | AC30: 0.1 | AE30: 650 | AG30: =AC30*AE30 -> 65 | AI30: Thermoplastic | AK30: Worn Out
V31: 62+455 | W31: 62+519 | X31: N2 | Y31: Centerline | AA31: Dual Soild Broken White Line | AC31: 0.1 | AE31: =64*2 -> 128 | AG31: =AC31*AE31 -> 12.8 | AI31: Thermoplastic | AK31: Worn Out
V32: 62+812 | W32: 63+613 | X32: N2 | Y32: Centerline | AA32: Broken White Line | AC32: 0.1 | AE32: 800 | AG32: =AC32*AE32 -> 80 | AI32: Thermoplastic | AK32: Worn Out
V33: 63+620 | W33: 64+470 | X33: N2 | Y33: Centerline | AA33: Solid Broken White Line | AC33: 0.1 | AE33: 850 | AG33: =AC33*AE33 -> 85 | AI33: Thermoplastic | AK33: Worn Out
V34: 64+020 | W34: 64+120 | X34: N2 | Y34: Centerline | AA34: Dual Soild Broken White Line | AC34: 0.1 | AE34: =100*2 -> 200 | AG34: =AC34*AE34 -> 20 | AI34: Thermoplastic | AK34: Worn Out
V35: 64+470 | W35: 64+870 | X35: N2 | Y35: Centerline | AA35: Broken White Line | AC35: 0.1 | AE35: 400 | AG35: =AC35*AE35 -> 40 | AI35: Thermoplastic | AK35: Worn Out
V36: 64+877 | W36: 66+270 | X36: N2 | Y36: Centerline | AA36: Solid Broken White Line | AC36: 0.1 | AE36: 1400 | AG36: =AC36*AE36 -> 140 | AI36: Thermoplastic | AK36: Worn Out
V37: 65+017 | W37: 65+207 | X37: Additional Lane | Y37: SBC | AA37: Broken White Line | AC37: 0.1 | AE37: 190 | AG37: =AC37*AE37 -> 19 | AI37: Thermoplastic | AK37: Worn Out
V38: 65+061 | W38: 65+107 | X38: Additional Lane | Y38: NBC | AA38: Broken White Line | AC38: 0.1 | AE38: 46 | AG38: =AC38*AE38 -> 4.6 | AI38: Thermoplastic | AK38: Worn Out
V39: 65+507 | W39: 65+206 | X39: N2 | Y39: Centerline | AA39: Dual Soild Broken White Line | AC39: 0.1 | AE39: =99*2 -> 198 | AG39: =AC39*AE39 -> 19.8 | AI39: Thermoplastic | AK39: Worn Out
V40: 65+386 | W40: 65+516 | X40: Extending from on ramp | Y40: NBC | AA40: Solid White Line | AC40: 0.1 | AE40: 130 | AG40: =AC40*AE40 -> 13 | AI40: Thermoplastic | AK40: Worn Out
...

Sheet Acc Traffic
A1: ITEM | E1: DESCRIPTION | F1: UNIT | G1: QTY | H1: RATE | I1: AMOUNT
A2: C1.5 | E2: ACCOMMODATION OF TRAFFIC
A3: C1.5.1 | E3: ACCOMMODATION OF PEDESTRIAN AND NON-MOTORISED TRAFFIC
B4: C1.5.1.1 | E4: Accommodation of pedestrian and non-motorised traffic | F4: month
A5: C1.5.2 | E5: Accommodation of vehicular traffic | F5: month | G5: 9 | H5: 25000 | I5: =G5*H5 -> 225000
A7: C1.5.3 | E7: Liaison with traffic authorities | F7: month | G7: 9 | H7: 5500 | I7: =G7*H7 -> 49500
A9: PC1.5.7 | E9: Temporary traffic control facilities
B10: C1.5.7.1 | E10: Delineators including mounting bases and ballast:
C11: (a) | E11: Single sided, reversible left or right
D12: (i) | E12: Size 250 mm x 800mm | F12: number (No) | G12: 0 | H12: 250 | I12: =G12*H12 -> 0
C13: (b) | E13: Double sided, reversible left or right
D14: (i) | E14: Size 250 mm x 800mm | F14: number (No) | G14: =F77 -> 1000 | H14: 180 | I14: =G14*H14 -> 180000
B16: C1.5.7.2 | E16: Traffic cones, minimum height 750mm | F16: number (No) | G16: 100 | H16: 325 | I16: =G16*H16 -> 32500
B18: C1.5.7.3 | E18: Flagmen | F18: man-shift | G18: =I68 -> 6510 | H18: 540 | I18: =G18*H18 -> 3515400
B20: C1.5.7.4 | E20: Traffic controllers | F20: man-shift | G20: 0 | H20: 350 | I20: =G20*H20 -> 0
B21: C1.5.7.5 | E21: Provision of illuminated traffic signs
C22: (a) | E22: Sign mounted amber flashing lights (2 lights with the specified power supply) mounted on a backing board which is:
D23: (ii) | E23: 1200mm wide x 200mm high | F23: Number (No) | G23: 6 | H23: 6500 | I23: =G23*H23 -> 39000
C24: (b) | E24: Flashing LED illuminated arrow board | F24: Number (No) | G24: 6 | H24: 4500 | I24: =G24*H24 -> 27000
C25: (c) | E25: Illuminated road sign – R & TR series (900 size) | F25: Number (No) | G25: =M28+M31+M33 -> 102 | H25: 1634 | I25: =G25*H25 -> 166668
C26: (d) | E26: Illuminated road sign – TW series (1200 size) | F26: Number (No) | G26: 0 | H26: 1765.2 | I26: =G26*H26 -> 0 | K26: Signs
C27: (g) | E27: Illuminated road sign – TW series (1 200 mm size) | F27: Number (No) | G27: 0 | H27: 580 | I27: =G27*H27 -> 0 | K27: TR Ref. | L27: No | M27: 3 Closures
B28: C1.5.7.6 | E28: Maintenance of illuminated traffic signs: | I28: =G28*H28 -> 0 | K28: TR214 | L28: 12 | M28: =L28*3 -> 36
C29: (a) | E29: Sign mounted flashing amber lights (a pair of two lights mounted on a separate backing board) | F29: month | G29: 9 | H29: 500 | I29: =G29*H29 -> 4500 | K29: TGS 107/108 | L29: 10 | M29: =L29*3 -> 30
C30: (b) | E30: Flashing LED illuminated arrow board | F30: month | G30: 9 | H30: 500 | I30: =G30*H30 -> 4500 | K30: TIN 11.3 | L30: 18 | M30: =L30*3 -> 54
C31: (c) | E31: Illuminated road sign – R & TR series (900 size) | F31: month | G31: 9 | H31: 500 | I31: =G31*H31 -> 4500 | K31: TR 201 -40 & 60 | L31: 16 | M31: =L31*3 -> 48
C32: (d) | E32: Illuminated road sign – TW series (1200 size) | F32: month | G32: 9 | H32: 500 | I32: =G32*H32 -> 4500 | K32: TW 336 | L32: 8 | M32: =L32*3 -> 24
C33: (g) | E33: Illuminated road sign – TG/TIN series | F33: month | G33: 9 | H33: 500 | I33: =G33*H33 -> 4500 | K33: TR104 | L33: 6 | M33: =L33*3 -> 18
B34: PC1.5.7.10 | E34: Moveable traffic signs | I34: =G34*H34 -> 0 | K34: TW411 | L34: 3 | M34: =L34*3 -> 9
C35: (a) | E35: Regulatory signs. Temporary | I35: =G35*H35 -> 0
D36: (i) | E36: R & TR series (900 diameter) | F36: number | G36: =M28+M31+M33 -> 102 | H36: 150 | I36: =G36*H36 -> 15300 | K36: Cones | L36: 10
C37: (b) | E37: Warning signs, temporary | I37: =G37*H37 -> 0
D38: (ii) | E38: TW series (1 200 mm size) | F38: number | G38: =M32+M34 -> 33 | H38: 150 | I38: =G38*H38 -> 4950
C39: (c) | E39: Portable STOP and GO-RY signs | F39: number | G39: 0 | H39: 150 | I39: =G39*H39 -> 0
C40: (d) | E40: Road signs, STW-, DTG-, TGS- AND TG-series (excluding delineators and barricades) | F40: number | G40: =M29 -> 30 | H40: 150 | I40: =G40*H40 -> 4500
C41: (e) | E41: Moveable barricade/road sign combination (8m wide chevron and road closed types) | F41: number | G41: 0 | H41: 150 | I41: =G41*H41 -> 0
C42: (f) | E42: TIN 11-3 (600m) | F42: number | G42: 0 | H42: 150 | I42: =G42*H42 -> 0
C43: (g) | E43: TIN 11-3 (400m) | F43: number | G43: =M30 -> 54 | H43: 150 | I43: =G43*H43 -> 8100
C44: (h) | E44: TIN 11-3 (200m) | F44: number | G44: 0 | H44: 150 | I44: =G44*H44 -> 0
C45: (i) | E45: TIN 11-4 (End/Thank you) | F45: number | G45: 0 | H45: 150 | I45: =G45*H45 -> 0
...

Sheet Road signs
A1: ITEM | E1: DESCRIPTION | F1: UNIT | G1: QTY | H1: RATE | I1: AMOUNT
A2: C11.6 | E2: ROAD SIGNS
A3: C11.6.1 | E3: Road signboards with painted or coloured semi-matt background. Symbols, lettering and borders in semi- matt black or in Class I retro-reflective material, where the sign board is constructed from:
B4: C11.6.1.3 | E4: Prepainetd Galvanised steel plate | F4: =0.2*0.2 -> 0.04
C5: (a) | E5: Area 0 to 0.5m² | F5: square metre (m²) | G5: 1.26 | H5: 650 | I5: =G5*H5 -> 819
C6: (b) | E6: Area exceeding 0.5m² but not 2.0m² | F6: square metre (m²) | G6: 46.24 | H6: 680 | I6: =G6*H6 -> 31443.2
C7: (c) | E7: Area exceeding 2m² but not 10m² | F7: square metre (m²) | G7: 31.87 | H7: 700 | I7: =G7*H7 -> 22309
C8: (d) | E8: Area exceeding 10m² | F8: square metre (m²) | G8: 10.16 | H8: 715 | I8: =G8*H8 -> 7264.4
B9: C11.6.1.8 | E9: Regulatory signs, temporary | I9: =G9*H9 -> 0
C10: (b) | E10: 900mm diameter (prepainted galvanised sheeting with class III retroreflective backgrounds and borders and semi matt symbols) | F10: number (No.) | H10: 650 | I10: =G10*H10 -> 0
B11: C11.6.1.9 | E11: Warning Signs, permanent | I11: =G11*H11 -> 0
C12: (c) | E12: 1200mm diameter (prepainted galvanised sheeting with class III retroreflective backgrounds and borders and semi matt symbols) | F12: number (No.) | G12: 24 | H12: 1200 | I12: =G12*H12 -> 28800
B13: C11.6.1.11 | E13: Supplementary plates to permanent regulatory or warning signs (prepainted galvanised sheeting with class III retroreflective backgrounds and borders and semi matt symbols) | F13: square metre (m²) | G13: 5.61 | H13: 1200 | I13: =G13*H13 -> 6732
A14: C11.6.2 | E14: Extra over on item C11.6.1 for using: | I14: =G14*H14 -> 0
B15: C11.6.2.1 | E15: Background of retro-reflective material: | I15: =G15*H15 -> 0
C16: (a) | E16: Class I | F16: square metre (m²) | H16: 650 | I16: =G16*H16 -> 0
B17: C11.6.2.2 | E17: Lettering, symbols, Nos, arrows, emblems and borders of retro-reflective material: | I17: =G17*H17 -> 0
C18: (b) | E18: Class III | F18: square metre (m²) | H18: 650 | I18: =G18*H18 -> 0
A19: C11.6.3 | E19: Road sign supports (overhead road sign structures excluded) | I19: =G19*H19 -> 0
B20: C11.6.3.1 | E20: Steel tubing (150Ø ) | F20: ton (t) | H20: 3500 | I20: =G20*H20 -> 0
B21: C11.6.3.2 | E21: Timber (150Ø and CCA treated) | F21: metre (m) | G21: 236 | H21: 150 | I21: =G21*H21 -> 35400
A22: C11.6.5 | E22: Excavation and backfilling for road sign supports (not applicable for kilometer posts) | I22: =G22*H22 -> 0
B23: C11.6.5.1 | E23: Excavating soft material and backfilling | F23: cubic metre (m³) | G23: 40 | H23: 125 | I23: =G23*H23 -> 5000
B24: C11.6.5.2 | E24: Extra over on item C11.6.5.1 for hard material excavation | F24: cubic metre (m³) | G24: 4 | H24: 900 | I24: =G24*H24 -> 3600
A25: C11.6.10 | E25: Disposing of road signs with surface area of: | I25: =G25*H25 -> 0
B26: C11.6.10.1 | E26: Area 0 to 0.5m² | F26: square metre (m²) | G26: 1.26 | H26: 60 | I26: =G26*H26 -> 75.6
B27: C11.6.10.2 | E27: Area exceeding 0.5m² but not 2.0m² | F27: square metre (m²) | G27: 70.24 | H27: 60 | I27: =G27*H27 -> 4214.4
B28: C11.6.10.3 | E28: Area exceeding 2.0m² but not 10.0m² | F28: square metre (m²) | G28: 31.87 | H28: 60 | I28: =G28*H28 -> 1912.2
B29: C11.6.10.4 | E29: Area exceeding 10m² | F29: square metre (m²) | G29: 10.16 | H29: 60 | I29: =G29*H29 -> 609.6
H31: Total | I31: =SUM(I4:I30) -> 148179.4

Sheet Overlay
A1: ITEM | E1: DESCRIPTION | F1: UNIT | G1: QTY | H1: RATE | I1: AMOUNT
A2: C9.1 | E2: ASPHALT LAYERS
A3: C9.1.1 | E3: Asphalt mix designs
B4: C9.1.1.2 | E4: Sand skeletal mix:
C5: (a) | E5: Continuously graded base or surfacing (PG58E-22,Level II mix design) | F5: lump sum | G5: 1 | H5: 150000 | I5: =G5*H5 -> 150000
A6: C9.1.2 | E6: Construction of trial sections
B7: C9.1.2.1 | E7: Asphalt layers (sand skeletal (continuosly graded) utilising an PG58E-22 binder with a maximum binder replacement of 15%, 50mm, paver placed) | F7: square metre (m²) | G7: =(240/0.05)/2.5 -> 1920 | H7: 212 | I7: =G7*H7 -> 407040
A8: C9.1.3 | E8: Application of bond coat
B9: C9.1.3.1 | E9: Stable–grade 30% net bitumen emulsion as specified. Applied with a calibrated distributer | F9: litre (ℓ) | G9: =G40 -> 155765.5 | H9: 13 | I9: =G9*H9 -> 2024951.5
B10: C9.3.1.3 | E10: Applied by hand using brushes on all exposed transverse and longitudinal construction joints | F10: litre (ℓ) | G10: 200 | H10: 21 | I10: =G10*H10 -> 4200
A11: C9.1.5 | E11: Asphalt surfacing
B12: C9.1.5.2 | E12: Rehabilitation
C13: (e ) | E13: Sand skeletal mix – continuously graded as defined (50mm, PG58E-22 utilising a maximum binder replacement of 15%, Level II mix design, paver placed) | F13: ton (t) | G13: =J44 -> 41441.375 | H13: 1380 | I13: =G13*H13 -> 57189098
A14: C9.1.9 | E14: Application of Rolled in chips
B15: C9.1.9.1 | E15: By means of a chip spreader | F15: square metre (m²) | G15: 0 | H15: 15 | I15: =G15*H15 -> 0
A16: C9.1.10 | E16: Variation rates
B17: C9.1.10.1 | E17: Bitumen (PG58E-22) | F17: ton (t) | H17: 3000 | I17: =G17*H17 -> 0
B18: C9.1.10.2 | E18: Aggregate | F18: ton (t) | H18: 3000 | I18: =G18*H18 -> 0
B19: C9.1.10.3 | E19: Active filler (lime unless stated in Contract Document) | F19: ton (t) | H19: 3500 | I19: =G19*H19 -> 0
A20: C9.1.13 | E20: Coring of asphalt layers
B21: C9.1.13.1 | E21: 100mm diameter | F21: number (No.) | G21: 0 | H21: 300 | I21: =G21*H21 -> 0
A22: C9.1.14 | E22: Surface regularity testing as described in Clause A9.1.8.4
B23: C9.1.14.1 | E23: Establishment of equipment: Inertial laser Profilometer | F23: number (No.) | G23: 1 | H23: 35000 | I23: =G23*H23 -> 35000
B24: C9.1.14.2 | E24: Profiler Surveys utilising equipment as specified - Base layers and surfacing layers | F24: lane kilometre (km) | G24: =22.3*2 -> 44.6 | H24: 3500 | I24: =G24*H24 -> 156100
H27: Total | I27: =SUM(I2:I25) -> 59966389
F35: Bond coat | I35: Asphalt surfacing | L35: Based on m²
F36: Length | G36: 22300 | I36: Length | J36: 22300 | L36: 22300 | N36: 50 | O36: mm
F37: Width | G37: 12.7 | I37: Width | J37: 12.7 | L37: 12.7 | N37: 45 | O37: mm
F38: Area | G38: =G36*G37 -> 283210 | I38: Area | J38: =J36*J37 -> 283210 | L38: =L36*L37 -> 283210 | N38: =(N36-N37)/N36 -> 0.1
F39: spray rate | G39: 0.55 | I39: Thickness | J39: 0.05
F40: litre (ℓ) | G40: =G38*G39 -> 155765.5 | I40: conv. Factor | J40: 2.5
J41: =J38*J39*J40 -> 35401.25 | Q41: =J38*J39 -> 14160.5 | R41: m³ | S41: =Q41/J39 -> 283210 | T41: m² | U41: Road
I42: 10% Allowence for thickness variations | J42: =J41*10% -> 3540.125
I43: Allowence for ramps | J43: 2500 | L43: 16790 | Q43: =J43/J40 -> 1000 | R43: m³ | S43: =839.5/J39 -> 16790 | T43: m² | U43: Ramps
I44: Tons | J44: =J41+J42+J43 -> 41441.375 | L44: =L43+L42+L38 -> 300000
J46: =J44*2466 -> 1.0219443e+08 | Q46: =Q43+Q42+Q41 -> 15160.5 | R46: m³ | S46: =S41+S43 -> 300000 | T46: m²
Q47: =Q46/J39 -> 303210 | R47: m²

Sheet Water-cutting
A1: ITEM | E1: DESCRIPTION | F1: UNIT | G1: QTY | H1: RATE | I1: AMOUNT
A2: C8.9 | E2: REPAIR OF SURFACE DEFECTS
A4: C8.9.5 | E4: Water Cutting
B5: C8.9.5.1 | E5: Establishing of water cutting equipment on site | F5: lump sum | G5: 1 | H5: 100000 | I5: =G5*H5 -> 100000
B6: C8.9.5.2 | E6: Applying herbicides for sealing cracks | F6: square metre (m²) | G6: =G16 -> 34950 | H6: 38 | I6: =G6*H6 -> 1328100
A7: C8.9.6 | E7: Trail sections for water cutting | F7: square metre (m²) | G7: 150 | H7: 350 | I7: =G7*H7 -> 52500
H8: Total | I8: =SUM(I2:I7) -> 1480600
F12: Length | G12: 23300
F13: Width | G13: 1
F14: Lane / pulls | G14: 1.5
G16: =G12*G13*G14 -> 34950

Sheet Drains
A1: ITEM | E1: DESCRIPTION | F1: UNIT | G1: QTY | H1: RATE | I1: AMOUNT | K1: QTY | L1: RATE | M1: AMOUNT
A2: C3.1 | E2: DRAINS
A3: C3.1.1 | E3: Excavation for open drain
C4: (a) | E4: 0m - 1.5m | F4: cubic metre (m³) | G4: 990 | H4: 105 | I4: =G4*H4 -> 103950 | K4: 0 | L4: 105 | M4: =K4*L4 -> 0 | N4: No new unlined drains required
I5: =G5*H5 -> 0 | M5: =K5*L5 -> 0
B6: C3.1.2.1 | E6: Clearing, shaping and disposal of accumulated sediment in existing unlined open drains | I6: =G6*H6 -> 0 | M6: =K6*L6 -> 0
B7: C3.1.2.1 | E7: Using conventional methods | F7: cubic metre (m³) | G7: 1930 | H7: 105 | I7: =G7*H7 -> 202650 | K7: 0 | L7: 105 | M7: =K7*L7 -> 0 | N7: May not be required
I8: =G8*H8 -> 0 | M8: =K8*L8 -> 0
A9: C3.1.3 | E9: Excavation, clearing and disposal of accumulated sediment in existing lined drains and drainage systems | I9: =G9*H9 -> 0 | M9: =K9*L9 -> 0
B10: C3.1.3.1 | E10: Using conventional methods (up to 1,5m): | I10: =G10*H10 -> 0 | M10: =K10*L10 -> 0
C11: (a) | E11: Manholes and inlet and outlet structures | F11: cubic metre (m³) | G11: 200 | H11: 190 | I11: =G11*H11 -> 38000 | K11: =1.2*1.2*1*30 -> 43.2 | L11: 190 | M11: =K11*L11 -> 8208 | N11: 1,2mX1,2mX1.0mX30no.
C12: (b) | E12: Culvert barrels | F12: cubic metre (m³) | G12: 540 | H12: 190 | I12: =G12*H12 -> 102600 | K12: 540 | L12: 190 | M12: =K12*L12 -> 102600 | N12: Unknown at this stage
C13: (c) | E13: (c)Concrete or other lined side drains | F13: cubic metre (m³) | G13: 1930 | H13: 190 | I13: =G13*H13 -> 366700 | K13: =22300*2*1*0.075*0.5 -> 1672.5 | L13: 190 | M13: =K13*L13 -> 317775 | N13: Assumed - 22300mX2no. X1.0mX0,075m*50%
I14: =G14*H14 -> 0 | M14: =K14*L14 -> 0
A15: C3.1.4 | E15: Excavation and disposal of material for subsoil drainage systems: | I15: =G15*H15 -> 0 | M15: =K15*L15 -> 0
B16: C3.1.4.1 | E16: Excavating in all materials situated within the following depth ranges below the surface: | I16: =G16*H16 -> 0 | M16: =K16*L16 -> 0
C17: (a) | E17: 0m to 1.5m | F17: cubic metre (m³) | G17: 2460 | H17: 190 | I17: =G17*H17 -> 467400 | K17: =+K25*0.42 -> 911.4 | L17: 190 | M17: =K17*L17 -> 173166 | N17: There is only sufficient concrete for 2170m of 1.0m wide drain
A18: C3.1.5 | E18: Impermeable backfilling to subsoil drainage system | I18: =G18*H18 -> 0 | M18: =K18*L18 -> 0
B19: C3.1.5.1 | E19: Unstabilised natural gravel obtained from approved source on the site | F19: cubic metre (m³) | G19: 1720 | H19: 75 | I19: =G19*H19 -> 129000 | K19: 0 | L19: 75 | M19: =K19*L19 -> 0
A20: C3.1.7 | E20: Natural permeable material in subsoil drainage systems | I20: =G20*H20 -> 0 | M20: =K20*L20 -> 0
B21: C3.1.7.2 | E21: Crushed stone obtained from commercial sources | F21: cubic metre (m³) | G21: 500 | H21: 650 | I21: =G21*H21 -> 325000 | K21: =+K25*0.12 -> 260.4 | L21: 650 | M21: =K21*L21 -> 169260 | N21: There is only sufficient concrete for 2170m of 1.0m wide drain
A22: C3.1.8 | E22: Natural permeable material in subsoil drainage systems (approved natural sand): | I22: =G22*H22 -> 0 | M22: =K22*L22 -> 0
B23: C3.1.8.2 | E23: Natural sand from commercial sources | F23: cubic metre (m³) | G23: 250 | H23: 650 | I23: =G23*H23 -> 162500 | K23: =+K25*0.3 -> 651 | L23: 650 | M23: =K23*L23 -> 423150 | N23: There is only sufficient concrete for 2170m of 1.0m wide drain
A24: C3.1.9 | E24: Pipes in subsoil drainage systems: | I24: =G24*H24 -> 0 | M24: =K24*L24 -> 0
B25: C3.1.9.1 | E25: U-PVC pipes and fittings, normal duty, complete with couplings | F25: metre (m) | G25: 6132.5 | H25: 65 | I25: =G25*H25 -> 398612.5 | K25: 2170 | L25: 65 | M25: =K25*L25 -> 141050 | N25: There is only sufficient concrete for 2170m of 1.0m wide drain
A26: C3.1.11 | E26: Geotextiles (A1) | I26: =G26*H26 -> 0 | M26: =K26*L26 -> 0
B27: C3.1.11.1 | E27: 0.15mm thick | F27: square metre (m²) | G27: 8590 | H27: 35 | I27: =G27*H27 -> 300650 | K27: =+K25*1.87 -> 4057.9 | L27: 35 | M27: =K27*L27 -> 142026.5 | N27: There is only sufficient concrete for 2170m of 1.0m wide drain
A28: C3.1.13 | E28: Concrete outlet structures, manhole boxes, junction boxes and cleaning eyes for subsoil drainage systems | I28: =G28*H28 -> 0 | M28: =K28*L28 -> 0
B29: C3.1.13.4 | E29: Cleaning eyes | F29: number (No.) | G29: 60 | H29: 1450 | I29: =G29*H29 -> 87000 | K29: 4 | L29: 1450 | M29: =K29*L29 -> 5800 | N29: Assumed 4 drains are going to be installed
A30: C3.1.14 | E30: Caps for subsoil drain pipes | I30: =G30*H30 -> 0 | M30: =K30*L30 -> 0
B31: C3.1.14.3 | E31: Other (PVC) | F31: number (No.) | G31: 60 | H31: 185 | I31: =G31*H31 -> 11100 | K31: 8 | L31: 185 | M31: =K31*L31 -> 1480 | N31: Assumed 4 drains are going to be installed. Existing Rodding Eyes not found
A32: C3.1.15 | E32: Repairing or replacing existing drainage systems | F32: provisional sum | G32: 1 | H32: 100000 | I32: =G32*H32 -> 100000 | K32: 1 | L32: 100000 | M32: =K32*L32 -> 100000
A33: C3.1.22 | E33: Test flushing of subsoil drain pipe system | F33: number (No.) | G33: 60 | H33: 350 | I33: =G33*H33 -> 21000 | K33: 4 | L33: 350 | M33: =K33*L33 -> 1400 | N33: Assumed 4 drains are going to be installed. Existing Rodding Eyes not found
A34: C3.1/C1.7.2.2 | E34: Hauling material to spoil and off-loading it at a designated spoil or stockpile area: | I34: =G34*H34 -> 0 | M34: =K34*L34 -> 0
C35: (a) | E35: Cleared and grubbed material (organic matter and all other unsuitable or waste material) | F35: cubic metre - kilometre (m³.km) | G35: 92000 | H35: 7 | I35: =G35*H35 -> 644000 | K35: =(+K7+K11+K12+K13)*25 -> 56392.5 | L35: 7 | M35: =K35*L35 -> 394747.5 | N35: Above qty over a 25km haul distance
H37: Toat | I37: =SUM(I3:I35) -> 3460162.5 | L37: Toat | M37: =SUM(M3:M35) -> 1980663

Sheet Kerbs_conc drains
B1: ITEM | F1: DESCRIPTION | G1: UNIT | H1: SCHEDULED QTY | I1: RATE R | J1: SCHEDULED AMOUNT
B2: C3.3 | F2: CONCRETE KERBING AND CHANNELING, ASPHALT BERMS, CHUTES, DOWNPIPES, AS WELL AS CONCRETE, STONE PITCHED AND GABION LININGS FOR OPEN DRAINS
B4: C3.3.8 | F4: Linings for open drains:
C5: C3.3.8.1 | F5: Cast in situ concrete lining (Class 20/19 for open drains) as per drawing contained in Appendix 15 | G5: square metre (m²) | H5: =+G20*0.129 -> 279.93 | I5: 2100 | J5: =IFERROR(IF(AND($G5<>"",$H5<>""),$H5*$I5,""),0) -> 587853
C6: C3.3.8.2 | F6: ClassU2 surface finish to cast in situ concrete (Open Drains) | G6: square metre (m²) | H6: =+G20*1.03 -> 2235.1 | I6: 140 | J6: =IFERROR(IF(AND($G6<>"",$H6<>""),$H6*$I6,""),0) -> 312914
B7: C3.3.9 | F7: Formwork to cast in situ concrete lining for open drains (Class F2 surface finish):
C8: C3.3.9.1 | F8: To sides with formwork on the internal face only | G8: square metre (m²) | H8: =+G20*2*0.125 -> 542.5 | I8: 430 | J8: =IFERROR(IF(AND($G8<>"",$H8<>""),$H8*$I8,""),0) -> 233275
C9: C3.3.9.3 | F9: To ends of slabs | G9: square metre (m²) | H9: =(+G20/3*1.03*0.125) -> 93.129167 | I9: 430 | J9: =IFERROR(IF(AND($G9<>"",$H9<>""),$H9*$I9,""),0) -> 40045.542
B10: C3.3.10 | F10: Sealed joints in concrete and stone pitched linings of open drains ((Polysulphide sealant) at 12m centres - Appendix 15) | G10: metre (m) | H10: =((+G20/12)+1)*1.03 -> 187.28833 | I10: 65 | J10: =IFERROR(IF(AND($G10<>"",$H10<>""),$H10*$I10,""),0) -> 12173.742
B11: C3.3.12 | F11: Reinforcement:
C12: C3.3.12.3 | F12: Welded steel fabric (REF 193) | G12: kilogram (kg) | H12: =+G20*1.03*1.93 -> 4313.743 | I12: 75 | J12: =IFERROR(IF(AND($G12<>"",$H12<>""),$H12*$I12,""),0) -> 323530.72
J15: =IFERROR(IF(AND($G15<>"",$H15<>""),$H15*$I15,""),0)
B16: TOTAL CARRIED FORWARD TO SUMMARY | J16: =SUM(J5:J15) -> 1509792
I17: Billed | J17: 3657850
J18: =+J16-J17 -> -2148058
A20: 0 | F20: Assumed length of Type E drain = | G20: 2170 | H20: m

Sheet Patching
A1: ITEM | E1: DESCRIPTION | F1: UNIT | G1: QTY | H1: RATE | I1: AMOUNT
A2: C8.8 | E2: PATCHING AND EDGE BREAK REPAIR
A3: C8.8.1 | E3: Saw cutting pavement layers for patching
B4: C8.8.1.1 | E4: Asphalt or bituminous surfacing to an average depth
C5: (a) | E5: Not exceeding 50mm | F5: metre (m) | G5: 7000 | H5: 56 | I5: =G5*H5 -> 392000
B6: C8.8.1.3 | E6: Granular layers to an average depth
C7: (b) | E7: Not exceeding 200mm | F7: metre (m) | G7: 7000 | H7: 56 | I7: =G7*H7 -> 392000
A8: C8.8.2 | E8: Excavation in existing pavements for patching (non-milling)
B9: C8.8.2.3 | E9: Crushed Stone layers
C10: (b) | E10: Not exceeding 10 m² including for edge repairs wider than 250mm | F10: cubic metre (m³) | G10: 1090 | H10: 340 | I10: =G10*H10 -> 370600
C11: (c) | E11: Not exceeding 50 m² up to 100m² including for edge repairs wider than 250mm | F11: cubic metre (m³) | G11: 90 | H11: 340 | I11: =G11*H11 -> 30600
C12: (d) | E12: Exceeding 100m² | F12: cubic metre (m³) | G12: 1090 | H12: 340 | I12: =G12*H12 -> 370600
B13: C8.8.2.4 | E13: Asphalt layers
C14: (b) | E14: Not exceeding 10 m² including for edge repairs wider than 250mm | F14: cubic metre (m³) | G14: 200 | H14: 340 | I14: =G14*H14 -> 68000
C15: (c) | E15: Not exceeding 50 m² up to 100m² including for edge repairs wider than 250mm | F15: cubic metre (m³) | G15: 20 | H15: 340 | I15: =G15*H15 -> 6800
C16: (d) | E16: Exceeding 100m² | F16: cubic metre (m³) | G16: 200 | H16: 340 | I16: =G16*H16 -> 68000
A17: C8.8.3 | E17: Compacting the floor of excavations for patching (Compacted to 95% MDD) | F17: square metre (m2) | G17: 12000 | H17: 45 | I17: =G17*H17 -> 540000
A18: C8.8.4 | E18: Backfilling of excavations for patching with:
B19: C8.8.4.3 | E19: Asphalt for a patch with a surface area (sand skelatal (congtinuosly graded) utilising a PG58E-22 binder utilisinga maximum binder replacement of 15%, compacted to 97% -% design voids of MVD
C20: (b) | E20: Not exceeding 10 m² including for edge repairs wider than 250mm | F20: ton (t) | G20: 2900 | H20: 1000 | I20: =G20*H20 -> 2900000
C21: (c) | E21: Not exceeding 50 m² up to 100m² including for edge repairs wider than 250mm | F21: ton (t) | G21: 230 | H21: 1000 | I21: =G21*H21 -> 230000
C22: (d) | E22: Exceeding 100m² | F22: ton (t) | G22: 2900 | H22: 1000 | I22: =G22*H22 -> 2900000
H24: Toat | I24: =SUM(I4:I22) -> 8268600

Sheet Clear and Grub
A2: ITEM | E2: DESCRIPTION | F2: UNIT | G2: QTY | H2: RATE | I2: AMOUNT
A3: C1.6 | E3: CLEARING AND GRUBBING
A4: C1.6.1 | E4: CLEARING
B5: C1.6.1.1 | E5: Clearing with machines and some hard labour where necessary | F5: hectare (ha) | G5: =G24 -> 4.46 | H5: 16500 | I5: =G5*H5 -> 73590
A6: C1.6.2 | E6: GRUBBING
B7: C1.6.2.1 | E7: Grubbing with machines and some hard labour where necessary | F7: hectare (ha) | G7: =G24 -> 4.46 | H7: 18000 | I7: =G7*H7 -> 80280
A8: C1.6/C1.7.2 | E8: HAULING
A9: C1.6/C1.7.2.1 | E9: Hauling material to spoil and off-loading it at a designated spoil or stockpile area:
C10: (a) | E10: Cleared and grubbed material (organic matter and all other unsuitable or waste material) | F10: cubic metre - kilometre (m³.km) | G10: =G22 -> 111500 | H10: 7 | I10: =G10*H10 -> 780500
H12: Toat | I12: =SUM(I5:I10) -> 934370
G14: Subcontractors | H14: 6 | I14: =I12/H14 -> 155728.33
F16: Length | G16: =22300*2 -> 44600
F17: Width | G17: 1
F18: Area | G18: =G16*G17 -> 44600
F19: Thickness | G19: =0.1 -> 0.1
F20: Volume | G20: =G18*G19 -> 4460
F21: Distance | G21: 25 | H21: Assumed Avarage
F22: Est. Haul | G22: =G20*G21 -> 111500
F24: Clearing in ha | G24: =G18/10000 -> 4.46
