Workbook
Name _sec12: #REF!
Name _sec12: #REF!
Name _sec12: #REF!
Name _SEC1200: #REF!
Name _SEC1200: #REF!
Name _SEC1200: #REF!
Name Evaluation: #REF!
Name Evaluation: #REF!
Name Evaluation: #REF!
Name Tender: #REF!
Name Tender: #REF!
Name Tender: #REF!

Sheet Schedule A Summary
B1: SCHEDULE A: ROADWORKS
B2: SUMMARY OF SCHEDULE OF QUANTITIES
B4: SCHEDULE | C4: SECTION | D4: TOTAL | E4: TOTAL | F4: TOTAL
C6: SERIES 1000 : GENERAL
B8: 1200 | C8: General requirements and provisions | D8: ='Schedule A Roadworks'!I67 -> 709590 | E8: ='Schedule A Roadworks'!L67 -> 858090 | F8: ='Schedule A Roadworks'!O67 -> 735214.09
B10: 1300 | C10: Contractor's establishment on site and general obligations | D10: ='Schedule A Roadworks'!I134 -> 990000 | E10: ='Schedule A Roadworks'!L134 -> 3775373.1 | F10: ='Schedule A Roadworks'!O134 -> 3775379.2 | G10: ='[1]Schedule A Summary'!$D$10 -> 4238050.6 | H10: =F10-G10 -> -462671.43
B12: 1400 | C12: Housing, offices and laboratories for the engineer's site personnel | D12: ='Schedule A Roadworks'!I268 -> 1199500 | E12: ='Schedule A Roadworks'!L268 -> 827084.84 | F12: ='Schedule A Roadworks'!O268 -> 817000 | I12: 815500 | J12: =E12-I12 -> 11584.84
B14: 1500 | C14: Accommodation of traffic | D14: ='Schedule A Roadworks'!I336 -> 944200 | E14: ='Schedule A Roadworks'!L336 -> 1493946 | F14: ='Schedule A Roadworks'!O336 -> 1338138
B16: 1700 | C16: Clearing and grubbing | D16: ='Schedule A Roadworks'!I403 -> 87400 | E16: ='Schedule A Roadworks'!L403 -> 98260 | F16: ='Schedule A Roadworks'!O403 -> 98260
B18: 1800 | C18: Dayworks | D18: ='Schedule A Roadworks'!I471 -> 1430000 | E18: ='Schedule A Roadworks'!L471 -> 1430000 | F18: ='Schedule A Roadworks'!O471 -> 1365000
C20: SERIES 2000 : DRAINAGE
E21: ='Schedule A Roadworks'!L80
B22: 2100 | C22: Drains | D22: ='Schedule A Roadworks'!I539 -> 168925 | E22: ='Schedule A Roadworks'!L539 -> 728072.5 | F22: ='Schedule A Roadworks'!O539 -> 472497.5
E23: ='Schedule A Roadworks'!L82
B24: 2200 | C24: Prefabricated culverts | D24: ='Schedule A Roadworks'!I679 -> 468700 | E24: ='Schedule A Roadworks'!L679 -> 517375 | F24: ='Schedule A Roadworks'!O679 -> 517375 | G24: ='[1]Schedule A Summary'!$D$24 -> 517375 | H24: =F24-G24 -> 0
E25: ='Schedule A Roadworks'!L84
B26: 2300 | C26: Concrete kerbing, concrete channelling, chutes and downpipes, and concrete linings for open drains | D26: ='Schedule A Roadworks'!I816 -> 3827743 | E26: ='Schedule A Roadworks'!L816 -> 3876832.2 | F26: ='Schedule A Roadworks'!O816 -> 3389991 | I26: 3891832.2 | J26: =E26-I26 -> -15000
E27: ='Schedule A Roadworks'!L86
C28: SERIES 3000 : EARTHWORKS AND PAVEMENT LAYERS OF GRAVEL OR CRUSHED STONE
E29: ='Schedule A Roadworks'!L88
B30: 3100 | C30: Borrow Material | D30: ='Schedule A Roadworks'!I884 -> 92000 | E30: ='Schedule A Roadworks'!L884 -> 104900 | F30: ='Schedule A Roadworks'!O884 -> 104900 | G30: ='[1]Schedule A Summary'!$D$30 -> 104900 | H30: =F30-G30 -> 0
E31: ='Schedule A Roadworks'!L90
B32: 3300 | C32: Mass earthworks | D32: ='Schedule A Roadworks'!I951 -> 1181480 | E32: ='Schedule A Roadworks'!L951 -> 2528420 | F32: ='Schedule A Roadworks'!O951 -> 1807820
E33: ='Schedule A Roadworks'!L92
B34: 3400 | C34: Pavement layers of gravel material | D34: ='Schedule A Roadworks'!I1019 -> 341460 | E34: ='Schedule A Roadworks'!L1019 -> 1080981.5 | F34: ='Schedule A Roadworks'!O1019 -> 914381.5
E35: ='Schedule A Roadworks'!L94
B36: 3500 | C36: Stabilization | D36: ='Schedule A Roadworks'!I1087 -> 216580 | E36: ='Schedule A Roadworks'!L1087 -> 266560 | F36: ='Schedule A Roadworks'!O1087 -> 241570
E37: ='Schedule A Roadworks'!L96
B38: 3600 | C38: Crushed stone base | D38: ='Schedule A Roadworks'!I1155 -> 2648145 | E38: ='Schedule A Roadworks'!L1155 -> 995340 | F38: ='Schedule A Roadworks'!O1155 -> 1444883.9
E39: ='Schedule A Roadworks'!L98
C40: SERIES 4000 : ASPHALT PAVEMENTS AND SEALS | E40: ='Schedule A Roadworks'!L99
E41: ='Schedule A Roadworks'!L100
B42: 4100 | C42: Prime Coat | D42: ='Schedule A Roadworks'!I1223 -> 361808 | E42: ='Schedule A Roadworks'!L1223 -> 702288.64 | F42: ='Schedule A Roadworks'!O1223 -> 683888.64 | I42: 702410.75 | J42: =E42-I42 -> -122.11
E43: ='Schedule A Roadworks'!L102
B44: 4200 | C44: Asphalt Base and Surfacing | D44: ='Schedule A Roadworks'!I1290 -> 12294600 | E44: ='Schedule A Roadworks'!L1290 -> 5426178 | F44: ='Schedule A Roadworks'!O1290 -> 9386178 | I44: 5426138.4
E45: ='Schedule A Roadworks'!L104
C46: SERIES 5000 : ANCILLARY ROADWORKS | E46: ='Schedule A Roadworks'!L105
E47: ='Schedule A Roadworks'!L106
B48: 5100 | C48: Pitching, stonework and protection against erosion | D48: ='Schedule A Roadworks'!I1357 -> 385000 | E48: ='Schedule A Roadworks'!L1357 -> 660000 | F48: ='Schedule A Roadworks'!O1357 -> 335000
E49: ='Schedule A Roadworks'!L108
...

Sheet Schedule A Roadworks
B1: SCHEDULE A : ROADWORKS
B2: SCHEDULE OF QUANTITIES | G2: T2 Tech | J2: TM&S Original rates | M2: TM&S Proposed rates | P2: Difference in | Q2: Difference in
P3: Rates | Q3: Value
B4: Item | C4: Description | D4: Description | F4: Unit | G4: Scheduled | J4: Scheduled | M4: Scheduled
B5: No | G5: Quantity | H5: Rate | I5: Value | J5: Quantity | K5: Rate | L5: Value | M5: Quantity | N5: Rate | O5: Value | P5: Value | Q5: Value
B7: 1200 | C7: GENERAL REQUIREMENTS AND PROVISIONS
I8: =IF(G8=0," ",G8*H8) | L8: =IF(J8=0," ",J8*K8) | O8: =IF(M8=0," ",M8*N8) | P8: =IF(N8=0," ",N8*O8)
B9: B12.01 | C9: Training:
C10: a) | D10: CETA accredited training | F10: Prov Sum | G10: 0 | H10: 100000 | I10: =G10*H10 -> 0 | J10: 0 | K10: 100000 | L10: =K10 -> 100000 | M10: 0 | N10: 100000 | O10: =M10*N10 -> 0 | P10: =K10-N10 -> 0 | Q10: =L10-O10 -> 100000 | R10: TC balancing original rate on training provision
C12: b) | D12: Handling cost and profit in respect of B12.01 a) above | F12: % | G12: =G10 -> 0 | H12: 0.1 | I12: =IF(G12=0," ",G12*H12) | J12: =J10 -> 0 | K12: 0.1 | L12: =L10*K12 -> 10000 | M12: =M10 -> 0 | N12: 0.1 | O12: =O10*N12 -> 0 | Q12: =L12-O12 -> 10000 | R12: TC balancing original rate
B14: L B12.02 | C14: Excavation for services:
C15: a) | D15: Excavation in search of existing services in soft material
D16: situated within the following depth ranges below the
D17: surface level:
D18: i) | E18: 0m to 2m | F18: m3 | G18: 300 | H18: 95 | I18: =IF(G18=0," ",G18*H18) -> 28500 | J18: 300 | K18: 95 | L18: =IF(J18=0," ",J18*K18) -> 28500 | M18: 300 | N18: 95 | O18: =IF(M18=0," ",M18*N18) -> 28500 | P18: =K18-N18 -> 0 | Q18: =L18-O18 -> 0
C19: b) | D19: Extra over item B12.02 a) for excavation in hard material
D20: in the close vicinity of services using jackhammers,
D21: power tools, etc where no blasting or machine
D22: excavation is permitted | F22: m3 | G22: 45 | H22: 850 | I22: =IF(G22=0," ",G22*H22) -> 38250 | J22: 45 | K22: 850 | L22: =IF(J22=0," ",J22*K22) -> 38250 | M22: 45 | N22: 850 | O22: =IF(M22=0," ",M22*N22) -> 38250 | P22: =K22-N22 -> 0 | Q22: =L22-O22 -> 0
B24: B12.03 | C24: Relocation and protection of existing services:
C25: a) | D25: Relocation, including lowering or raising, protection | I25: =IF(G25=0," ",G25*H25) | L25: =IF(J25=0," ",J25*K25) | O25: =IF(M25=0," ",M25*N25)
D26: and/or repair of existing services which are not allowed | I26: =IF(G26=0," ",G26*H26) | L26: =IF(J26=0," ",J26*K26) | O26: =IF(M26=0," ",M26*N26)
D27: for under items in the schedule of quantities | F27: Prov Sum | G27: 400000 | H27: 1 | I27: =IF(G27=0," ",G27*H27) -> 400000 | J27: 400000 | K27: 1 | L27: =IF(J27=0," ",J27*K27) -> 400000 | M27: 400000 | N27: 1 | O27: =IF(M27=0," ",M27*N27) -> 400000 | P27: =K27-N27 -> 0 | Q27: =L27-O27 -> 0
I28: =IF(G28=0," ",G28*H28) | L28: =IF(J28=0," ",J28*K28) | O28: =IF(M28=0," ",M28*N28)
C29: b) | D29: Handling cost and profit in respect of B12.03 (a) above | F29: % | G29: =G27 -> 400000 | H29: 0.1 | I29: =IF(G29=0," ",G29*H29) -> 40000 | J29: =J27 -> 400000 | K29: 0.1 | L29: =IF(J29=0," ",J29*K29) -> 40000 | M29: =M27 -> 400000 | N29: 0.1 | O29: =IF(M29=0," ",M29*N29) -> 40000 | P29: =K29-N29 -> 0 | Q29: =L29-O29 -> 0
I30: =IF(G30=0," ",G30*H30) | L30: =IF(J30=0," ",J30*K30) | O30: =IF(M30=0," ",M30*N30)
B31: B12.04 | C31: Provision of Community Liaison Officer
C32: a) | D32: Community liaison officer | F32: Prov sum | G32: =(10000*2*6) -> 120000 | H32: 1 | I32: =IF(G32=0," ",G32*H32) -> 120000 | J32: =(10000*2*6) -> 120000 | K32: 1 | L32: =IF(J32=0," ",J32*K32) -> 120000 | M32: =(10000*2*6) -> 120000 | N32: 1 | O32: =IF(M32=0," ",M32*N32) -> 120000 | P32: =K32-N32 -> 0 | Q32: =L32-O32 -> 0
C34: b) | D34: Handling costs and profit in respect of | F34: % | G34: =G32 -> 120000 | H34: 0.1 | I34: =IF(G34=0," ",G34*H34) -> 12000 | J34: =J32 -> 120000 | K34: 0.1 | L34: =IF(J34=0," ",J34*K34) -> 12000 | M34: =M32 -> 120000 | N34: 0.1 | O34: =IF(M34=0," ",M34*N34) -> 12000 | P34: =K34-N34 -> 0 | Q34: =L34-O34 -> 0
D35: sub-item B12.04(a) | I35: =IF(G35=0," ",G35*H35) | L35: =IF(J35=0," ",J35*K35) | O35: =IF(M35=0," ",M35*N35)
I36: =IF(G36=0," ",G36*H36) | L36: =IF(J36=0," ",J36*K36) | O36: =IF(M36=0," ",M36*N36)
B37: B12.06 | C37: Community participation | I37: =IF(G37=0," ",G37*H37) | L37: =IF(J37=0," ",J37*K37) | O37: =IF(M37=0," ",M37*N37)
C38: a) | D38: Cost of community participation and PLC support | F38: Prov Sum | G38: =(8*6*300) -> 14400 | H38: 1 | I38: =IF(G38=0," ",G38*H38) -> 14400 | J38: =(8*6*300) -> 14400 | K38: 1 | L38: =IF(J38=0," ",J38*K38) -> 14400 | M38: =(8*6*300) -> 14400 | N38: 1 | O38: =IF(M38=0," ",M38*N38) -> 14400 | P38: =K38-N38 -> 0 | Q38: =L38-O38 -> 0
I39: =IF(G39=0," ",G39*H39) | L39: =IF(J39=0," ",J39*K39) | O39: =IF(M39=0," ",M39*N39)
C40: b) | D40: Handling cost and profit in respect of subitem 12.05 (a) | F40: % | G40: =G38 -> 14400 | H40: 0.1 | I40: =IF(G40=0," ",G40*H40) -> 1440 | J40: =J38 -> 14400 | K40: 0.1 | L40: =IF(J40=0," ",J40*K40) -> 1440 | M40: =M38 -> 14400 | N40: 0.1 | O40: =IF(M40=0," ",M40*N40) -> 1440 | P40: =K40-N40 -> 0 | Q40: =L40-O40 -> 0
I41: =IF(G41=0," ",G41*H41) | L41: =IF(J41=0," ",J41*K41) | O41: =IF(M41=0," ",M41*N41)
B42: B12.07 | C42: Compensation to land owners | I42: =IF(G42=0," ",G42*H42) | L42: =IF(J42=0," ",J42*K42) | O42: =IF(M42=0," ",M42*N42)
C43: a) | D43: Cost of compensation to land owners | F43: Prov Sum | G43: 50000 | H43: 1 | I43: =IF(G43=0," ",G43*H43) -> 50000 | J43: 50000 | K43: 1 | L43: =IF(J43=0," ",J43*K43) -> 50000 | M43: 50000 | N43: 1 | O43: =IF(M43=0," ",M43*N43) -> 50000 | P43: =K43-N43 -> 0 | Q43: =L43-O43 -> 0
I44: =IF(G44=0," ",G44*H44) | L44: =IF(J44=0," ",J44*K44) | O44: =IF(M44=0," ",M44*N44)
C45: b) | D45: Handling cost and profit in respect of subitem 12.07 (a) | F45: % | G45: =G43 -> 50000 | H45: 0.1 | I45: =IF(G45=0," ",G45*H45) -> 5000 | J45: =J43 -> 50000 | K45: 0.1 | L45: =IF(J45=0," ",J45*K45) -> 5000 | M45: =M43 -> 50000 | N45: 0.1 | O45: =IF(M45=0," ",M45*N45) -> 5000 | P45: =K45-N45 -> 0 | Q45: =L45-O45 -> 0
...

Sheet Schedule B Structures
B1: SCHEDULE B : STRUCTURAL
B2: SCHEDULE OF QUANTITIES | G2: T2 Tech | J2: TM&S Original rates | M2: TM&S Proposed rates | P2: Difference in | Q2: Difference in
P3: Rates | Q3: Value
B4: Item | C4: Description | D4: Description | F4: Unit | G4: Scheduled | J4: Scheduled | M4: Scheduled
B5: No | G5: Quantity | H5: Rate | I5: Value | J5: Quantity | K5: Rate | L5: Value | M5: Quantity | N5: Rate | O5: Value | P5: Value | Q5: Value
C7: Cell Structures for in-situ cast Box Culverts and In- and
C8: Outlet structures for Pipe and Box Culverts
B10: 6100 | C10: FOUNDATIONS FOR STRUCTURES
B12: 61.01 | C12: Additional foundation investigations | F12: Prov Sum | K12: 100000 | P12: =K12-N12 -> 100000 | Q12: =L12-O12 -> 0
I13: =IF(G13=0," ",G13*H13) | L13: =IF(J13=0," ",J13*K13) | O13: =IF(M13=0," ",M13*N13)
B14: 61.02 | C14: Excavation: | I14: =IF(G14=0," ",G14*H14) | L14: =IF(J14=0," ",J14*K14) | O14: =IF(M14=0," ",M14*N14)
C15: a) | D15: Excavating soft material situated within the following | I15: =IF(G15=0," ",G15*H15) | L15: =IF(J15=0," ",J15*K15) | O15: =IF(M15=0," ",M15*N15)
D16: successive depth ranges | I16: =IF(G16=0," ",G16*H16) | L16: =IF(J16=0," ",J16*K16) | O16: =IF(M16=0," ",M16*N16)
D17: i) | E17: Foundations, from 0 m up to 2 m | F17: m3 | G17: Rate Only | H17: 60 | J17: Rate Only | K17: 95 | M17: Rate Only | N17: 60 | P17: =K17-N17 -> 35 | Q17: =L17-O17 -> 0
H18: =IF(F18=0," ",F18*G18) | N18: =IF(L18=0," ",L18*M18)
D19: ii) | E19: Foundations, exceeding 2 m and up to 4 m | F19: m3 | G19: Rate Only | H19: 100 | J19: Rate Only | K19: 145 | M19: Rate Only | N19: 100 | P19: =K19-N19 -> 45 | Q19: =L19-O19 -> 0
H20: =IF(F20=0," ",F20*G20) | N20: =IF(L20=0," ",L20*M20)
D21: iii) | E21: Foundations, exceeding 4 m and up to 6 m | F21: m3 | G21: Rate Only | H21: 100 | J21: Rate Only | K21: 195 | M21: Rate Only | N21: 100 | P21: =K21-N21 -> 95 | Q21: =L21-O21 -> 0
C23: b) | D23: Extra over Subitem 61.02(a) for hard excavation | F23: m3 | G23: =(20*5*1.5) -> 150 | H23: 400 | I23: =IF(G23=0," ",G23*H23) -> 60000 | J23: 150 | K23: 800 | L23: =IF(J23=0," ",J23*K23) -> 120000 | M23: 150 | N23: 400 | O23: =IF(M23=0," ",M23*N23) -> 60000 | P23: =K23-N23 -> 400 | Q23: =L23-O23 -> 60000
H24: =IF(F24=0," ",F24*G24) | N24: =IF(L24=0," ",L24*M24)
B25: 61.03 | C25: Access and drainage | H25: =IF(F25=0," ",F25*G25) | N25: =IF(L25=0," ",L25*M25)
C26: a) | D26: Access | F26: Lump Sum | G26: 1 | H26: 150000 | I26: =IF(G26=0," ",G26*H26) -> 150000 | J26: 1 | K26: 15000 | L26: =IF(J26=0," ",J26*K26) -> 15000 | M26: 1 | N26: 150000 | O26: =IF(M26=0," ",M26*N26) -> 150000 | P26: =K26-N26 -> -135000 | Q26: =L26-O26 -> -135000
H27: =IF(F27=0," ",F27*G27) | I27: =IF(G27=0," ",G27*H27) | L27: =IF(J27=0," ",J27*K27) | O27: =IF(M27=0," ",M27*N27)
B28: 61.04 | C28: Backfill to excavations utilising: | H28: =IF(F28=0," ",F28*G28) | I28: =IF(G28=0," ",G28*H28) | L28: =IF(J28=0," ",J28*K28) | O28: =IF(M28=0," ",M28*N28)
C29: a) | D29: Material from excavation compacted to 90% of | H29: =IF(F29=0," ",F29*G29) | I29: =IF(G29=0," ",G29*H29) | L29: =IF(J29=0," ",J29*K29) | O29: =IF(M29=0," ",M29*N29)
D30: modified AASHTO density | F30: m3 | G30: =(25*6*2) -> 300 | H30: 50 | I30: =IF(G30=0," ",G30*H30) -> 15000 | J30: 300 | K30: 65 | L30: =IF(J30=0," ",J30*K30) -> 19500 | M30: 300 | N30: 50 | O30: =IF(M30=0," ",M30*N30) -> 15000 | P30: =K30-N30 -> 15 | Q30: =L30-O30 -> 4500
I31: =IF(G31=0," ",G31*H31) | L31: =IF(J31=0," ",J31*K31) | O31: =IF(M31=0," ",M31*N31)
C32: b) | D32: Imported material (G5) | F32: m3 | G32: Rate Only | H32: 80 | J32: Rate Only | K32: 450 | M32: Rate Only | N32: 450 | P32: =K32-N32 -> 0 | Q32: =L32-O32 -> 0
H33: =IF(F33=0," ",F33*G33) | I33: =IF(G33=0," ",G33*H33) | L33: =IF(J33=0," ",J33*K33) | O33: =IF(M33=0," ",M33*N33)
B34: 61.05 | C34: Fill within a restricted area (extra over item 61.04) | F34: m3 | G34: =2*(25*1*10) -> 500 | H34: 50 | I34: =IF(G34=0," ",G34*H34) -> 25000 | J34: 500 | K34: 65 | L34: =IF(J34=0," ",J34*K34) -> 32500 | M34: 500 | N34: 50 | O34: =IF(M34=0," ",M34*N34) -> 25000 | P34: =K34-N34 -> 15 | Q34: =L34-O34 -> 7500
H35: =IF(F35=0," ",F35*G35) | I35: =IF(G35=0," ",G35*H35) | L35: =IF(J35=0," ",J35*K35) | O35: =IF(M35=0," ",M35*N35)
B36: 61.06 | C36: Overhaul in excess of 1,0 km on excavated material and | H36: =IF(F36=0," ",F36*G36) | I36: =IF(G36=0," ",G36*H36) | L36: =IF(J36=0," ",J36*K36) | O36: =IF(M36=0," ",M36*N36)
C37: on material imported for backfill and foundation fill and | H37: =IF(F37=0," ",F37*G37) | I37: =IF(G37=0," ",G37*H37) | L37: =IF(J37=0," ",J37*K37) | O37: =IF(M37=0," ",M37*N37)
C38: foundation fill and fill for caissons | F38: m3-km | G38: =(G23+G30+G34)*3 -> 2850 | H38: 8 | I38: =IF(G38=0," ",G38*H38) -> 22800 | J38: 2850 | K38: 18.5 | L38: =IF(J38=0," ",J38*K38) -> 52725 | M38: 2850 | N38: 8 | O38: =IF(M38=0," ",M38*N38) -> 22800 | P38: =K38-N38 -> 10.5 | Q38: =L38-O38 -> 29925
H39: =IF(F39=0," ",F39*G39) | I39: =IF(G39=0," ",G39*H39) | L39: =IF(J39=0," ",J39*K39) | O39: =IF(M39=0," ",M39*N39)
B40: 61.08 | C40: Foundation fill consisting of: | H40: =IF(F40=0," ",F40*G40) | I40: =IF(G40=0," ",G40*H40) | L40: =IF(J40=0," ",J40*K40) | O40: =IF(M40=0," ",M40*N40)
C41: a) | D41: Rock fill | F41: m3 | G41: =(5*10*10)+(11*46*0.6) -> 803.6 | H41: 300 | I41: =IF(G41=0," ",G41*H41) -> 241080 | J41: 804 | K41: 350 | L41: =IF(J41=0," ",J41*K41) -> 281400 | M41: 804 | N41: 300 | O41: =IF(M41=0," ",M41*N41) -> 241200 | P41: =K41-N41 -> 50 | Q41: =L41-O41 -> 40200
H42: =IF(F42=0," ",F42*G42) | I42: =IF(G42=0," ",G42*H42) | L42: =IF(J42=0," ",J42*K42) | O42: =IF(M42=0," ",M42*N42)
C43: b) | D43: Imported material (G5) | F43: m3 | G43: Rate Only | H43: 80 | J43: Rate Only | K43: 450 | M43: Rate Only | N43: 450 | P43: =K43-N43 -> 0 | Q43: =L43-O43 -> 0
H44: =IF(F44=0," ",F44*G44) | I44: =IF(G44=0," ",G44*H44) | L44: =IF(J44=0," ",J44*K44) | O44: =IF(M44=0," ",M44*N44)
...

Sheet Schedule B Summary
B1: SCHEDULE B : STRUCTURAL
B2: SUMMARY OF SCHEDULE OF QUANTITIES | M2: Contingency earthworks = | N2: 0.15
M3: Contingency = | N3: 0.1
B4: SCHEDULE | C4: SECTION | I4: TOTAL | J4: TOTAL | K4: TOTAL
I6: =IF(G16=0," ",G16*H6) | J6: =IF(H16=0," ",H16*I6) | K6: =IF(I16=0," ",I16*J6)
B7: 6100 | C7: FOUNDATIONS FOR STRUCTURES | I7: ='Schedule B Structures'!I77 -> 533700 | J7: ='Schedule B Structures'!L77 -> 561375 | K7: ='Schedule B Structures'!O77 -> 533820
I8: =IF(G8=0," ",G8*H8) | J8: =IF(H8=0," ",H8*I8)
B9: 6200 | C9: FALSEWORK, FORMWORK AND CONCRETE FINISH | I9: ='Schedule B Structures'!I154 -> 226200 | J9: ='Schedule B Structures'!L154 -> 162110 | K9: ='Schedule B Structures'!O154 -> 162110
B11: 6300 | C11: STEEL REINFORCEMENT FOR STRUCTURES | I11: ='Schedule B Structures'!I231 -> 153000 | J11: ='Schedule B Structures'!L231 -> 166000 | K11: ='Schedule B Structures'!O231 -> 162500
B13: 6400 | C13: CONCRETE FOR STRUCTURES | I13: ='Schedule B Structures'!I308 -> 381000 | J13: ='Schedule B Structures'!L308 -> 382500 | K13: ='Schedule B Structures'!O308 -> 382500
B15: 6600 | C15: NO-FINES CONCRETE, JOINTS, BEARINGS, PARAPETS | I15: ='Schedule B Structures'!I384 -> 103816.31 | J15: ='Schedule B Structures'!L384 -> 61955.037 | K15: ='Schedule B Structures'!O384 -> 61955.037
C16: AND DRAINAGE FOR STRUCTURES
B80: TOTAL OF SCHEDULE B CARRIED FORWARD TO TENDER SUMMARY | I80: =SUM(I7:I79) -> 1397716.3 | J80: =SUM(J7:J79) -> 1333940 | K80: =SUM(K7:K79) -> 1302885 | L80: =J80-K80 -> 31055

Sheet  Schedule C EMP
B1: SCHEDULE C : ENVIROMENTAL MANAGEMENT PLAN
B3: Item | C3: Description | D3: Unit | E3: Scheduled | F3: Estimated | G3: Estimated
B4: No | E4: Quantity | F4: Rate | G4: Value
B6: C | C6: ENVIROMENTAL MANAGEMENT PLAN
B8: C10.01 | C8: Penalty for unnecessary removal or damage to trees
C10: (a) 2600mm girth or less | D10: no. | F10: -5000
C12: (b) Greater than 2600mm, but less than 6180mm girth | D12: no. | F12: -10000
C14: (c) Greater than 61800mm girth | D14: no. | F14: -30000
B16: C10.02 | C16: Penalty for serious violations
C18: (a) Hazardous chemical/oil spill and/or dumping in non-approved sites | D18: no. | F18: -10000
C19: (b) General damage to sensitive environments | D19: no. | F19: -5000
C21: (c) Damage to cultural and historical sites | D21: no. | F21: -5000
C23: (d) Pollution of water sources | D23: no. | F23: -10000
C25: (e) Unauthorised blasting activities | D25: no. | F25: -5000
C27: (f) Uncontrolled/unmanaged erosion per incident, depending on environment impacts (over and above rehabilitation at contractor’s cost) | D27: no. | F27: -5000
B29: C10.03 | C29: Penalty for less serious violations
C31: (a) Littering on site | D31: no. | F31: -1000
C33: (b) Lighting of illegal fires on site | D33: no. | F33: -1000
C35: (c ) Persistent or un-repaired fuel and oil leaks | D35: no. | F35: -1000
C37: (f) Excess dust or excess noise emanating from site | D37: no. | F37: -1000
C39: (g) Dumping of milled material in side drains or on grassed areas | D39: no. | F39: -1000
C41: (h) Possession or use of intoxicating substances on site | D41: no. | F41: -500
C43: (i) Any vehicles being driven in excess of designated speed limits | D43: no. | F43: -500
C45: (j) Removal and/or damage to flora or cultural or heritage objects on site, and/or killing of wildlife | D45: no. | F45: -2000
C47: (k) Illegal hunting | D47: no. | F47: -2000
C49: (l) Urination and defecation anywhere except in designated areas | D49: no. | F49: -500
B56: C | C56: TOTAL CARRIED TO SUMMARY

Sheet Schedule D Remedial Works
B1: SCHEDULE : REMEDIAL WORK
B2: SCHEDULE OF QUANTITIES | G2: T2 Tech | J2: TM&S Original rates | M2: TM&S Proposed rates | P2: Difference in | Q2: Difference in
P3: Rates | Q3: Value
B4: Item | C4: Description | D4: Description | F4: Unit | G4: Scheduled | H4: Estimated | I4: Estimated | J4: Scheduled | K4: Estimated | L4: Estimated | M4: Scheduled | N4: Estimated | O4: Estimated
B5: No | G5: Quantity | H5: Rate | I5: Value | J5: Quantity | K5: Rate | L5: Value | M5: Quantity | N5: Rate | O5: Value | P5: Value | Q5: Value
B11: L 21.16 | C11: Backfilling existing eroded side drains | F11: m3 | G11: 150 | H11: 30 | I11: =G11*H11 -> 4500 | J11: 150 | K11: 60 | L11: =J11*K11 -> 9000 | M11: 150 | N11: 60 | O11: =M11*N11 -> 9000 | P11: =K11-N11 -> 0 | Q11: =L11-O11 -> 0
B14: 22.03 | C14: Concrete pipe culverts:
C15: b) | D15: On class B bedding | I15: =IF(G15=0," ",G15*H15) | L15: =IF(J15=0," ",J15*K15) | O15: =IF(M15=0," ",M15*N15)
D16: i) | E16: 600 mm diameter, class 75 D | F16: m | H16: 2000 | I16: =IF(G16=0," ",G16*H16) | K16: 950 | L16: =IF(J16=0," ",J16*K16) | N16: 950 | O16: =IF(M16=0," ",M16*N16) | P16: =K16-N16 -> 0
D18: ii) | E18: 900 mm diameter, class 75 D | F18: m | G18: =2.44*5 -> 12.2 | H18: 2800 | I18: =G18*H18 -> 34160 | J18: 12 | K18: 1350 | L18: =J18*K18 -> 16200 | M18: 12 | N18: 1350 | O18: =M18*N18 -> 16200 | P18: =K18-N18 -> 0 | Q18: =L18-O18 -> 0
B21: L 23.01 | C21: Concrete kerbing cast in-situ or manufactered on site
C22: (class 30/19 concrete): (dwg D4407-TD-002)
C23: a) | D23: Mountable kerb (fig.8b SABS) - pre-cast | F23: m | I23: =IF(G23=0," ",G23*H23) | K23: 199 | L23: =IF(J23=0," ",J23*K23) | N23: 199 | O23: =IF(M23=0," ",M23*N23)
C25: b) | D25: (i) Barrier kerb (fig.3 SABS) - pre-cast + 100mm channel | F25: m | G25: 789 | H25: 300 | I25: =G25*H25 -> 236700 | J25: 789 | K25: 315 | L25: =J25*K25 -> 248535 | M25: 789 | N25: 315 | O25: =M25*N25 -> 248535 | P25: =K25-N25 -> 0 | Q25: =L25-O25 -> 0
D27: (ii) Barrier kerb (fig.3 SABS) - pre-cast + 200mm channel | F27: m | G27: 350 | H27: 320 | I27: =G27*H27 -> 112000 | J27: 350 | K27: 315 | L27: =J27*K27 -> 110250 | M27: 350 | N27: 315 | O27: =M27*N27 -> 110250 | P27: =K27-N27 -> 0 | Q27: =L27-O27 -> 0
I28: =IF(G28=0," ",G28*H28) | L28: =IF(J28=0," ",J28*K28) | O28: =IF(M28=0," ",M28*N28)
B29: B33.01 | C29: Cut and borrow to fill, including free-haul up to 1,0 km: | I29: =IF(G29=0," ",G29*H29) | L29: =IF(J29=0," ",J29*K29) | O29: =IF(M29=0," ",M29*N29)
C30: a) | D30: Material in compacted layer thickness of 200 mm | I30: =IF(G30=0," ",G30*H30) | L30: =IF(J30=0," ",J30*K30) | O30: =IF(M30=0," ",M30*N30)
D31: and less: | I31: =IF(G31=0," ",G31*H31) | L31: =IF(J31=0," ",J31*K31) | O31: =IF(M31=0," ",M31*N31)
D32: i) | E32: Compacted to 90 % of modified AASHTO density | F32: m3 | G32: =375*0.8*5 -> 1500 | H32: 30 | I32: =G32*H32 -> 45000 | J32: 1500 | K32: 45 | L32: =J32*K32 -> 67500 | M32: 1500 | N32: 45 | O32: =M32*N32 -> 67500 | P32: =K32-N32 -> 0 | Q32: =L32-O32 -> 0
I33: =IF(G33=0," ",G33*H33) | L33: =IF(J33=0," ",J33*K33) | O33: =IF(M33=0," ",M33*N33)
I34: =IF(G34=0," ",G34*H34) | L34: =IF(J34=0," ",J34*K34) | O34: =IF(M34=0," ",M34*N34)
B35: 33.10 | C35: Roadbed preparation and the compaction of material: | I35: =IF(G35=0," ",G35*H35) | L35: =IF(J35=0," ",J35*K35) | O35: =IF(M35=0," ",M35*N35)
C36: a) | D36: Compaction to 90 % of modified AASHTO density. | F36: m3 | G36: =179*2.6*0.2+90*5.6*0.2+((179*2.6*0.2+90*5.6*0.2)*0.1) -> 213.268 | H36: 60 | I36: =G36*H36 -> 12796.08 | J36: 213 | K36: 45 | L36: =J36*K36 -> 9585 | M36: 213 | N36: 45 | O36: =M36*N36 -> 9585 | P36: =K36-N36 -> 0 | Q36: =L36-O36 -> 0
I37: =IF(G37=0," ",G37*H37) | L37: =IF(J37=0," ",J37*K37) | O37: =IF(M37=0," ",M37*N37)
I38: =IF(G38=0," ",G38*H38) | L38: =IF(J38=0," ",J38*K38) | O38: =IF(M38=0," ",M38*N38)
B39: L 33.13 | C39: Finishing-off cut and fill slopes
C40: a) | D40: Cut slopes | F40: m2 | K40: 25 | N40: 25 | P40: =K40-N40 -> 0 | Q40: =L40-O40 -> 0
P41: =K41-N41 -> 0 | Q41: =L41-O41 -> 0
C42: b) | D42: Fill slopes | F42: m2 | G42: =1132.5*10 -> 11325 | H42: 11 | I42: =G42*H42 -> 124575 | J42: 11325 | K42: 15 | L42: =J42*K42 -> 169875 | M42: 11325 | N42: 15 | O42: =M42*N42 -> 169875 | P42: =K42-N42 -> 0 | Q42: =L42-O42 -> 0
B45: 3400 | C45: PAVEMENT LAYERS OF GRAVEL MATERIAL
B47: 34.01 | C47: Pavement layers constructed from gravel taken from cut
C48: or borrow, including free-haul up to 1,0 km:
C49: a) | D49: Gravel selected layer compacted to:
D50: i) | E50: 93% of modified AASHTO density, 150 mm thick | F50: m3 | G50: =179*2.45*0.3+90*5.5*0.3+48*5.45*0.3+(358.9*0.1) -> 394.435 | H50: 40 | I50: =G50*H50 -> 15777.4 | J50: 394 | K50: 65 | L50: =J50*K50 -> 25610 | M50: 394 | N50: 65 | O50: =M50*N50 -> 25610 | P50: =K50-N50 -> 0 | Q50: =L50-O50 -> 0
C53: d) | D53: Gravel subbase C4 (chemically stabilized) compacted to:
D54: i) | E54: 95% of modified AASHTO density, 200 mm thick | F54: m3 | G54: =179*2.3*0.2+90*5.3*0.2+48*5.3*0.2 -> 228.62 | H54: 80 | I54: =G54*H54 -> 18289.6 | J54: 229 | K54: 450 | L54: =J54*K54 -> 103050 | M54: 229 | N54: 450 | O54: =M54*N54 -> 103050 | P54: =K54-N54 -> 0 | Q54: =L54-O54 -> 0
C57: h) | D57: Gravel wearing course compacted to:
D58: i) | E58: 93% of modified AASHTO density, 150 mm thick | F58: m3 | G58: =(0.9*0.3*7200)*2 -> 3888 | H58: 40 | I58: =G58*H58 -> 155520 | J58: 3888 | K58: 55 | L58: =J58*K58 -> 213840 | M58: 3888 | N58: 55 | O58: =M58*N58 -> 213840 | P58: =K58-N58 -> 0 | Q58: =L58-O58 -> 0
B61: 3500 | C61: STABILIZATION
...

Sheet Schedule D Summary 
B1: SCHEDULE D: REMEDIAL WORKS
B2: SUMMARY OF SCHEDULE OF QUANTITIES
B4: SCHEDULE | C4: SECTION | D4: TOTAL | E4: TOTAL | F4: TOTAL
C6: Remedial Works Summary | D6: ='Schedule D Remedial Works'!I154 -> 1283900.8 | E6: ='Schedule D Remedial Works'!L154 -> 1267387.6 | F6: ='Schedule D Remedial Works'!O154 -> 1267387.6
C8: SERIES 1000 : GENERAL
B10: 1200 | C10: General requirements and provisions | D10: 0 | E10: 0 | F10: 0
B12: 1300 | C12: Contractor's establishment on site and general obligations | D12: 0 | E12: 0 | F12: 0
B14: 1400 | C14: Housing, offices and laboratories for the engineer's site personnel | D14: 0 | E14: 0 | F14: 0
B16: 1500 | C16: Accommodation of traffic | D16: 0 | E16: 0 | F16: 0
B18: 1700 | C18: Clearing and grubbing | D18: 0 | E18: 0 | F18: 0
B20: 1800 | C20: Dayworks | D20: 0 | E20: 0 | F20: 0
C22: SERIES 2000 : DRAINAGE | D22: 0 | E22: 0 | F22: 0
B24: 2100 | C24: Drains | D24: 0 | E24: 0 | F24: 0
B26: 2200 | C26: Prefabricated culverts | D26: 0 | E26: 0 | F26: 0
B28: 2300 | C28: Concrete kerbing, concrete channelling, chutes and downpipes, and concrete linings for open drains | D28: 0 | E28: 0 | F28: 0
C30: SERIES 3000 : EARTHWORKS AND PAVEMENT LAYERS OF GRAVEL OR CRUSHED STONE
B32: 3100 | C32: Borrow Material | D32: 0 | E32: 0 | F32: 0
B34: 3300 | C34: Mass earthworks | D34: 0 | E34: 0 | F34: 0
B36: 3400 | C36: Pavement layers of gravel material | D36: 0 | E36: 0 | F36: 0
B38: 3500 | C38: Stabilization | D38: 0 | E38: 0 | F38: 0
B40: 3600 | C40: Crushed stone base | D40: 0 | E40: 0 | F40: 0
C42: SERIES 4000 : ASPHALT PAVEMENTS AND SEALS
B44: 4100 | C44: Prime Coat | D44: 0 | E44: 0 | F44: 0
B46: 4200 | C46: Asphalt Base and Surfacing | D46: 0 | E46: 0 | F46: 0
C48: SERIES 5000 : ANCILLARY ROADWORKS
B50: 5100 | C50: Pitching, stonework and protection against erosion | D50: 0 | E50: 0 | F50: 0
B52: 5200 | C52: Gabions | D52: 0 | E52: 0 | F52: 0
B54: 5400 | C54: Guardrails | D54: 0 | E54: 0 | F54: 0
B56: 5500 | C56: Fencing | D56: 0 | E56: 0 | F56: 0
B58: 5600 | C58: Road signs | D58: 0 | E58: 0 | F58: 0
B60: 5700 | C60: Road markings | D60: 0 | E60: 0 | F60: 0
B62: 5800 | C62: Landscaping | D62: 0 | E62: 0 | F62: 0
B64: 5900 | C64: Finishing the road and road reserve and treating old roads | D64: 0 | E64: 0 | F64: 0
B66: 8100 | C66: Testing Materials and Workmanship | D66: 0 | E66: 0 | F66: 0
B72: TOTAL OF SCHEDULE A CARRIED FORWARD TO TENDER SUMMARY | D72: =SUM(D6:D71) -> 1283900.8 | E72: =SUM(E6:E71) -> 1267387.6 | F72: =SUM(F6:F71) -> 1267387.6 | G72: =E72-F72 -> 0

Sheet Total Tender Sum
B3: SCHEDULE | C3: SECTION | D3: TOTAL | E3: TOTAL OLD TM&S | F3: TOTAL NEW TM&S
B5: A | C5: ROADWORKS | D5: ='Schedule A Summary'!D70 -> 37261694 | E5: ='Schedule A Summary'!E70 -> 36342487 | F5: ='Schedule A Summary'!F70 -> 36373542 | G5: =E5-F5 -> -31055 | H5: ='[1]Total Tender Sum'!$D$4 -> 36964129 | I5: =H5-F5 -> 590586.79 | J5: 36345984 | K5: =E5-J5 -> -3497.68
I6: =H6-F6 -> 0 | K6: =E6-J6 -> 0
B7: B | C7: STRUCTURES | D7: ='Schedule B Summary'!I80 -> 1397716.3 | E7: ='Schedule B Summary'!J80 -> 1333940 | F7: ='Schedule B Summary'!K80 -> 1302885 | G7: =E7-F7 -> 31055 | H7: ='[1]Total Tender Sum'!$D$6 -> 1330300 | I7: =H7-F7 -> 27415 | J7: 1330440 | K7: =E7-J7 -> 3500.0375
I8: =H8-F8 -> 0 | K8: =E8-J8 -> 0
B9: C | C9: REMEDIAL WORKS | D9: ='Schedule D Summary '!D72 -> 1283900.8 | E9: ='Schedule D Summary '!E72 -> 1267387.6 | F9: ='Schedule D Summary '!F72 -> 1267387.6 | G9: =E9-F9 -> 0 | H9: ='[1]Total Tender Sum'!$D$8 -> 1258160.9 | I9: =H9-F9 -> -9226.796 | J9: 1267390 | K9: =E9-J9 -> -2.3528
I10: =H10-F10 -> 0
G19: =E20-F20 -> 3.002584e-06
B20: TOTAL OF SCHEDULE OF QUANTITIES | D20: =SUM(D5:D19) -> 39943311 | E20: =SUM(E5:E19) -> 38943815 | F20: =SUM(F5:F19) -> 38943815 | H20: =SUM(H5:H19) -> 39552590 | I20: =F20-H20 -> -608775 | J20: =SUM(J5:J19) -> 38943814 | K20: =E20-J20 -> 0.0047000051
I21: =F21-H21 -> 0
B22: CONTRACT PRICE ADJUSTMENT (6%) | D22: =D20*6% -> 2396598.7 | E22: =E20*6% -> 2336628.9 | F22: =F20*6% -> 2336628.9 | H22: =H20*6% -> 2373155.4 | I22: =F22-H22 -> -36526.5 | J22: =J20*6% -> 2336628.9 | K22: =E22-J22 -> 0.00028200028
I23: =F23-H23 -> 0
B24: CONTINGENCIES (5%) | D24: =D20*5% -> 1997165.6 | E24: =E20*5% -> 1947190.7 | F24: =F20*5% -> 1947190.7 | H24: =H20*5% -> 1977629.5 | I24: =F24-H24 -> -30438.75 | J24: =J20*5% -> 1947190.7 | K24: =E24-J24 -> 0.00023500016
I25: =F25-H25 -> 0
B26: SUBTOTAL | D26: =D20+D22+D24 -> 44337075 | E26: =E20+E22+E24 -> 43227634 | F26: =F20+F22+F24 -> 43227634 | H26: =H20+H22+H24 -> 43903374 | I26: =F26-H26 -> -675740.25 | J26: =J20+J22+J24 -> 43227634 | K26: =E26-J26 -> 0.0052170083
I27: =F27-H27 -> 0
B28: VALUE ADDED TAX (15%) | D28: =D26*15% -> 6650561.3 | E28: =(E26*15%)-(0.01) -> 6484145.1 | F28: =(F26*15%)-0.01 -> 6484145.1 | H28: =H26*15% -> 6585506.2 | I28: =F28-H28 -> -101361.05 | J28: =J26*15% -> 6484145.1 | K28: =E28-J28 -> -0.0092174485
I29: =F29-H29 -> 0
B30: TOTAL TENDER SUM | D30: =D26+D28 -> 50987637 | E30: =E26+E28 -> 49711779 | F30: =F26+F28 -> 49711779 | G30: =E30-F30 -> 3.8295984e-06 | H30: =H26+H28 -> 50488880 | I30: =F30-H30 -> -777101.29 | J30: =J26+J28 -> 49711779 | K30: =E30-J30 -> -0.0040004402
E34: 49711779 | F34: Appointed amount | G34: =E34-F30 -> 0.0047542751
E36: 49121171 | F36: =E36-F30 -> -590608.01
E37: =E34-E30 -> 0.0047504455 | F37: =E34-F30 -> 0.0047542751 | G37: Over and above the appointed amount
E38: =E34-F30 -> 0.0047542751
E40: =E34-F30 -> 0.0047542751
