Workbook
Name _SEC1200: #REF!

Sheet Site Establishment, monthlycost
A1: M0300 | B1: CONTRACTOR'S ESTABLISHMENT ON SITE AND GENERAL OBLIGATIONS
H2: Site establishment | I2: =E3 -> 1661138.2
A3: BM030.01 | B3: Fixed obligations | C3: LS | D3: 1 | E3: 1661138.2 | H3: Monthly obligations | I3: =SUM(E5:E56) -> 267523.64
A4: BM030.03 | B4: Time-related obligations
B5: (a) General obligations | C5: month | D5: 36 | E5: 61523.636
B6: (b) Occupational health and safety obligations including adherence to all COVID 19 protocols wrt PPE,transportation of workers,hygiene protocols,access to site , compliance checking&monitoring etc | C6: month | D6: 36 | E6: 15000
A7: M0400 | B7: ROUTE PATROL SERVICES
B8: Route patrol service per team (including LDV, trailer and
A9: BM040.01 | B9: equipment)
B10: (a)Team A | C10: month | D10: 36 | E10: 20000
B11: (b)Team B | C11: month | D11: 36 | E11: =+E10 -> 20000
A12: BM050.03 | B12: Accommodation of traffic and maintaining temporary
B13: deviations
B14: (a) Work undertaken by contractor
B15: Various road sections as descibed under C3.1.2.1 : Description of site | C15: month | D15: 36 | E15: 10000
A16: BM050.04 | B16: Supply and use of truck mounted attenuator
B17: Various road sections as descibed under C3.1.2.1 : Description of site | C17: month | D17: 36 | E17: 12000
A18: M1200 | B18: REPAIR OF POTHOLES
A19: BM120.01 | B19: Repair of potholes (all sections) | C19: month | D19: 36 | E19: 8000
A20: M1210 | B20: REPAIR OF EDGE BREAKS
A21: BM121.01 | B21: Repair of edge breaks (all sections) | C21: month | D21: 36 | E21: 8000
A22: M1220 | B22: REPAIR OF SURFACE FAILURES
A23: BM122.01 | B23: Repair of surface failures (all sections) | C23: month | D23: 36 | E23: 8000
A24: M1230 | B24: TEMPORARY REPAIR
B25: Temporary partial-depth pothole repair of concrete with
A26: M123.02 | B26: asphalt surfacing
B27: (a) Removal of damaged concrete and replacement of
B28: damaged concrete with asphalt surfacing (cold mix asphalt) | C28: No | D28: 20 | E28: 5000
A29: M2300 | B29: CLEANING OF WATERWAY STRUCTURES
A31: BM230.01 | B31: Cleaning of waterway structures, inlet and outlet areas
B33: (a) Cleaning of waterway structures, inlet and outlet areas:
B35: Various road sections as descibed under C3.1.2.1 : Description of site | C35: month | D35: 36 | E35: 20000
A36: M2400 | B36: CLEANING OF PREFABRICATED CULVERTS
A38: M240.01 | B38: Cleaning of prefabricated culverts, inlet and outlet areas
B40: Various road sections as descibed under C3.1.2.1 : Description of site | C40: month | D40: 36 | E40: 20000
A41: M2500 | B41: CLEANING OF CONCRETE DRAINS AND CHANNELS
A42: BM250.01 | B42: Cleaning of concrete drainage channels:
B43: Various road sections as descibed under C3.1.2.1 :
B44: Description of site
B45: (a)(i) Hand cleaning | C45: month | D45: 36 | E45: 10000
...

Sheet A-MO300
A1: TENDER NUMBER: DRT 31 D2/09/2019
A2: EXECUTION OF ROUTINE ROAD MAINTENANCE CONTRACTS ON SELECTED RISFSA CLASS 3 PROVINCIAL ROADS IN IDENTIFIED AREAS OF GAUTENG PROVINCE
A3: PACKAGE D - Contract D2
A4: PART B : OPERATIONAL
A6: ITEM NO | B6: DESCRIPTION | C6: UNIT | D6: QUANTITY | E6: RATE | F6: AMOUNT
A7: M0300 | B7: CONTRACTOR'S ESTABLISHMENT ON SITE AND GENERAL OBLIGATIONS
A9: BM030.01 | B9: Fixed obligations | C9: LS | D9: 1 | E9: =+G9*Summary!K52 -> 1661138.2 | F9: =+E9*D9 -> 1661138.2 | G9: 0.06
A11: BM030.03 | B11: Time-related obligations
B12: (a) General obligations | C12: month | D12: 36 | E12: =+G12*Summary!K52/36 -> 61523.636 | F12: =+E12*D12 -> 2214850.9 | G12: 0.08
B13: (b) Occupational health and safety obligations including adherence to all COVID 19 protocols wrt PPE,transportation of workers,hygiene protocols,access to site , compliance checking&monitoring etc | C13: month | D13: 36 | E13: 15000 | F13: =+E13*D13 -> 540000
A23: M0300 | B23: TOTAL CARRIED FORWARD TO SUMMARY | F23: =SUM(F7:F22) -> 4415989
A26: C2.4

Sheet B-M0200
A1: TENDER NUMBER: DRT 31 D2/09/2019
A2: EXECUTION OF ROUTINE ROAD MAINTENANCE CONTRACTS ON SELECTED RISFSA CLASS 3 PROVINCIAL ROADS IN IDENTIFIED AREAS OF GAUTENG PROVINCE
A3: PACKAGE C - CONTRACT D2
A4: PART B : OPERATIONAL
A6: ITEM NO | B6: DESCRIPTION | C6: UNIT | D6: QUANTITY | E6: RATE | F6: AMOUNT
A7: M0200 | B7: GENERAL REQUIREMENTS AND PROVISIONS
A8: M020.01 | B8: Information signboards
B9: (a)Type 1 (large) | C9: No | D9: 3 | E9: 35000 | F9: =+E9*D9 -> 105000
B10: (b)Type 2 (small) | C10: No | D10: 6 | E10: 25000 | F10: =+E10*D10 -> 150000
F11: =+E11*D11 -> 0
A12: 20.05 | B12: Project Liaison Committee
B13: (a)Cost of Project Liaison Committee | C13: Prov Sum | D13: 1 | E13: 200000 | F13: 200000
B15: (b)The Contractor's overhead charges and profit in respect of sub-item DM020.05 (a) | C15: % | D15: 200000 | E15: 0.15 | F15: =+E15*D15 -> 30000
A17: DM020.06 | B17: Training
B18: (a) Engineering skills | C18: Prov Sum | D18: 1 | E18: 200000 | F18: =SUM(D18*E18) -> 200000
B19: (b) Genric skills | C19: Prov Sum | D19: 1 | E19: 200000 | F19: =SUM(D19*E19) -> 200000
B20: (c) Enterpreneurial skills | C20: Prov Sum | D20: 1 | E20: 200000 | F20: =SUM(D20*E20) -> 200000
B21: (d) Training Venue | C21: Prov Sum | D21: 1 | E21: 200000 | F21: =SUM(D21*E21) -> 200000
B22: (e) Renumeration of worker undergoing training | C22: Prov Sum | D22: 1 | E22: 300000 | F22: =SUM(D22*E22) -> 300000
B23: (f) Contractors handling cost and other charges in
B24: respect of (a) to (e) | C24: % | D24: 600000 | E24: 0.15 | F24: =+E24*D24 -> 90000
A26: M0200 | B26: TOTAL CARRIED FORWARD TO SUMMARY | F26: =SUM(F7:F24) -> 1675000
A29: C2.5

Sheet B-M0300
A1: TENDER NUMBER: DRT 31 D2/09/2019
A2: EXECUTION OF ROUTINE ROAD MAINTENANCE CONTRACTS ON SELECTED RISFSA CLASS 3 PROVINCIAL ROADS IN IDENTIFIED AREAS OF GAUTENG PROVINCE
A4: PART B : OPERATIONAL
A6: ITEM NO | B6: DESCRIPTION | C6: UNIT | D6: QUANTITY | E6: RATE | F6: AMOUNT
A7: M0300 | B7: CONTRACTOR'S ESTABLISHMENT ON SITE AND GENERAL OBLIGATIONS
A8: DM030.12 | B8: Employment of personnel by Contractor
B9: (a) 25 EPWP Participants
B10: (i) Remuneration of EPWP Partcipants | C10: Prov Sum | D10: 1 | E10: 7500000 | F10: 7500000
B11: (ii)Handeling cost & ptofit in respect sub-item DM030.12(a)(i) | C11: % | D11: 7500000 | E11: 0.15 | F11: =+E11*D11 -> 1125000
A23: M0300 | B23: TOTAL CARRIED FORWARD TO SUMMARY | F23: =SUM(F8:F21) -> 8625000
A26: C2.6

Sheet B-M0400
A1: TENDER NUMBER: DRT 31 D2/09/2019
A2: EXECUTION OF ROUTINE ROAD MAINTENANCE CONTRACTS ON SELECTED RISFSA CLASS 3 PROVINCIAL ROADS IN IDENTIFIED AREAS OF GAUTENG PROVINCE
A4: PART B : OPERATIONAL
A6: ITEM NO | B6: DESCRIPTION | C6: UNIT | D6: QUANTITY | E6: RATE | F6: AMOUNT
A7: M0400 | B7: ROUTE PATROL SERVICES
B8: Route patrol service per team (including LDV, trailer and
A9: BM040.01 | B9: equipment)
B10: (a)Team A | C10: month | D10: 36 | E10: 20000 | F10: =+E10*D10 -> 720000
B11: (b)Team B | C11: month | D11: 36 | E11: =+E10 -> 20000 | F11: =+E11*D11 -> 720000
A24: M0400 | B24: TOTAL CARRIED TO SUMMARY | F24: =SUM(F8:F23) -> 1440000
A26: C2.7

Sheet B-M0500
A1: TENDER NUMBER: DRT D2_P08/02/2025
A2: EXECUTION OF ROUTINE ROAD MAINTENANCE CONTRACTS ON SELECTED RISFSA CLASS 3 PROVINCIAL ROADS IN IDENTIFIED AREAS OF GAUTENG PROVINCE
A4: PART B : OPERATIONAL
A6: ITEM NO | B6: DESCRIPTION | C6: UNIT | D6: QUANTITY | E6: RATE | F6: AMOUNT
A7: M0500 | B7: ACCOMMODATION OF TRAFFIC
A8: M050.01 | B8: Provision of temporary traffic control facilities | C8: L S | D8: 1 | E8: 80000 | F8: =+E8*D8 -> 80000
F9: =+E9*D9 -> 0
A10: M050.02 | B10: Provision of temporary traffic control facilities if contract is extended as specified | C10: L S | D10: 1 | E10: 80000 | F10: =+E10*D10 -> 80000
A11: BM050.03 | B11: Accommodation of traffic and maintaining temporary | F11: =+E11*D11 -> 0
B12: deviations | F12: =+E12*D12 -> 0
B13: (a) Work undertaken by contractor | F13: =+E13*D13 -> 0
B14: Various road sections as descibed under C3.1.2.1 : Description of site | C14: month | D14: 36 | E14: 10000 | F14: =+E14*D14 -> 360000
A15: BM050.04 | B15: Supply and use of truck mounted attenuator | F15: =+E15*D15 -> 0
B16: Various road sections as descibed under C3.1.2.1 : Description of site | C16: month | D16: 36 | E16: 12000 | F16: =+E16*D16 -> 432000
A17: BM050.05 | B17: Additional lane closures | C17: No | D17: 4 | E17: 20000 | F17: =+E17*D17 -> 80000
F18: =+E18*D18 -> 0
B19: Maintenace of Traffic SIGNAL | C19: Prov Sum | D19: 1 | E19: 5000000 | F19: =SUM(D19*E19) -> 5000000
B20: (ii)Handeling cost & profit in respect sub-item DM030.12(a)(i) | C20: % | D20: =F19 -> 5000000 | E20: 0.15 | F20: =+E20*D20 -> 750000
A23: M0500 | B23: TOTAL CARRIED TO SUMMARY | F23: =SUM(F7:F22) -> 6782000
A25: C2.8

Sheet M1100
A1: TENDER NUMBER: DRT D2_P08/02/2025
A2: EXECUTION OF ROUTINE ROAD MAINTENANCE CONTRACTS ON SELECTED RISFSA CLASS 3 PROVINCIAL ROADS IN IDENTIFIED AREAS OF GAUTENG PROVINCE
A4: PART B : OPERATIONAL
A5: ITEM NO | B5: DESCRIPTION | C5: UNIT | D5: QUANTITY | E5: RATE | F5: AMOUNT
A6: M1100 | B6: PAVEMENT LAYERS REPAIR
B7: Removal and excavating material from existing pavements
A8: M110.01 | B8: (except milled material)
B9: (a)Areas up to 50 m2 | C9: m3 | D9: 778 | E9: 85 | F9: =+E9*D9 -> 66130
B10: (b)Areas 50.1 m2 to 100m2 | C10: m3 | D10: 700 | E10: 75 | F10: =+E10*D10 -> 52500
B11: (c)Areas greater than 100 m2 | C11: m3 | D11: 1000 | E11: 125 | F11: =+E11*D11 -> 125000
A12: M110.02 | B12: Milling out material from existing pavements | C12: m3 | D12: 600 | E12: 125 | F12: =+E12*D12 -> 75000
B13: Backfilling of base layer for surface failures with (98% of | F13: =+E13*D13 -> 0
A14: BM110.03 | B14: modified AASHTO density): | F14: =+E14*D14 -> 0
B15: (a) Chemically stabilised gravel excavated from the existing pavement | F15: =+E15*D15 -> 0
B16: (i)Areas up to 50 m2 | C16: m3 | D16: 300 | E16: 120 | F16: =+E16*D16 -> 36000
B17: (ii)Areas 50.1 m2 to 100m2 | C17: m3 | D17: 100 | E17: 125 | F17: =+E17*D17 -> 12500
B18: (iii)Areas greater than 100 m2 | C18: m3 | D18: 200 | E18: 140 | F18: =+E18*D18 -> 28000
B19: (b) Emulsion-treated crushed stone pavement | F19: =+E19*D19 -> 0
B20: (i)Areas up to 50 m2 | C20: m3 | D20: 400 | E20: 190 | F20: =+E20*D20 -> 76000
B21: (ii)Areas 50.1 m2 to 100m2 | C21: m3 | D21: 400 | E21: 190 | F21: =+E21*D21 -> 76000
B22: (iii)Areas greater than 100 m2 | C22: m3 | D22: 50 | E22: 290 | F22: =+E22*D22 -> 14500
B23: (iv)Extra over sub-items (b) (i), (ii) and (iii) for importing crushed stone | C23: m3 | D23: 30 | E23: 290 | F23: =+E23*D23 -> 8700
B24: (c) Asphalt base (hot mixed) | F24: =+E24*D24 -> 0
B25: (i)Areas up to 50 m2 | C25: t | D25: 40 | E25: 2000 | F25: =+E25*D25 -> 80000
B26: (ii)Areas 50.1 m2 to 100m2 (paver) | C26: t | D26: 40 | E26: =+E25 -> 2000 | F26: =+E26*D26 -> 80000
B27: (iii)Areas greater than 100 m2 (paver) | C27: t | D27: 40 | E27: =+E26 -> 2000 | F27: =+E27*D27 -> 80000
B28: (d) Asphalt surfacing (continuously graded medium) | F28: =+E28*D28 -> 0
B29: (i)Areas up to 50 m2 | C29: t | D29: 40 | E29: 12000 | F29: =+E29*D29 -> 480000
B30: (ii)Areas 50.1 m2 to 100m2 (paver) | C30: t | D30: 40 | E30: =+E29 -> 12000 | F30: =+E30*D30 -> 480000
B31: (iii)Areas greater than 100 m2 (paver) | C31: t | D31: 40 | E31: =+E30 -> 12000 | F31: =+E31*D31 -> 480000
A32: M1100 | B32: TOTAL CARRIED FORWARD | F32: =SUM(F9:F31) -> 2250330
A33: C2.9

Sheet M1100- C
A1: TENDER NUMBER: DRT D2_P08/02/2025
A2: EXECUTION OF ROUTINE ROAD MAINTENANCE CONTRACTS ON SELECTED RISFSA CLASS 3 PROVINCIAL ROADS IN IDENTIFIED AREAS OF GAUTENG PROVINCE
A4: PART B : OPERATIONAL
A6: ITEM NO | B6: DESCRIPTION | C6: UNIT | D6: QUANTITY | E6: RATE | F6: AMOUNT
B7: BROUGHT FORWARD | F7: ='M1100'!F32 -> 2250330
A8: M110.04 | B8: Backfilling of pavement layers to compaction as specified
B9: (a) Subbase layer (95% of modified AASHTO density)
B10: (i)Areas up to 50 m2 | C10: m3 | D10: 40 | E10: 450 | F10: =+E10*D10 -> 18000
B11: (ii)Areas 50.1 m2 to 100m 2 | C11: m3 | D11: 40 | E11: 450 | F11: =+E11*D11 -> 18000
B12: (iii)Areas greater than 100 m2 | C12: m3 | D12: 40 | E12: 450 | F12: =+E12*D12 -> 18000
B13: (b) Selected layer (93% of modified AASHTO density) | F13: =+E13*D13 -> 0
B14: (i)Areas up to 50 m2 | C14: m3 | D14: 40 | E14: =+E12 -> 450 | F14: =+E14*D14 -> 18000
B15: (ii)Areas 50.1 m2 to 100m2 | C15: m3 | D15: 40 | E15: =+E14 -> 450 | F15: =+E15*D15 -> 18000
B16: (iii)Areas greater than 100 m2 | C16: m3 | D16: 40 | E16: =+E15 -> 450 | F16: =+E16*D16 -> 18000
B17: (c ) Fill layer (90% of modified AASHTO density) | F17: =+E17*D17 -> 0
B18: (i)Areas up to 50 m2 | C18: m3 | D18: 40 | E18: 450 | F18: =+E18*D18 -> 18000
B19: (ii)Areas 50.1 m2 to 100m2 | C19: m3 | D19: 40 | E19: 450 | F19: =+E19*D19 -> 18000
B20: (iii)Areas greater than 100 m2 | C20: m3 | D20: 40 | E20: 450 | F20: =+E20*D20 -> 18000
A21: M110.05 | B21: Binder variations | F21: =+E21*D21 -> 0
B22: (a) Penetration-grade bitumen | C22: t | E22: 24000 | F22: Rate Only
A23: M110.06 | B23: Variation in active filler content
B24: (a)Cement | C24: t | E24: 2600 | F24: Rate Only
B25: (b)Lime | C25: t | E25: 2100 | F25: Rate Only
A26: M110.07 | B26: Overhaul on material hauled in excess of 1,0 km | F26: =+E26*D26 -> 0
B27: (a) Spoil material | C27: m3-km | D27: 600 | E27: 10 | F27: =+E27*D27 -> 6000
A28: BM110.08 | B28: Establishment of Milling Machine on Site | C28: No | D28: 1 | E28: 70000 | F28: =+E28*D28 -> 70000
A29: BM110.09 | B29: Establishment of Paver on Site | C29: No | D29: 1 | E29: 60000 | F29: =+E29*D29 -> 60000
A30: M1100 | B30: TOTAL CARRIED FORWARD TO SUMMARY | F30: =SUM(F7:F29) -> 2548330
A32: C2.10

Sheet M1200
A1: TENDER NUMBER: DRT D2_P08/02/2025
A2: EXECUTION OF ROUTINE ROAD MAINTENANCE CONTRACTS ON SELECTED RISFSA CLASS 3 PROVINCIAL ROADS IN IDENTIFIED AREAS OF GAUTENG PROVINCE
A4: PART B : OPERATIONAL
A6: ITEM NO | B6: DESCRIPTION | C6: UNIT | D6: QUANTITY | E6: RATE | F6: AMOUNT
A7: M1200 | B7: REPAIR OF POTHOLES
A8: BM120.01 | B8: Repair of potholes (all sections) | C8: month | D8: 36 | E8: 8000 | F8: =+E8*D8 -> 288000
A9: M1210 | B9: REPAIR OF EDGE BREAKS | F9: =+E9*D9 -> 0
A10: BM121.01 | B10: Repair of edge breaks (all sections) | C10: month | D10: 36 | E10: 8000 | F10: =+E10*D10 -> 288000
A11: M1220 | B11: REPAIR OF SURFACE FAILURES | F11: =+E11*D11 -> 0
A12: BM122.01 | B12: Repair of surface failures (all sections) | C12: month | D12: 36 | E12: 8000 | F12: =+E12*D12 -> 288000
A13: M1230 | B13: TEMPORARY REPAIR | F13: =+E13*D13 -> 0
B14: Temporary partial-depth pothole repair of concrete with | F14: =+E14*D14 -> 0
A15: M123.02 | B15: asphalt surfacing | F15: =+E15*D15 -> 0
B16: (a) Removal of damaged concrete and replacement of | F16: =+E16*D16 -> 0
B17: damaged concrete with asphalt surfacing (cold mix asphalt) | C17: No | D17: 20 | E17: 5000 | F17: =+E17*D17 -> 100000
F18: =+E18*D18 -> 0
A19: M1200 | B19: TOTAL CARRIED TO SUMMARY | F19: =SUM(F8:F18) -> 964000
A23: C2.11

Sheet M1300
A1: TENDER NUMBER: DRT D2_P08/02/2025
A2: EXECUTION OF ROUTINE ROAD MAINTENANCE CONTRACTS ON SELECTED RISFSA CLASS 3 PROVINCIAL ROADS IN IDENTIFIED AREAS OF GAUTENG PROVINCE
A4: PART B : OPERATIONAL
A6: ITEM NO | B6: DESCRIPTION | C6: UNIT | D6: QUANTITY | E6: RATE | F6: AMOUNT
A7: M1300 | B7: SEALING OF ACTIVE CRACKS
B9: Cleaning of active cracks with hot compressed air and
A10: M130.01 | B10: sealing cracks as specified
B11: (a) Stabilisation cracks | F11: =+E11*D11 -> 0
B12: (i)Without bandage | C12: m | D12: 300 | E12: 120 | F12: =+E12*D12 -> 36000
B13: (ii)With bandage ("Sealmac 150" or similar) 200mm id | C13: m | D13: 1000 | E13: 120 | F13: =+E13*D13 -> 120000
B14: (d) Longitudinal cracks | C14: m | D14: 450 | E14: 120 | F14: =+E14*D14 -> 54000
F15: =+E15*D15 -> 0
A16: M1310 | B16: SEALING OF PASSIVE CRACKS | F16: =+E16*D16 -> 0
F17: =+E17*D17 -> 0
B18: Cleaning of passive cracks with hot compressed air and | F18: =+E18*D18 -> 0
A19: M131.01 | B19: seaing the cracks as specified for: | F19: =+E19*D19 -> 0
B20: (a)Surfacing cracks | C20: m2 | D20: 450 | E20: 35 | F20: =+E20*D20 -> 15750
B21: (b)Crocodile cracks | C21: m2 | D21: 1000 | E21: 35 | F21: =+E21*D21 -> 35000
B22: (c)Longitudinal cracks | C22: m | D22: 350 | E22: 120 | F22: =+E22*D22 -> 42000
F23: =+E23*D23 -> 0
A24: M1320 | B24: CRACKSEALING PER INDIVIDUAL ITEM | F24: =+E24*D24 -> 0
F25: =+E25*D25 -> 0
A26: BM132.01 | B26: Cracksealing per individual item | F26: =+E26*D26 -> 0
B27: (b) Priming of cracks (MSP1 or similar) | C27: litre | D27: 200 | E27: 30 | F27: =+E27*D27 -> 6000
B28: (c) Sealant (hot applied sealant) | C28: litre | D28: 200 | E28: 30 | F28: =+E28*D28 -> 6000
A29: M1300 | B29: TOTAL CARRIED TO SUMMARY | F29: =SUM(F11:F28) -> 314750
A31: C2.12

Sheet M1500
A1: TENDER NUMBER: DRT D2_P08/02/2025
A2: EXECUTION OF ROUTINE ROAD MAINTENANCE CONTRACTS ON SELECTED RISFSA CLASS 3 PROVINCIAL ROADS IN IDENTIFIED AREAS OF GAUTENG PROVINCE
A4: PART B : OPERATIONAL
A6: ITEM NO | B6: DESCRIPTION | C6: UNIT | D6: QUANTITY | E6: RATE | F6: AMOUNT
B7: CRACK AND JOINT SEALING OF CONCRETE
A8: M1500 | B8: PAVEMENTS
B9: Preparation and sealing or resealing of old joints and cracks
A10: M150.01 | B10: in existing concrete pavements
B11: (a)Expansion joints | C11: m | D11: 160 | E11: 65 | F11: =+E11*D11 -> 10400
B12: (b)Construction joints and weakened plane joints | F12: =+E12*D12 -> 0
B13: (i)Smaller or equal to 10mm | C13: m | D13: 250 | E13: 65 | F13: =+E13*D13 -> 16250
B14: (ii)Wider than 10mm | C14: m | D14: 50 | E14: 65 | F14: =+E14*D14 -> 3250
B15: (c ) Cracks | F15: =+E15*D15 -> 0
B16: (i)Smaller or equal to 3mm | C16: m | D16: 100 | E16: 120 | F16: =+E16*D16 -> 12000
B17: (ii)Wider than 3mm | C17: m | D17: 100 | E17: 120 | F17: =+E17*D17 -> 12000
A18: BM150.02 | B18: Small repairs to existing concrete pavements | F18: =+E18*D18 -> 0
B19: (a)Provisional sum for small repairs to existing concrete pavements | C19: Prov Sum | D19: 1 | E19: 50000 | F19: 50000
B20: (b)The Contractor's overhead charges and profit in respect of sub-item BM150.02 (a) | C20: % | D20: 50000 | E20: 0.15 | F20: =+E20*D20 -> 7500
A26: M1500 | B26: TOTAL CARRIED TO SUMMARY | F26: =SUM(F11:F25) -> 111400
A28: C2.13

Sheet M1600
A1: TENDER NUMBER: DRT D2_P08/02/2025
A2: EXECUTION OF ROUTINE ROAD MAINTENANCE CONTRACTS ON SELECTED RISFSA CLASS 3 PROVINCIAL ROADS IN IDENTIFIED AREAS OF GAUTENG PROVINCE
A4: PART B : OPERATIONAL
A6: ITEM NO | B6: DESCRIPTION | C6: UNIT | D6: QUANTITY | E6: RATE | F6: AMOUNT
A7: M1600 | B7: SURFACE TREATMENT - TEXTURE CORRECTION
A8: M160.01 | B8: Application of slurry mixed on site
B9: (a)Tack coat using 30% bitumen emulsion | C9: l | D9: 200 | E9: 25 | F9: =+E9*D9 -> 5000
B10: (b)Slurry applied for texture treatment | F10: =+E10*D10 -> 0
B11: (Coarse grading and 80/100 pen. bitumen) | F11: =+E11*D11 -> 0
B12: (i)Applied by hand | C12: m3 | D12: 16 | E12: 250 | F12: =+E12*D12 -> 4000
B13: (ii)Applied by spreader box | C13: m3 | D13: 16 | E13: 250 | F13: =+E13*D13 -> 4000
A14: M160.02 | B14: Application of slurry from commercial sources | F14: =+E14*D14 -> 0
B15: (a) Tack coat using 30% bitumen emulsion | C15: l | D15: 100 | E15: 30 | F15: =+E15*D15 -> 3000
B16: (b) Slurry applied for texture treatment | F16: =+E16*D16 -> 0
B17: (Coarse grading and 80/100 pen. bitumen) | F17: =+E17*D17 -> 0
B18: (i)Applied by hand | C18: m3 | D18: 10 | E18: 250 | F18: =+E18*D18 -> 2500
B19: (ii)Applied by spreader box | C19: m3 | D19: 10 | E19: 250 | F19: =+E19*D19 -> 2500
A20: M1610 | B20: SURFACE TREATMENT - RUT FILLING | F20: =+E20*D20 -> 0
A21: M161.01 | B21: Application of slurry for rut filling mixed on site | F21: =+E21*D21 -> 0
B22: (a) Slurry applied by spreader box with rigid squeegees in | F22: =+E22*D22 -> 0
B23: one application for rut filling (Coarse grading and | C23: m3 | D23: 20 | E23: 350 | F23: =+E23*D23 -> 7000
B24: 80/100 pen.bitumen) | F24: =+E24*D24 -> 0
A25: M161.02 | B25: Application of slurry for rut filling from commercial sources | F25: =+E25*D25 -> 0
B26: (a) Slurry applied by spreader box with rigid squeegees in | F26: =+E26*D26 -> 0
B27: one application for rut filling (Coarse grading and | C27: m3 | D27: 20 | E27: 250 | F27: =+E27*D27 -> 5000
B28: 80/100 pen.bitumen) | F28: =+E28*D28 -> 0
B29: (c) Tack coat using 30% bitumen emulsion | C29: l | D29: 100 | E29: 30 | F29: =+E29*D29 -> 3000
A30: M1600 | B30: TOTAL CARRIED FORWARD TO SUMMARY | F30: =SUM(F9:F29) -> 36000
A33: C2.14

Sheet M1700
A1: TENDER NUMBER:DRT D2_P08/02/2025
A2: EXECUTION OF ROUTINE ROAD MAINTENANCE CONTRACTS ON SELECTED RISFSA CLASS 3 PROVINCIAL ROADS IN IDENTIFIED AREAS OF GAUTENG PROVINCE
A4: PART B : OPERATIONAL
A5: ITEM NO | B5: DESCRIPTION | C5: UNIT | D5: QUANTITY | E5: RATE | F5: AMOUNT
A6: M1700 | B6: REPAIR OF SLOPE FAILURES AND WASHAWAYS
A7: BM170.05 | B7: Repair of slope failures and washaways | F7: =IF(D7=0,"",ROUND(D7*E7,2))
B8: (a)Provisional sum for repair of slope failures and washaways | C8: Prov Sum | D8: 1 | E8: 50000 | F8: 50000
B9: (b)The Contractor's overhead charges and profit in respect of sub-item BM170.05 (a) | C9: % | D9: =+E8 -> 50000 | E9: 0.15 | F9: =+E9*D9 -> 7500
A15: M1700 | B15: TOTAL CARRIED FORWARD TO SUMMARY | F15: =SUM(F6:F12) -> 57500
A17: C2.15

Sheet M2100
A1: TENDER NUMBER: DRT D2_P08/02/2025
A2: EXECUTION OF ROUTINE ROAD MAINTENANCE CONTRACTS ON SELECTED RISFSA CLASS 3 PROVINCIAL ROADS IN IDENTIFIED AREAS OF GAUTENG PROVINCE
A4: PART B : OPERATIONAL
A5: PART B : OPERATIONAL
A7: ITEM NO | B7: DESCRIPTION | C7: UNIT | D7: QUANTITY | E7: RATE | F7: AMOUNT
A8: M2100 | B8: REPAIR AND MAINTENANCE OF INLET AND OUTLET STRUCTURES
A10: M210.01 | B10: Excavation | C10: m3 | D10: 70 | E10: 85 | F10: =+E10*D10 -> 5950
A11: M210.02 | B11: Backfilling | F11: =+E11*D11 -> 0
B12: (a)Using the excavated material | C12: m3 | D12: 70 | E12: 65 | F12: =+E12*D12 -> 4550
B13: (b)Using stabilised excavated material | C13: m3 | D13: 20 | E13: 65 | F13: =+E13*D13 -> 1300
A14: BM210.03 | B14: Reconstruction of inlet and outlet structures | F14: =+E14*D14 -> 0
B15: (a)Concrete (class 20/19) | C15: m3 | D15: 20 | E15: 2700 | F15: =+E15*D15 -> 54000
B16: (b)Brickwork | C16: m3 | D16: 20 | E16: 3000 | F16: =+E16*D16 -> 60000
B17: (c ) Plastering | C17: m2 | D17: 200 | E17: 80 | F17: =+E17*D17 -> 16000
B18: (d) Pre-cast Concrete inlets (as per drwg no's N-08-v1 & N-09-v1) | C18: No | D18: 20 | E18: 4500 | F18: =+E18*D18 -> 90000
A19: BM210.04 | B19: Accessories | F19: =+E19*D19 -> 0
B20: (a)Provisional sum for the cost of accessories | C20: Prov Sum | D20: 1 | E20: 150000 | F20: 150000
B21: (b)The Contractor's overhead charges and profit in respect of sub-item BM210.04 (a) | C21: % | D21: 150000 | E21: 0.15 | F21: =+E21*D21 -> 22500
A22: M210.05 | B22: Demolition of existing structures | F22: =+E22*D22 -> 0
B23: (a) Plain concrete | C23: m3 | D23: 2 | E23: 850 | F23: =+E23*D23 -> 1700
B24: (c) Brickwork | C24: m3 | D24: 2 | E24: 850 | F24: =+E24*D24 -> 1700
A25: M210.07 | B25: Steel reinforcement | F25: =+E25*D25 -> 0
B26: (a)Mild steel bars | C26: t | D26: 1 | E26: 24000 | F26: =+E26*D26 -> 24000
B27: (b)High tensile steel bars | C27: t | D27: 1 | E27: 24000 | F27: =+E27*D27 -> 24000
B28: (c ) Welded steel mesh (Ref 311) | C28: kg | D28: 100 | E28: 25 | F28: =+E28*D28 -> 2500
A29: M210.08 | B29: Overhaul on material hauled in excess of 1,0 km | F29: =+E29*D29 -> 0
B30: (a)Excavated material to spoil | C30: m3-km | D30: 500 | E30: 10 | F30: =+E30*D30 -> 5000
B31: (b)Existing structures demolished | C31: m3-km | D31: 100 | E31: 10 | F31: =+E31*D31 -> 1000
A32: M2100 | B32: TOTAL CARRIED FORWARD TO SUMMARY | F32: =SUM(F8:F31) -> 464200
A34: C2.16

Sheet M2300
A1: TENDER NUMBER: DRT D2_P08/02/2025
A2: EXECUTION OF ROUTINE ROAD MAINTENANCE CONTRACTS ON SELECTED RISFSA CLASS 3 PROVINCIAL ROADS IN IDENTIFIED AREAS OF GAUTENG PROVINCE
A4: PART B : OPERATIONAL
A6: ITEM NO | B6: DESCRIPTION | C6: UNIT | D6: QUANTITY | E6: RATE | F6: AMOUNT
A7: M2300 | B7: CLEANING OF WATERWAY STRUCTURES
A9: BM230.01 | B9: Cleaning of waterway structures, inlet and outlet areas
B11: (a) Cleaning of waterway structures, inlet and outlet areas:
B13: Various road sections as descibed under C3.1.2.1 : Description of site | C13: month | D13: 36 | E13: 20000 | F13: =+E13*D13 -> 720000
A25: M2300 | B25: TOTAL CARRIED FORWARD TO SUMMARY | F25: =SUM(F7:F24) -> 720000
A26: C2.17

Sheet M2400
A1: TENDER NUMBER: DRT D2_P08/02/2025
A2: EXECUTION OF ROUTINE ROAD MAINTENANCE CONTRACTS ON SELECTED RISFSA CLASS 3 PROVINCIAL ROADS IN IDENTIFIED AREAS OF GAUTENG PROVINCE
A4: PART B : OPERATIONAL
A6: ITEM NO | B6: DESCRIPTION | C6: UNIT | D6: QUANTITY | E6: RATE | F6: AMOUNT
A7: M2400 | B7: CLEANING OF PREFABRICATED CULVERTS
A9: M240.01 | B9: Cleaning of prefabricated culverts, inlet and outlet areas
B11: Various road sections as descibed under C3.1.2.1 : Description of site | C11: month | D11: 36 | E11: 20000 | F11: =+E11*D11 -> 720000
A22: M2400 | B22: TOTAL CARRIED FORWARD TO SUMMARY | F22: =SUM(F7:F20) -> 720000
A24: C2.18

Sheet M2500
A1: TENDER NUMBER: DRT D2_P08/02/2025
A2: EXECUTION OF ROUTINE ROAD MAINTENANCE CONTRACTS ON SELECTED RISFSA CLASS 3 PROVINCIAL ROADS IN IDENTIFIED AREAS OF GAUTENG PROVINCE
A4: PART B : OPERATIONAL
A6: ITEM NO | B6: DESCRIPTION | C6: UNIT | D6: QUANTITY | E6: RATE | F6: AMOUNT
A7: M2500 | B7: CLEANING OF CONCRETE DRAINS AND CHANNELS
A8: BM250.01 | B8: Cleaning of concrete drainage channels:
B9: Various road sections as descibed under C3.1.2.1 :
B10: Description of site
B11: (a)(i) Hand cleaning | C11: month | D11: 36 | E11: 10000 | F11: =+E11*D11 -> 360000
B12: (ii) Machine cleaning | C12: km | D12: 1000 | E12: 35 | F12: =+E12*D12 -> 35000
B13: (b)Extra over item for all work related to Section M2500
B14: and carried out during night time on the instruction of the Engineer. | C14: % | D14: 700000 | E14: 0.15 | F14: =+E14*D14 -> 105000
A15: BM250.02 | B15: Additional cleaning of concrete drainage channels:
B16: (c)Machine cleaning | C16: h | D16: 60 | E16: 1500 | F16: =+E16*D16 -> 90000
A24: M2500 | B24: TOTAL CARRIED FORWARD TO SUMMARY | F24: =SUM(F7:F23) -> 590000
A26: C2.19

Sheet M2600
A1: TENDER NUMBER: DRT D2_P08/02/2025
A2: EXECUTION OF ROUTINE ROAD MAINTENANCE CONTRACTS ON SELECTED RISFSA CLASS 3 PROVINCIAL ROADS IN IDENTIFIED AREAS OF GAUTENG PROVINCE
A4: PART B : OPERATIONAL
A5: ITEM NO | B5: DESCRIPTION | C5: UNIT | D5: QUANTITY | E5: RATE | F5: AMOUNT
A6: M2600 | B6: CLEANING AND MAINTENANCE OF EXISTING EARTH CHANNELS
A8: M260.01 | B8: Cleaning earth drains and channels | C8: m3 | D8: 240 | E8: 65 | F8: =+E8*D8 -> 15600
A9: M260.02 | B9: Repairing of earth drains and channels | C9: m3 | D9: 800 | E9: 65 | F9: =+E9*D9 -> 52000
A10: M260.03 | B10: Banks and dykes | C10: m3 | D10: 160 | E10: 650 | F10: =+E10*D10 -> 104000
A11: M260.04 | B11: Overhaul on material hauled in excess of 1,0 km | C11: m3-km | D11: 1600 | E11: 10 | F11: =+E11*D11 -> 16000
A21: M2600 | B21: TOTAL CARRIED FORWARD TO SUMMARY | F21: =SUM(F6:F20) -> 187600
A23: C2.20

Sheet M2700
A1: TENDER NUMBER: DRT D2_P08/02/2025
A2: EXECUTION OF ROUTINE ROAD MAINTENANCE CONTRACTS ON SELECTED RISFSA CLASS 3 PROVINCIAL ROADS IN IDENTIFIED AREAS OF GAUTENG PROVINCE
A4: PART B : OPERATIONAL
A6: ITEM NO | B6: DESCRIPTION | C6: UNIT | D6: QUANTITY | E6: RATE | F6: AMOUNT
A7: M2700 | B7: EDGE BUILD-UP REMOVAL
A8: M270.01 | B8: Removal of edge build-ups:
B9: Various road sections as descibed under C3.1.2.1 : Description of site | C9: month | D9: 36 | E9: 10000 | F9: =+E9*D9 -> 360000
A20: M2700 | B20: TOTAL CARRIED FORWARD TO SUMMARY | F20: =SUM(F7:F19) -> 360000
A22: C2.21

Sheet M2800
A1: TENDER NUMBER: DRT D2_P08/02/2025
A2: EXECUTION OF ROUTINE ROAD MAINTENANCE CONTRACTS ON SELECTED RISFSA CLASS 3 PROVINCIAL ROADS IN IDENTIFIED AREAS OF GAUTENG PROVINCE
A4: PART B : OPERATIONAL
A6: ITEM NO | B6: DESCRIPTION | C6: UNIT | D6: QUANTITY | E6: RATE | F6: AMOUNT
B7: CONCRETE CHANNEL CONSTRUCTION AND
A8: M2800 | B8: MAINTENANCE OF EXISTING CHANNELS
A9: M280.01 | B9: Excavation
B10: (a) Open drains
B11: (i)Soft material | C11: m3 | D11: 160 | E11: 85 | F11: =+E11*D11 -> 13600
B12: (ii)Hard material | C12: m3 | D12: 16 | E12: 450 | F12: =+E12*D12 -> 7200
B13: (b) Chutes and kerb-channel combination | F13: =+E13*D13 -> 0
B14: (i) Soft material | C14: m3 | D14: 56 | E14: 150 | F14: =+E14*D14 -> 8400
A15: M280.02 | B15: Cast in situ concrete | F15: =+E15*D15 -> 0
B16: (a)Linings (Class 20/19) | C16: m3 | D16: 24 | E16: 2600 | F16: =+E16*D16 -> 62400
B17: (b)Chutes (Class 20/19) | C17: m3 | D17: 10 | E17: 2600 | F17: =+E17*D17 -> 26000
B18: (c)Channels for kerb and channel (Class 20/19) | C18: m3 | D18: 10 | E18: 2600 | F18: =+E18*D18 -> 26000
A19: M280.03 | B19: Concrete screed or backfill below chutes (Class 20/19) | C19: m3 | D19: 10 | E19: 2600 | F19: =+E19*D19 -> 26000
A20: M280.04 | B20: Precast concrete kerbing and chutes | F20: =+E20*D20 -> 0
B21: (a)Kerbing (SABS figure 3) | C21: m | D21: 10 | E21: 250 | F21: =+E21*D21 -> 2500
B22: (b)Chutes (SABS figure 7) | C22: m | D22: 10 | E22: 250 | F22: =+E22*D22 -> 2500
A23: M280.05 | B23: Steel reinforcement | F23: =+E23*D23 -> 0
B24: (c)Welded steel mesh | C24: kg | D24: 160 | E24: 25 | F24: =+E24*D24 -> 4000
B25: Sealed joints in concrete lining of open drains ("Flexicell" or | F25: =+E25*D25 -> 0
A26: M280.06 | B26: similar) | C26: m | D26: 160 | E26: 65 | F26: =+E26*D26 -> 10400
A27: M280.07 | B27: Demolition and removal of damaged existing structures | F27: =+E27*D27 -> 0
B28: (a)Plain concrete | C28: m3 | D28: 16 | E28: 850 | F28: =+E28*D28 -> 13600
B29: (b)Kerbing and channelling | C29: m3 | D29: 16 | E29: 550 | F29: =+E29*D29 -> 8800
A30: M280.09 | B30: Overhaul on material hauled in excess of 1,0 km | F30: =+E30*D30 -> 0
F31: =+E31*D31 -> 0
B32: (a)Excavated material to spoil | C32: m3-km | D32: 260 | E32: 10 | F32: =+E32*D32 -> 2600
B33: (b)Existing structures demolished | C33: m3-km | D33: 260 | E33: 10 | F33: =+E33*D33 -> 2600
A54: M2800 | B54: TOTAL CARRIED FORWARD TO SUMMARY | F54: =SUM(F7:F53) -> 216600
A56: C2.22

Sheet M3100
A1: TENDER NUMBER: DRT D2_P08/02/2025
A2: EXECUTION OF ROUTINE ROAD MAINTENANCE CONTRACTS ON SELECTED RISFSA CLASS 3 PROVINCIAL ROADS IN IDENTIFIED AREAS OF GAUTENG PROVINCE
A4: PART B : OPERATIONAL
A6: ITEM NO | B6: DESCRIPTION | C6: UNIT | D6: QUANTITY | E6: RATE | F6: AMOUNT
A7: M3100 | B7: FENCING
A8: M310.01 | B8: Clearing fence line 2 m wide strip | C8: km | D8: 4 | E8: 50000 | F8: =+E8*D8 -> 200000
A9: M310.02 | B9: Erection of new fences | F9: =+E9*D9 -> 0
B10: (a)Stock-proof fences | C10: m | D10: 4500 | E10: 80 | F10: =+E10*D10 -> 360000
B11: (b)Vermin-proof fences | C11: m | D11: 1300 | E11: 80 | F11: =+E11*D11 -> 104000
B12: (c)Pedestrian fences | C12: m | D12: 240 | E12: 80 | F12: =+E12*D12 -> 19200
B13: (d)Security fences | C13: m | D13: 240 | E13: 200 | F13: =+E13*D13 -> 48000
B14: (e)Steel palisade fences | C14: m | D14: 160 | E14: 1800 | F14: =+E14*D14 -> 288000
B15: (f)Concrete palisade fences | C15: m | D15: 160 | E15: 1800 | F15: =+E15*D15 -> 288000
A16: M310.03 | B16: Repair of existing fences of less than 100 m lengths | F16: =+E16*D16 -> 0
B17: (a)Stock-proof fences | C17: m | D17: 240 | E17: 75 | F17: =+E17*D17 -> 18000
B18: (b)Vermin-proof fences | C18: m | D18: 240 | E18: 75 | F18: =+E18*D18 -> 18000
B19: (c)Pedestrian fences | C19: m | D19: 240 | E19: 75 | F19: =+E19*D19 -> 18000
B20: (d)Security fences | C20: m | D20: 24 | E20: 450 | F20: =+E20*D20 -> 10800
B21: (e)Steel palisade fences | C21: m | D21: 24 | E21: 450 | F21: =+E21*D21 -> 10800
B22: (f)Concrete palisade fences | C22: m | D22: 24 | E22: 800 | F22: =+E22*D22 -> 19200
A23: M310.04 | B23: Repair of existing fence of more than 100 m lengths | F23: =+E23*D23 -> 0
B24: (a)Stock-proof fences | C24: m | D24: 10000 | E24: 20 | F24: =+E24*D24 -> 200000
B25: (b)Vermin-proof fences | C25: m | D25: 240 | E25: 45 | F25: =+E25*D25 -> 10800
B26: (c)Pedestrian fences | C26: m | D26: 100 | E26: 45 | F26: =+E26*D26 -> 4500
B27: (d)Security fences | C27: m | D27: 500 | E27: 120 | F27: =+E27*D27 -> 60000
A28: M3100 | B28: TOTAL CARRIED FORWARD | F28: =SUM(F7:F27) -> 1677300
A30: C2.23

Sheet M3100-C
A1: TENDER NUMBER: DRT D2_P08/02/2025
A2: EXECUTION OF ROUTINE ROAD MAINTENANCE CONTRACTS ON SELECTED RISFSA CLASS 3 PROVINCIAL ROADS IN IDENTIFIED AREAS OF GAUTENG PROVINCE
A4: PART B : OPERATIONAL
A6: ITEM NO | B6: DESCRIPTION | C6: UNIT | D6: QUANTITY | E6: RATE | F6: AMOUNT
B7: TOTAL BROUGHT FORWARD | F7: =+'M3100'!F28 -> 1677300
A8: M310.05 | B8: Supply of fencing material for new and repaired fences
B9: (a) Barbed wire (high tensile grade single strand 3.15mm x | F9: =IF(D9=0,"",ROUND(D9*E9,2))
B10: 2.50mm, oval shaped, 2.81mm equivalent diameter fully galvanised) | C10: km | D10: 5 | E10: 185 | F10: =+E10*D10 -> 925
B11: (b) Smooth wire (high tensile grade, 2.24mm diameter fully galvanised) | C11: km | D11: 6 | E11: 185 | F11: =+E11*D11 -> 1110
B12: (c) Diamond mesh | C12: m2 | D12: 140 | E12: 450 | F12: =+E12*D12 -> 63000
B13: (d) Wire netting square | C13: m2 | D13: 160 | E13: 350 | F13: =+E13*D13 -> 56000
B14: (e) Razor tape wire (with core thickness of 2,5 mm) | C14: km | D14: 5 | E14: 12000 | F14: =+E14*D14 -> 60000
B15: (f) Corner, end and straining posts | C15: No | D15: 30 | E15: 1200 | F15: =+E15*D15 -> 36000
B16: (g) Standards (2.5kg/m "V" sections, complete with holes at | F16: =+E16*D16 -> 0
B17: 50mm c/c) | F17: =+E17*D17 -> 0
B18: (i)1800mm | C18: No | D18: 150 | E18: 350 | F18: =+E18*D18 -> 52500
B19: (ii)2100mm | C19: No | D19: 150 | E19: 450 | F19: =+E19*D19 -> 67500
B20: (iii)2400mm | C20: No | D20: 100 | E20: 650 | F20: =+E20*D20 -> 65000
B21: (h) Droppers (0.56kg/m ridgeback pattern) | F21: =+E21*D21 -> 0
B22: (i) 1500mm | C22: No | D22: 400 | E22: 250 | F22: =+E22*D22 -> 100000
B23: (ii)1800mm | C23: No | D23: 130 | E23: 350 | F23: =+E23*D23 -> 45500
B24: (iii)2100mm | C24: No | D24: 150 | E24: 450 | F24: =+E24*D24 -> 67500
B25: (j) Steel palisade fence height 2,4 m | C25: m | D25: 24 | E25: 1800 | F25: =+E25*D25 -> 43200
B26: (k) Concrete palisade fence height 2,4 m | C26: m | D26: 24 | E26: 2800 | F26: =+E26*D26 -> 67200
A27: M310.08 | B27: Dismantling of existing and damaged fences | C27: m | D27: 5000 | E27: 60 | F27: =+E27*D27 -> 300000
A28: BM310.11 | B28: Procurement of specialised fencing: | F28: =+E28*D28 -> 0
B29: (a)Procurement and erection of specialised fencing | C29: Prov Sum | D29: 1 | E29: 50000 | F29: 50000
B30: (b)The Contractor's overhead charges and profit in respect of sub-item BM310.12 (a) | C30: % | D30: 50000 | E30: 0.15 | F30: =+E30*D30 -> 7500
A31: M3100 | B31: TOTAL CARRIED FORWARD TO SUMMARY | F31: =SUM(F7:F30) -> 2760235
A32: C2.24

Sheet M3200
A1: TENDER NUMBER: DRT D2_P08/02/2025
A2: EXECUTION OF ROUTINE ROAD MAINTENANCE CONTRACTS ON SELECTED RISFSA CLASS 3 PROVINCIAL ROADS IN IDENTIFIED AREAS OF GAUTENG PROVINCE
A4: PART B : OPERATIONAL
A5: ITEM NO | B5: DESCRIPTION | C5: UNIT | D5: QUANTITY | E5: RATE | F5: AMOUNT
A6: M3200 | B6: COLLECTION AND REMOVAL OF DEBRIS AND LITTER
A7: M320.01 | B7: Clearing of the road reserve
B8: (a) Urban roads:
B9: Various road sections as descibed under C3.1.2.1 : Description of site | C9: month | D9: 36 | E9: 20000 | F9: =+E9*D9 -> 720000
A10: M320.02 | B10: Additional clearing of: | F10: =+E10*D10 -> 0
B11: (a) Lay-byes | C11: No | D11: 25 | E11: 5000 | F11: =+E11*D11 -> 125000
B12: (c) Interchanges: | C12: No | D12: 30 | E12: 5000 | F12: =+E12*D12 -> 150000
F13: =+E13*D13 -> 0
A22: M3200 | B22: TOTAL CARRIED FORWARD | F22: =SUM(F6:F20) -> 995000
A24: C2.25

Sheet M3300
A1: TENDER NUMBER:DRT D2_P08/02/2025
A2: EXECUTION OF ROUTINE ROAD MAINTENANCE CONTRACTS ON SELECTED RISFSA CLASS 3 PROVINCIAL ROADS IN IDENTIFIED AREAS OF GAUTENG PROVINCE
A4: PART B : OPERATIONAL
A5: ITEM NO | B5: DESCRIPTION | C5: UNIT | D5: QUANTITY | E5: RATE | F5: AMOUNT
A6: M3300 | B6: SHOULDER REPAIRS
A7: M330.01 | B7: Reinstating gravel shoulders
B8: (a)Ripping, watering, mixing, placing and compacting existing shoulders to 93% of modified AASHTO density | C8: m3 | D8: 2000 | E8: 65 | F8: =+E8*D8 -> 130000
B9: (b)Extra over sub-item M330.01 (a) for adding extra material from borrowpits outside the road reserve | C9: m3 | D9: 1300 | E9: 65 | F9: =+E9*D9 -> 84500
B10: (c ) Extra over sub-item M330.01 (a) for stabilising material | C10: m3 | D10: 1300 | E10: 150 | F10: =+E10*D10 -> 195000
B11: (d) Blading | C11: km | D11: 12 | E11: 12000 | F11: =+E11*D11 -> 144000
B12: (e ) Cutting of mitre drains | C12: m | D12: 100 | E12: 65 | F12: =+E12*D12 -> 6500
B13: Overhaul on material hauled in excess of 1,0 km | C13: m3-km | D13: 3500 | E13: 10 | F13: =+E13*D13 -> 35000
A21: M3300 | B21: TOTAL CARRIED FORWARD TO SUMMARY | F21: =SUM(F6:F20) -> 595000
A23: C2.26

Sheet M4100
A1: TENDER NUMBER: DRT D2_P08/02/2025
A2: EXECUTION OF ROUTINE ROAD MAINTENANCE CONTRACTS ON SELECTED RISFSA CLASS 3 PROVINCIAL ROADS IN IDENTIFIED AREAS OF GAUTENG PROVINCE
A4: PART B : OPERATIONAL
A5: ITEM NO | B5: DESCRIPTION | C5: UNIT | D5: QUANTITY | E5: RATE | F5: AMOUNT
A6: M4100 | B6: ERECTION AND REPAIR OF PERMANENT ROAD TRAFFIC SIGNS
A8: M410.01 | B8: Erection or re-erection of road signs with a surface area of:
B9: (a)Up to 2 m2 | C9: m2 | D9: 120 | E9: 500 | F9: =+E9*D9 -> 60000
B10: (b)Exceeding 2 m2 but not 10 m2 | C10: m2 | D10: 60 | E10: 750 | F10: =+E10*D10 -> 45000
B11: (c ) Exceeding 10 m2 | C11: m2 | D11: 32 | E11: 850 | F11: =+E11*D11 -> 27200
B12: (d)Overhead road signs | C12: m2 | D12: 16 | E12: 950 | F12: =+E12*D12 -> 15200
A13: BM410.02 | B13: Road sign supports (overhead road sign strutures excluded) | F13: =+E13*D13 -> 0
B14: (b) Timber: | F14: =+E14*D14 -> 0
B15: (i)100mm diameter | C15: m | D15: 56 | E15: 250 | F15: =+E15*D15 -> 14000
B16: (ii)125mm diameter | C16: m | D16: 56 | E16: 350 | F16: =+E16*D16 -> 19600
B17: (iii)150mm diameter | C17: m | D17: 56 | E17: 450 | F17: =+E17*D17 -> 25200
B18: (iv)175mm diameter | C18: m | D18: 56 | E18: 650 | F18: =+E18*D18 -> 36400
A19: BM410.03 | B19: Reference marker boards | F19: =+E19*D19 -> 0
B20: (a)Reference marker board and post Refer drawing C-10-v1 & C-11-v1 | C20: No | D20: 100 | E20: 1000 | F20: =+E20*D20 -> 100000
B21: (b)Reference marker board Refer drawing C-10-v1 & C-11-v1 | C21: No | D21: 100 | E21: 1000 | F21: =+E21*D21 -> 100000
B22: Excavation and backfilling for road sign supports (not | F22: =+E22*D22 -> 0
A23: M410.04 | B23: applicable to reference marker board posts) | C23: m3 | D23: 100 | E23: 450 | F23: =+E23*D23 -> 45000
A24: M410.05 | B24: Extra over item M410.04 for cement-treated soil backfill | C24: m3 | D24: 20 | E24: 65 | F24: =+E24*D24 -> 1300
B25: Dismantling, storing and re-erecting road signs with a | F25: =+E25*D25 -> 0
A29: M4100 | B29: TOTAL CARRIED FORWARD | F29: =SUM(F6:F26) -> 488900
A31: C2.27

Sheet M4100-C
A1: TENDER NUMBER: DRT D2_P08/02/2025
A2: EXECUTION OF ROUTINE ROAD MAINTENANCE CONTRACTS ON SELECTED RISFSA CLASS 3 PROVINCIAL ROADS IN IDENTIFIED AREAS OF GAUTENG PROVINCE
A4: PART B : OPERATIONAL
A5: ITEM NO | B5: DESCRIPTION | C5: UNIT | D5: QUANTITY | E5: RATE | F5: AMOUNT
B6: BROUGHT FORWARD | F6: =+'M4100'!F29 -> 488900
A7: M410.07 | B7: Dismantling, storing and re-erecting road signs with a | F7: =IF(D7=0,"",ROUND(D7*E7,2))
B8: surface area of: | F8: =IF(D8=0,"",ROUND(D8*E8,2))
B9: (a)Up to 2 m2 | C9: No | D9: 120 | E9: 250 | F9: =+E9*D9 -> 30000
B10: (b)Exceeding 2 m2 but not 10 m2 | C10: No | D10: 60 | E10: 350 | F10: =+E10*D10 -> 21000
B11: (c)Exceeding 10 m2 | C11: No | D11: 32 | E11: 450 | F11: =+E11*D11 -> 14400
A12: M410.08 | B12: Dismantling and storing road signs with a surface area of: | F12: =+E12*D12 -> 0
B13: (a)Up to 2 m2 | C13: No | D13: 16 | E13: 250 | F13: =+E13*D13 -> 4000
B14: (b)Exceeding 2 m2 but not 10 m2 | C14: No | D14: 56 | E14: 350 | F14: =+E14*D14 -> 19600
B15: (c)Exceeding 10 m2 | C15: No | D15: 56 | E15: 450 | F15: =+E15*D15 -> 25200
A16: BM410.10 | B16: Hazard plates (refer drawing C-07-v1) | F16: =+E16*D16 -> 0
B17: (a ) W401 sign (150 x 600mm) | F17: =+E17*D17 -> 0
B18: (i)Sign only | C18: No | D18: 56 | E18: 150 | F18: =+E18*D18 -> 8400
B19: (ii)Post only | C19: No | D19: 56 | E19: 200 | F19: =+E19*D19 -> 11200
B20: (b) W401 sign (200 x 800mm) | F20: =+E20*D20 -> 0
B21: (i)Sign only | C21: No | D21: 100 | E21: 250 | F21: =+E21*D21 -> 25000
B22: (ii)Post only | C22: No | D22: 100 | E22: 250 | F22: =+E22*D22 -> 25000
B23: (c ) W401 sign (300 x 1200mm) | F23: =+E23*D23 -> 0
B24: (i)Sign only | C24: No | D24: 18 | E24: 150 | F24: =+E24*D24 -> 2700
B25: (ii)Post only | C25: No | D25: 18 | E25: 150 | F25: =+E25*D25 -> 2700
A26: M410.11 | B26: Repair of road sign faces | C26: m2 | D26: 25 | E26: 150 | F26: =+E26*D26 -> 3750
A27: M410.12 | B27: Concrete in road sign footings (class 20/19) | C27: m3 | D27: 5 | E27: 2500 | F27: =+E27*D27 -> 12500
A28: M4100 | B28: TOTAL CARRIED FORWARD | F28: =SUM(F6:F27) -> 694350
A29: C2.27

Sheet M4100-C1
A1: TENDER NUMBER: DRT D2_P08/02/2025
A2: EXECUTION OF ROUTINE ROAD MAINTENANCE CONTRACTS ON SELECTED RISFSA CLASS 3 PROVINCIAL ROADS IN IDENTIFIED AREAS OF GAUTENG PROVINCE
A4: PART B : OPERATIONAL
A5: ITEM NO | B5: DESCRIPTION | C5: UNIT | D5: QUANTITY | E5: RATE | F5: AMOUNT
B6: BROUGHT FORWARD | F6: =+'M4100-C'!F28 -> 694350
A7: M410.13 | B7: Attachment of overlays to existing road signs (diamond grade, retro reflective) | C7: m2 | D7: 56 | E7: 950 | F7: =+E7*D7 -> 53200
A8: M410.14 | B8: Removal of road sign supports | C8: No | D8: 20 | E8: 350 | F8: =+E8*D8 -> 7000
A9: M410.15 | B9: Procurement of road signs
B10: (a)Purchase of manufactured road signs | C10: Prov Sum | D10: 1 | E10: 50000 | F10: 50000
B11: (b)The Contractor's overhead charges and profit in respect of sub-item M410.15 (a) | C11: % | D11: 50000 | E11: 0.15 | F11: =+E11*D11 -> 7500
A12: M410.16 | B12: Erection and repairs of gantry structures
B14: (a) Erection and repairs of gantry structures | C14: Prov Sum | D14: 1 | E14: 80000 | F14: 80000
B16: (b) The Contractor's overhead charges and profit in respect of sub-item M410.16 (a) | C16: % | D16: 80000 | E16: 0.15 | F16: =+E16*D16 -> 12000
A18: BM410.17 | B18: Extra over item for all work related to Section M4100 and carried out during night time on the instruction of the Engineer. | C18: % | D18: 700000 | E18: 0.15 | F18: =+E18*D18 -> 105000
A22: M4100 | B22: TOTAL CARRIED FORWARD TO SUMMARY | F22: =SUM(F6:F21) -> 1009050
A24: C2.29

Sheet M4200
A1: TENDER NUMBER: DRT D2_P08/02/2025
A2: EXECUTION OF ROUTINE ROAD MAINTENANCE CONTRACTS ON SELECTED RISFSA CLASS 3 PROVINCIAL ROADS IN IDENTIFIED AREAS OF GAUTENG PROVINCE
A4: PART B : OPERATIONAL
A5: ITEM NO | B5: DESCRIPTION | C5: UNIT | D5: QUANTITY | E5: RATE | F5: AMOUNT
A6: M4200 | B6: ROAD SIGN CLEANING
A7: M420.01 | B7: Road sign cleaning
B8: (a)Cleaning of guardrail reflectors (all types) | C8: No | D8: 1600 | E8: 20 | F8: =+E8*D8 -> 32000
B9: (b)Cleaning of road signs | F9: =+E9*D9 -> 0
B10: (i)Up to 2 m2 | C10: No | D10: 700 | E10: 150 | F10: =+E10*D10 -> 105000
B11: (ii)Exceeding 2 m2 but not 10 m2 | C11: No | D11: 160 | E11: 250 | F11: =+E11*D11 -> 40000
B12: (iii)Exceeding 10 m2 | C12: No | D12: 80 | E12: 350 | F12: =+E12*D12 -> 28000
B13: (c ) Cleaning of overhead road signs (all sizes) | C13: No | D13: 6 | E13: 450 | F13: =+E13*D13 -> 2700
A14: M420.02 | B14: Removal of graffiti | F14: =+E14*D14 -> 0
B15: (a)From road signs | C15: m2 | D15: 56 | E15: 200 | F15: =+E15*D15 -> 11200
B16: (b)From structures | C16: m2 | D16: 56 | E16: 200 | F16: =+E16*D16 -> 11200
A17: M420.03 | B17: Painting of metal road sign elements | F17: =+E17*D17 -> 0
B18: (a)Sign supports | C18: l | D18: 32 | E18: 25 | F18: =+E18*D18 -> 800
B19: (b)Sign frames | C19: l | D19: 32 | E19: 25 | F19: =+E19*D19 -> 800
A20: M4210 | B20: REMOVAL OF ILLEGAL SIGNS | F20: =+E20*D20 -> 0
A21: BM421.01 | B21: Removal of illegal signs | F21: =+E21*D21 -> 0
B22: (a) Signs within the road reserve | F22: =+E22*D22 -> 0
B23: (i)From 0,5 m2 to 2 m2 | C23: No | D23: 32 | E23: 350 | F23: =+E23*D23 -> 11200
B24: (ii)Exceeding 2 m2 but not 6 m2 | C24: No | D24: 16 | E24: 450 | F24: =+E24*D24 -> 7200
B25: (iii)Exceeding 6 m2 | C25: No | D25: 8 | E25: 650 | F25: =+E25*D25 -> 5200
B26: (b) Signs outside the road reserve | F26: =+E26*D26 -> 0
B27: (i)Any size | C27: Prov Sum | D27: 1 | E27: 50000 | F27: 50000
B28: (ii)The Contractor's overhead charges and profit in respect of sub-item M421.01 (b) (i) | C28: % | D28: 50000 | E28: 0.15 | F28: =+E28*D28 -> 7500
A29: M4200 | B29: TOTAL CARRIED FORWARD TO SUMMARY | F29: =SUM(F6:F28) -> 312800

Sheet M4300
A1: TENDER NUMBER: DRT D2_P08/02/2025
A2: EXECUTION OF ROUTINE ROAD MAINTENANCE CONTRACTS ON SELECTED RISFSA CLASS 3 PROVINCIAL ROADS IN IDENTIFIED AREAS OF GAUTENG PROVINCE
A4: PART B : OPERATIONAL
A6: ITEM NO | B6: DESCRIPTION | C6: UNIT | D6: QUANTITY | E6: RATE | F6: AMOUNT
A7: M4300 | B7: ROADSTUDS
A9: M430.01 | B9: Installation of roadstuds
B11: (a) Installation of roadstuds | C11: Prov Sum | D11: 1.00 | E11: 50000 | F11: 50000
B12: (b) The Contractor's overhead charges and profit in respect of sub-item M430.01 (a) | C12: % | D12: 50000 | E12: 0.15 | F12: =+E12*D12 -> 7500
A20: M4300 | B20: TOTAL CARRIED FORWARD TO SUMMARY | F20: =SUM(F8:F19) -> 57500
A22: C2.31

Sheet M4400
A1: TENDER NUMBER: DRT D2_P08/02/2025
A2: EXECUTION OF ROUTINE ROAD MAINTENANCE CONTRACTS ON SELECTED RISFSA CLASS 3 PROVINCIAL ROADS IN IDENTIFIED AREAS OF GAUTENG PROVINCE
A4: PART B : OPERATIONAL
A6: ITEM NO | B6: DESCRIPTION | C6: UNIT | D6: QUANTITY | E6: RATE | F6: AMOUNT
A7: M4400 | B7: GUARDRAIL ERECTION AND MAINTENANCE
A8: M440.01 | B8: Supply and erection of new galvanised guardrails
B9: (i)Conventional guardrail (3.8m eff. length) | C9: m | D9: 160 | E9: 200 | F9: =+E9*D9 -> 32000
B10: (ii)EU standard guardrail (4.0m eff Length) | C10: m | D10: 16 | E10: 200 | F10: =+E10*D10 -> 3200
B11: Supply and erection of new galvanised curved guardrails | F11: =+E11*D11 -> 0
A12: M440.02 | B12: factory bent to a radius of less than 45 m | C12: m | D12: 16 | E12: 700 | F12: =+E12*D12 -> 11200
A13: M440.03 | B13: Extra over for erection of guardrail posts | F13: =+E13*D13 -> 0
B14: (a)Additional timber posts for items M440.01 and M440.02 | C14: No | D14: 80 | E14: 250 | F14: =+E14*D14 -> 20000
B15: (b)Backfilling guardrail post with soilcrete | C15: No | D15: 16 | E15: 200 | F15: =+E15*D15 -> 3200
B16: (c ) Backfilling guardrail post with concrete | C16: No | D16: 3 | E16: 200 | F16: =+E16*D16 -> 600
A17: M440.04 | B17: End units | F17: =+E17*D17 -> 0
B18: (a)End wings | C18: No | D18: 3 | E18: 550 | F18: =+E18*D18 -> 1650
B19: (b)Terminal sections in accordance with the drawings where single guardrail sections are used | C19: No | D19: 5 | E19: 2500 | F19: =+E19*D19 -> 12500
B20: (c)Terminal sections in accordance with the drawings where double guardrail sections are used | C20: No | D20: 5 | E20: 2500 | F20: =+E20*D20 -> 12500
A21: M440.05 | B21: Guardrail reflectors | C21: No | D21: 80 | E21: 80 | F21: =+E21*D21 -> 6400
A22: BM440.06 | B22: Removal of damaged guardrails and re-erection of guardrails with new, recovered or renovated material | F22: =+E22*D22 -> 0
B23: (a) Guardrails | F23: =+E23*D23 -> 0
B24: (i)Conventional guardrail (3.8m eff. length) | C24: m | D24: 1600 | E24: 75 | F24: =+E24*D24 -> 120000
B25: (ii)EU standard guardrail (4.0m eff Length) | C25: m | D25: 32 | E25: 250 | F25: =+E25*D25 -> 8000
B26: (b) End wings | F26: =+E26*D26 -> 0
B27: (i)Conventional guardrail (3.8m eff. length) | C27: No | D27: 16 | E27: 220 | F27: =+E27*D27 -> 3520
B28: (ii)EU standard guardrail (4.0m eff Length) | C28: No | D28: 4 | E28: 220 | F28: =+E28*D28 -> 880
B29: (c ) Terminal sections with single guardrails | F29: =+E29*D29 -> 0
B30: (i) Conventional guardrail (3.8m eff. length) | C30: No | D30: 6 | E30: 220 | F30: =+E30*D30 -> 1320
B31: (ii) EU standard guardrail (4.0m eff Length) | C31: No | D31: 3 | E31: 220 | F31: =+E31*D31 -> 660
A32: M4400 | B32: TOTAL CARRIED FORWARD | F32: =SUM(F7:F31) -> 237630

Sheet M4400-C
A1: TENDER NUMBER:DRT D2_P08/02/2025
A2: EXECUTION OF ROUTINE ROAD MAINTENANCE CONTRACTS ON SELECTED RISFSA CLASS 3 PROVINCIAL ROADS IN IDENTIFIED AREAS OF GAUTENG PROVINCE
A4: PART B : OPERATIONAL
A6: ITEM NO | B6: DESCRIPTION | C6: UNIT | D6: QUANTITY | E6: RATE | F6: AMOUNT
B7: BROUGHT FORWARD | F7: =+'M4400'!F32 -> 237630
B8: (d) Terminal sections with double guardrails | F8: =+E8*D8 -> 0
B9: (i)Conventional guardrail (3.8m eff. length) | C9: No | D9: 56 | E9: 650 | F9: =+E9*D9 -> 36400
B10: (ii)EU standard guardrail (4.0m eff Length) | C10: No | D10: 3 | E10: 650 | F10: =+E10*D10 -> 1950
B11: (e) Guardrail posts | F11: =+E11*D11 -> 0
B12: (i)Conventional guardrail (3.8m eff. length) | C12: No | D12: 150 | E12: 150 | F12: =+E12*D12 -> 22500
B13: (ii)EU standard guardrail (4.0m eff Length) | C13: No | D13: 25 | E13: 150 | F13: =+E13*D13 -> 3750
A14: BM440.07 | B14: Supply of renovated guardrail material | F14: =+E14*D14 -> 0
B15: (a) Guardrails | C15: m | D15: 240 | E15: 200 | F15: =+E15*D15 -> 48000
B16: Supply of new material required for the re-erection of | F16: =+E16*D16 -> 0
A17: BM440.08 | B17: guardrails | F17: =+E17*D17 -> 0
B18: (a) Guardrails (galvanised) | F18: =+E18*D18 -> 0
B19: (i)Conventional guardrail (3.8m eff. length) | C19: m | D19: 1200 | E19: 200 | F19: =+E19*D19 -> 240000
B20: (ii)EU standard guardrail (4.0m eff Length) | C20: m | D20: 24 | E20: 200 | F20: =+E20*D20 -> 4800
B21: (b) Curved guardrails | F21: =+E21*D21 -> 0
B22: (i)Conventional guardrail (3.8m eff. length) | C22: m | D22: 24 | E22: 700 | F22: =+E22*D22 -> 16800
B23: (ii)EU standard guardrail (4.0m eff Length) | C23: m | D23: 2 | E23: 700 | F23: =+E23*D23 -> 1400
B24: (c ) Timber posts | C24: No | D24: 250 | E24: 250 | F24: =+E24*D24 -> 62500
B25: (d) Steel posts | F25: =+E25*D25 -> 0
B26: (i) Conventional guardrail (3.8m eff. length) | C26: No | D26: 8 | E26: 350 | F26: =+E26*D26 -> 2800
B27: (ii) EU standard guardrail (4.0m eff Length) | C27: No | D27: 8 | E27: 350 | F27: =+E27*D27 -> 2800
B28: (e) Spacer blocks | F28: =+E28*D28 -> 0
B29: (i)Conventional guardrail (3.8m eff. length) | C29: No | D29: 300 | E29: 50 | F29: =+E29*D29 -> 15000
B30: (ii)EU standard guardrail (4.0m eff Length) | C30: No | D30: 56 | E30: 50 | F30: =+E30*D30 -> 2800
A31: (f) | B31: (f) Guardrail reflectors | F31: =+E31*D31 -> 0
B32: (i)Type D1 (A) | C32: No | D32: 480 | E32: 80 | F32: =+E32*D32 -> 38400
B33: (ii)Type D1 (B) | C33: No | D33: 480 | E33: 80 | F33: =+E33*D33 -> 38400
A34: M4400 | B34: TOTAL CARRIED FORWARD | F34: =SUM(F7:F33) -> 775930

Sheet M4400-C1
A1: TENDER NUMBER: DRT D2_P08/02/2025
A2: EXECUTION OF ROUTINE ROAD MAINTENANCE CONTRACTS ON SELECTED RISFSA CLASS 3 PROVINCIAL ROADS IN IDENTIFIED AREAS OF GAUTENG PROVINCE
A4: PART B : OPERATIONAL
A6: ITEM NO | B6: DESCRIPTION | C6: UNIT | D6: QUANTITY | E6: RATE | F6: AMOUNT
B7: BROUGHT FORWARD | F7: =+'M4400-C'!F34 -> 775930
B8: (g) End wings | F8: =IF(D8=0,"",ROUND(D8*E8,2))
B9: (i)Conventional guardrail (3.8m eff. length) | C9: No | D9: 9 | E9: 650 | F9: =+E9*D9 -> 5850
B10: (ii)EU standard guardrail (4.0m eff Length) | C10: No | D10: 3 | E10: 650 | F10: =+E10*D10 -> 1950
B11: (h) Terminal sections with single guardrails | F11: =+E11*D11 -> 0
B12: (i) Conventional guardrail (3.8m eff. length) | C12: No | D12: 9 | E12: 2500 | F12: =+E12*D12 -> 22500
B13: (ii) EU standard guardrail (4.0m eff Length) | C13: No | D13: 3 | E13: 2500 | F13: =+E13*D13 -> 7500
B14: (i) Terminal sections with double guardrails | F14: =+E14*D14 -> 0
B15: (i) Conventional guardrail (3.8m eff. length) | C15: No | D15: 6 | E15: 2500 | F15: =+E15*D15 -> 15000
B16: (ii) EU standard guardrail (4.0m eff Length) | C16: No | D16: 3 | E16: 2500 | F16: =+E16*D16 -> 7500
A17: M440.09 | B17: Drilling and blasting holes for guardrail posts | C17: No | D17: 26 | E17: 950 | F17: =+E17*D17 -> 24700
A18: M440.10 | B18: Reinstatement of concrete to guardrail posts (class 20/19) | C18: m3 | D18: 6 | E18: 2800 | F18: =+E18*D18 -> 16800
A19: M440.11 | B19: Re-alignment of guardrails | C19: m | D19: 800 | E19: 200 | F19: =+E19*D19 -> 160000
A20: M440.12 | B20: Installation and repair of wire rope safety fence | F20: =+E20*D20 -> 0
B21: (a)Installation and repair of wire rope safety fence | C21: Prov Sum | D21: 1 | E21: 50000 | F21: =+E21*D21 -> 50000
B22: (b)The Contractor's overhead charges and profit in respect of sub-item M440.12 (a) | C22: % | D22: 50000 | E22: 0.15 | F22: =+E22*D22 -> 7500
F23: =+E23*D23 -> 0
F24: =+E24*D24 -> 0
A25: M4400 | B25: TOTAL CARRIED FORWARD | F25: =SUM(F7:F24) -> 1095230

Sheet M4400-C2
A1: TENDER NUMBER: DRT D2_P08/02/2025
A2: EXECUTION OF ROUTINE ROAD MAINTENANCE CONTRACTS ON SELECTED RISFSA CLASS 3 PROVINCIAL ROADS IN IDENTIFIED AREAS OF GAUTENG PROVINCE
A4: PART B : OPERATIONAL
B5: DESCRIPTION | C5: UNIT | D5: QUANTITY | E5: RATE | F5: AMOUNT
A6: ITEM NO | B6: BROUGHT FORWARD | F6: =+'M4400-C1'!F25 -> 1095230
A8: BM440.15 | B8: Painting of guardrails | C8: m | D8: 80 | E8: 120 | F8: =+E8*D8 -> 9600
A9: BM440.16 | B9: Re-galvanizing of guardrails | C9: m | D9: 80 | E9: 180 | F9: =+E9*D9 -> 14400
A10: BM440.17 | B10: Re-shaping of guardrails | C10: m | D10: 50 | E10: 350 | F10: =+E10*D10 -> 17500
F11: =+E11*D11 -> 0
F16: =IF(D16=0,"",ROUND(D16*E16,2))
A20: M4400 | B20: TOTAL CARRIED FORWARD TO SUMMARY | F20: =SUM(F6:F19) -> 1136730
A21: C2.35

Sheet M4500
A1: TENDER NUMBER: DRT D2_P08/02/2025
A2: EXECUTION OF ROUTINE ROAD MAINTENANCE CONTRACTS ON SELECTED RISFSA CLASS 3 PROVINCIAL ROADS IN IDENTIFIED AREAS OF GAUTENG PROVINCE
A4: PART B : OPERATIONAL
B5: DESCRIPTION | C5: UNIT | D5: QUANTITY | E5: RATE | F5: AMOUNT
A6: ITEM NO | B6: DAZZLE SCREEN ERECTION AND REPLACEMENT
A7: M4500 | B7: Supply and erection of dazzle screens
A8: M450.01 | B8: (a)Metal | C8: m | D8: 16 | E8: 650 | F8: =+E8*D8 -> 10400
B9: (b)Timber | C9: m | D9: 16 | E9: 650 | F9: =+E9*D9 -> 10400
B10: Supply and erection of dazzle screens and supporting posts | F10: =+E10*D10 -> 0
A11: M450.02 | B11: (a)Metal | C11: No | D11: 16 | E11: 350 | F11: =+E11*D11 -> 5600
B12: (b)Timber | C12: No | D12: 16 | E12: 350 | F12: =+E12*D12 -> 5600
A13: M450.03 | B13: Removal of damaged dazzle screens and supporting posts | C13: m | D13: 32 | E13: 250 | F13: =+E13*D13 -> 8000
A14: M4500 | B14: TOTAL CARRIED FORWARD TO SUMMARY | F14: =SUM(F8:F13) -> 40000
A16: C2.36

Sheet M4600
A1: TENDER NUMBER:DRT D2_P08/02/2025
A2: EXECUTION OF ROUTINE ROAD MAINTENANCE CONTRACTS ON SELECTED RISFSA CLASS 3 PROVINCIAL ROADS IN IDENTIFIED AREAS OF GAUTENG PROVINCE
A4: PART B : OPERATIONAL
B5: DESCRIPTION | C5: UNIT | D5: QUANTITY | E5: RATE | F5: AMOUNT
A6: ITEM NO | B6: ROAD MARKING
A7: M4600 | B7: Removal of existing, temporary or permanent road markings by:
A8: BM460.05 | B8: (a) Sandblasting | C8: m2 | D8: 80 | E8: 100 | F8: =+E8*D8 -> 8000
B9: Road markings on a section of road
A10: BM460.06 | B10: (a)Road markings on a section of road | C10: Prov Sum | D10: 1 | E10: 100000 | F10: 100000
B11: (b)The Contractor's overhead charges and profit in respect of sub-item BM460.06 (a) | C11: I | D11: 100000 | E11: 0.15 | F11: =+E11*D11 -> 15000
A12: M4600 | B12: TOTAL CARRIED FORWARD TO SUMMARY | F12: =SUM(F7:F11) -> 123000
A14: C2.37

Sheet M4700
A1: TENDER NUMBER: DRT D2_P08/02/2025
A2: EXECUTION OF ROUTINE ROAD MAINTENANCE CONTRACTS ON SELECTED RISFSA CLASS 3 PROVINCIAL ROADS IN IDENTIFIED AREAS OF GAUTENG PROVINCE
A4: PART B : OPERATIONAL
A5: ITEM NO | B5: DESCRIPTION | C5: UNIT | D5: QUANTITY | E5: RATE | F5: AMOUNT
A6: M4700 | B6: MAINTENANCE OF LAY-BYES AND REST AREAS
A8: M470.01 | B8: Maintenance of lay-byes and rest areas
B10: (a) Maintenance of lay-byes and rest areas | C10: Prov Sum | D10: 1 | E10: 50000 | F10: 50000
B12: (b) The Contractor's overhead charges and profit in respect of sub-item M470.01 (a) | C12: % | D12: 50000 | E12: 0.15 | F12: =+E12*D12 -> 7500
B14: Provision of refuse bins, gazebos, tables and chairs
B16: (a) Provision of refuse bins | C16: Prov Sum | D16: 1 | E16: 2000 | F16: 2000
A18: BM470.02 | B18: (b) The Contractor's overhead charges and profit in respect of sub-item BM470.02 (a) | C18: % | D18: 2000 | E18: 0.15 | F18: =+E18*D18 -> 300
A20: M4700 | B20: TOTAL CARRIED FORWARD TO SUMMARY | F20: =SUM(F7:F19) -> 59800
A22: C2.38

Sheet M5100
A1: TENDER NUMBER: DRT D2_P08/02/2025
A2: EXECUTION OF ROUTINE ROAD MAINTENANCE CONTRACTS ON SELECTED RISFSA CLASS 3 PROVINCIAL ROADS IN IDENTIFIED AREAS OF GAUTENG PROVINCE
A4: PART B : OPERATIONAL
A6: ITEM NO | B6: DESCRIPTION | C6: UNIT | D6: QUANTITY | E6: RATE | F6: AMOUNT
A7: M5100 | B7: GENERAL EROSION PROTECTION
A8: M510.01 | B8: Stone pitching | F8: =IF(D8=0,"",ROUND(D8*E8,2))
B9: (a) Plain pitching
B10: (i) Method 1 | C10: m2 | D10: 24 | E10: 450 | F10: =+E10*D10 -> 10800
B11: (ii) Method 2 | C11: m2 | D11: 24 | E11: 450 | F11: =+E11*D11 -> 10800
B12: (b) Grouted pitching | C12: m2 | D12: 56 | E12: 450 | F12: =+E12*D12 -> 25200
B13: (c) Wired-and-grouted pitching | C13: m2 | D13: 56 | E13: 450 | F13: =+E13*D13 -> 25200
B14: (d) Grouted pitching on a concrete bed (75mm thick, 20/19 MPa concrete) | C14: m2 | D14: 56 | E14: 450 | F14: =+E14*D14 -> 25200
A15: M510.02 | B15: Riprap | F15: =+E15*D15 -> 0
B16: (a) Packed riprap | C16: m3 | D16: 16 | E16: 900 | F16: =+E16*D16 -> 14400
B17: (b) Dumped riprap | C17: m3 | D17: 16 | E17: 900 | F17: =+E17*D17 -> 14400
B18: (c ) Filter backing | F18: =+E18*D18 -> 0
B19: (i) Crushed stone | C19: m3 | D19: 16 | E19: 650 | F19: =+E19*D19 -> 10400
B20: (ii) Filter sand | C20: m3 | D20: 16 | E20: 650 | F20: =+E20*D20 -> 10400
B21: (d) Synthetic-fibre filter fabric (Grade 2) | C21: m2 | D21: 140 | E21: 45 | F21: =+E21*D21 -> 6300
A22: M510.03 | B22: Stone masonry walls | F22: =+E22*D22 -> 0
B23: (a) Plain packed stone | C23: m3 | D23: 16 | E23: 950 | F23: =+E23*D23 -> 15200
B24: (b) Cement-mortared stone walls | C24: m3 | D24: 16 | E24: 950 | F24: =+E24*D24 -> 15200
A25: M510.04 | B25: Concrete pitching and block paving | F25: =+E25*D25 -> 0
B26: (a)Cast in situ concrete pitching (75mm, 20/19 Mpa concrete) | C26: m2 | D26: 48 | E26: 2600 | F26: =+E26*D26 -> 124800
B27: (b)Segmented block paving (60mm thick blocks) | C27: m2 | D27: 48 | E27: 300 | F27: =+E27*D27 -> 14400
B28: (c)Prefabricated concrete grass blocks | C28: m2 | D28: 48 | E28: 320 | F28: =+E28*D28 -> 15360
B29: (d)Prefabricated concrete paving blocks for a sidewalk pavement (60mm thick paving blocks) | C29: m2 | D29: 48 | E29: 320 | F29: =+E29*D29 -> 15360
A30: M5100 | B30: TOTAL CARRIED FORWARD | F30: =SUM(F8:F29) -> 353420

Sheet M5100-C
A1: TENDER NUMBER: DRT D2_P08/02/2025
A2: EXECUTION OF ROUTINE ROAD MAINTENANCE CONTRACTS ON SELECTED RISFSA CLASS 3 PROVINCIAL ROADS IN IDENTIFIED AREAS OF GAUTENG PROVINCE
A4: PART B : OPERATIONAL
A5: ITEM NO | B5: DESCRIPTION | C5: UNIT | D5: QUANTITY | E5: RATE | F5: AMOUNT
B6: BROUGHT FORWARD | F6: =+'M5100'!F30 -> 353420
A7: M510.05 | B7: Concrete edge beams (20 Mpa concrete) | C7: m3 | D7: 20 | E7: 2600 | F7: =+E7*D7 -> 52000
A8: M510.06 | B8: Foundation trenches | C8: m3 | D8: 50 | E8: 2600 | F8: =+E8*D8 -> 130000
A9: M510.07 | B9: Spraying of vegetation destroyer and ant poison | F9: =+E9*D9 -> 0
B10: (a) Herbicide | F10: =+E10*D10 -> 0
B11: (i)Selective | C11: l | D11: 15 | E11: 25 | F11: =+E11*D11 -> 375
B12: (ii)Non-selective | C12: l | D12: 15 | E12: 25 | F12: =+E12*D12 -> 375
B13: (b) Ant poison | C13: l | D13: 15 | E13: 25 | F13: =+E13*D13 -> 375
A14: M5100 | B14: TOTAL CARRIED FORWARD TO SUMMARY | F14: =SUM(F6:F13) -> 536545
A16: C2.40

Sheet M5200
A1: TENDER NUMBER: DRT D2_P08/02/2025
A2: EXECUTION OF ROUTINE ROAD MAINTENANCE CONTRACTS ON SELECTED RISFSA CLASS 3 PROVINCIAL ROADS IN IDENTIFIED AREAS OF GAUTENG PROVINCE
A4: PART B : OPERATIONAL
A6: ITEM NO | B6: DESCRIPTION | C6: UNIT | D6: QUANTITY | E6: RATE | F6: AMOUNT
A7: M5200 | B7: GABION PROTECTION | F7: =IF(D7=0,"",ROUND(D7*E7,2))
A8: M520.01 | B8: Foundation trench excavation and backfilling
B9: (a)In solid rock (material which requires blasting) | C9: m3 | D9: 16 | E9: 250 | F9: =+E9*D9 -> 4000
